Workbook

Sheet Read Me
A1: Solar panel readings — replay store compression, full scale
A2: Measured through the real SQL query path, not by calling the codecs directly. One run per configuration (N=1).
A4: WHAT WAS MEASURED
A5: Input | B5: 42,700,000 rows x 28 B = 1,195,600,000 B (1.11 GiB) of DEBS solar panel readings
A6: Unit sizes | B6: 256, 1024, 4096, 16384 KB. 16 and 64 KB were dropped: at this volume they are granule bookkeeping, not a codec measurement.
A7: Standalone | B7: 6 configurations. NO MemoryStore -- standing alone it holds ~8 MB and would have wrapped ~150 times, measuring an evicting store.
A8: Chained | B8: 5 configurations, MemoryStore -> FileStore -> tail.
A9: Float column | B9: 9 accuracy bounds from lossless to 20%, write-only, at default unit sizes.
A10: Repeats | B10: N=1. Byte counts are deterministic and exact; TIMINGS are single samples and should not be read to better than a few percent.
A12: HEADLINE FINDINGS
A13: Solar is hard | B13: Best ratio 3.31 (LossyStore, 5%, 256 KB) against wind's 8.33. Predicted by the data: producerId is a shuffled permutation of 0..42.7M so nothing can compress it, and the timestamp has no repeating delta.
A14: Smaller is better | B14: Every BOUNDED configuration compresses BETTER at smaller units, monotonically. This is the opposite of the usual expectation. See Anomalies.
A15: zstd does not care | B15: CompressedStore is 1.650 -> 1.652 across a 64x change in unit size. Flat.
A16: Chaining is free here | B16: Chained ratios are within 0.5% of standalone. FileStore keeps only 0.35-0.93% of the stream raw, because its 4 MB flush threshold is tiny relative to 1.2 GB.
A17: The bound buys a lot | B17: The float column is 51% of a lossless store and stored RAW. The very first bound, 0.01%, removes 73.6% of it.
A18: Decode is now flat | B18: 85-95 s at every unit size. Before the per-cursor decode buffer was added, a 16384 KB unit would have cost 64x a 256 KB one.
A20: HOW TO READ THIS WORKBOOK
A21: Green figures | B21: Formulas computed by the sheet. Black figures are measurements.
A22: Data sheets | B22: Standalone, Chained and Float Column hold the CSVs verbatim. Everything else is derived from them by formula, so correcting a measurement moves the analysis.
A23: ratio_on_data | B23: bytes_in / data_out -- framing excluded. Compares codecs.
A24: ratio_on_disk | B24: bytes_in / disk_bytes -- framing included. What it costs to keep.
A25: ratio_on_tail | B25: Chained only. Excludes the bytes FileStore is still holding raw, so it is what the tail codec achieved on what it was actually handed.
A26: Anomalies sheet | B26: Read it before quoting any single number. Four results here are not what a reader would predict and one is unexplained.

Sheet Standalone
A1: dataset | B1: configuration | C1: store_order | D1: tail_tier | E1: bound_pct | F1: unit_kb | G1: rows | H1: row_width_bytes | I1: bytes_in | J1: encode_s | K1: decode_s | L1: data_out | M1: disk_bytes | N1: framing_bytes | O1: framing_ratio | P1: ratio_on_data | Q1: ratio_on_disk | R1: units | S1: runs | T1: filestore_segment_kb | U1: filestore_total_mb | V1: filestore_files_at_capacity | W1: filestore_flush_threshold_kb | X1: lossystore_group_kb | Y1: compressedstore_segment_kb | Z1: compressedstore_level | AA1: memorystore_max_buffer_count | AB1: pool_buffer_bytes | AC1: flush_threshold | AD1: merge_factor | AE1: MemoryStore_data | AF1: MemoryStore_disk | AG1: FileStore_data | AH1: FileStore_disk | AI1: CompressedStore_data | AJ1: CompressedStore_disk | AK1: LossyStore_data | AL1: LossyStore_disk
A2: debs_solar_panels | B2: standalone | C2: CompressedStore | D2: CompressedStore | F2: 256 | G2: 42700000 | H2: 28 | I2: 1195600000 | J2: 156.819 | K2: 85.5277 | L2: 724428841 | M2: 724616220 | N2: 187379 | O2: 0.000259 | P2: 1.6504 | Q2: 1.65 | R2: 4561 | S2: 1 | T2: 256 | U2: 4096 | V2: 4 | W2: 1048576 | X2: 256 | Y2: 256 | Z2: 3 | AA2: 128 | AB2: 4096 | AC2: 1MB | AI2: 724428841 | AJ2: 724616220
A3: debs_solar_panels | B3: standalone | C3: LossyStore | D3: LossyStore | F3: 256 | G3: 42700000 | H3: 28 | I3: 1195600000 | J3: 150.268 | K3: 85.794 | L3: 642199148 | M3: 643275922 | N3: 1076774 | O3: 0.001674 | P3: 1.8617 | Q3: 1.8586 | R3: 4561 | S3: 1 | T3: 256 | U3: 4096 | V3: 4 | W3: 1048576 | X3: 256 | Y3: 256 | Z3: 3 | AA3: 128 | AB3: 4096 | AC3: 1MB | AK3: 642199148 | AL3: 643275922
A4: debs_solar_panels | B4: standalone | C4: LossyStore | D4: LossyStore | E4: 0.1 | F4: 256 | G4: 42700000 | H4: 28 | I4: 1195600000 | J4: 150.094 | K4: 88.5696 | L4: 394504305 | M4: 395581079 | N4: 1076774 | O4: 0.002722 | P4: 3.0306 | Q4: 3.0224 | R4: 4561 | S4: 1 | T4: 256 | U4: 4096 | V4: 4 | W4: 1048576 | X4: 256 | Y4: 256 | Z4: 3 | AA4: 128 | AB4: 4096 | AC4: 1MB | AK4: 394504305 | AL4: 395581079
A5: debs_solar_panels | B5: standalone | C5: LossyStore | D5: LossyStore | E5: 1 | F5: 256 | G5: 42700000 | H5: 28 | I5: 1195600000 | J5: 153.796 | K5: 87.651 | L5: 373846800 | M5: 374923574 | N5: 1076774 | O5: 0.002872 | P5: 3.1981 | Q5: 3.1889 | R5: 4561 | S5: 1 | T5: 256 | U5: 4096 | V5: 4 | W5: 1048576 | X5: 256 | Y5: 256 | Z5: 3 | AA5: 128 | AB5: 4096 | AC5: 1MB | AK5: 373846800 | AL5: 374923574
A6: debs_solar_panels | B6: standalone | C6: LossyStore | D6: LossyStore | E6: 5 | F6: 256 | G6: 42700000 | H6: 28 | I6: 1195600000 | J6: 152.149 | K6: 88.1404 | L6: 360998795 | M6: 362075569 | N6: 1076774 | O6: 0.002974 | P6: 3.3119 | Q6: 3.3021 | R6: 4561 | S6: 1 | T6: 256 | U6: 4096 | V6: 4 | W6: 1048576 | X6: 256 | Y6: 256 | Z6: 3 | AA6: 128 | AB6: 4096 | AC6: 1MB | AK6: 360998795 | AL6: 362075569
A7: debs_solar_panels | B7: standalone | C7: FileStore | D7: FileStore | F7: 256 | G7: 42700000 | H7: 28 | I7: 1195600000 | J7: 146.488 | K7: 88.0405 | L7: 1195600000 | M7: 1195928436 | N7: 328436 | O7: 0.000275 | P7: 1 | Q7: 0.9997 | R7: 4561 | S7: 1 | T7: 256 | U7: 4096 | V7: 4 | W7: 1048576 | X7: 256 | Y7: 256 | Z7: 3 | AA7: 128 | AB7: 4096 | AC7: 1MB | AG7: 1195600000 | AH7: 1195928436
A8: debs_solar_panels | B8: standalone | C8: CompressedStore | D8: CompressedStore | F8: 1024 | G8: 42700000 | H8: 28 | I8: 1195600000 | J8: 135.662 | K8: 93.9734 | L8: 723861477 | M8: 723908636 | N8: 47159 | O8: 6.5e-05 | P8: 1.6517 | Q8: 1.6516 | R8: 1141 | S8: 1 | T8: 1024 | U8: 4096 | V8: 4 | W8: 1048576 | X8: 1024 | Y8: 1024 | Z8: 3 | AA8: 128 | AB8: 4096 | AC8: 1MB | AI8: 723861477 | AJ8: 723908636
A9: debs_solar_panels | B9: standalone | C9: LossyStore | D9: LossyStore | F9: 1024 | G9: 42700000 | H9: 28 | I9: 1195600000 | J9: 131.611 | K9: 93.6597 | L9: 639795627 | M9: 640065281 | N9: 269654 | O9: 0.000421 | P9: 1.8687 | Q9: 1.8679 | R9: 1141 | S9: 1 | T9: 1024 | U9: 4096 | V9: 4 | W9: 1048576 | X9: 1024 | Y9: 1024 | Z9: 3 | AA9: 128 | AB9: 4096 | AC9: 1MB | AK9: 639795627 | AL9: 640065281
A10: debs_solar_panels | B10: standalone | C10: LossyStore | D10: LossyStore | E10: 0.1 | F10: 1024 | G10: 42700000 | H10: 28 | I10: 1195600000 | J10: 131.677 | K10: 93.3639 | L10: 405314797 | M10: 405584451 | N10: 269654 | O10: 0.000665 | P10: 2.9498 | Q10: 2.9478 | R10: 1141 | S10: 1 | T10: 1024 | U10: 4096 | V10: 4 | W10: 1048576 | X10: 1024 | Y10: 1024 | Z10: 3 | AA10: 128 | AB10: 4096 | AC10: 1MB | AK10: 405314797 | AL10: 405584451
A11: debs_solar_panels | B11: standalone | C11: LossyStore | D11: LossyStore | E11: 1 | F11: 1024 | G11: 42700000 | H11: 28 | I11: 1195600000 | J11: 130.526 | K11: 93.9485 | L11: 385249990 | M11: 385519644 | N11: 269654 | O11: 0.000699 | P11: 3.1034 | Q11: 3.1013 | R11: 1141 | S11: 1 | T11: 1024 | U11: 4096 | V11: 4 | W11: 1048576 | X11: 1024 | Y11: 1024 | Z11: 3 | AA11: 128 | AB11: 4096 | AC11: 1MB | AK11: 385249990 | AL11: 385519644
A12: debs_solar_panels | B12: standalone | C12: LossyStore | D12: LossyStore | E12: 5 | F12: 1024 | G12: 42700000 | H12: 28 | I12: 1195600000 | J12: 130.055 | K12: 95.1764 | L12: 370154595 | M12: 370424249 | N12: 269654 | O12: 0.000728 | P12: 3.23 | Q12: 3.2277 | R12: 1141 | S12: 1 | T12: 1024 | U12: 4096 | V12: 4 | W12: 1048576 | X12: 1024 | Y12: 1024 | Z12: 3 | AA12: 128 | AB12: 4096 | AC12: 1MB | AK12: 370154595 | AL12: 370424249
A13: debs_solar_panels | B13: standalone | C13: FileStore | D13: FileStore | F13: 1024 | G13: 42700000 | H13: 28 | I13: 1195600000 | J13: 128.439 | K13: 93.4394 | L13: 1195600000 | M13: 1195682676 | N13: 82676 | O13: 6.9e-05 | P13: 1 | Q13: 0.9999 | R13: 1141 | S13: 1 | T13: 1024 | U13: 4096 | V13: 4 | W13: 1048576 | X13: 1024 | Y13: 1024 | Z13: 3 | AA13: 128 | AB13: 4096 | AC13: 1MB | AG13: 1195600000 | AH13: 1195682676
A14: debs_solar_panels | B14: standalone | C14: CompressedStore | D14: CompressedStore | F14: 4096 | G14: 42700000 | H14: 28 | I14: 1195600000 | J14: 135.817 | K14: 93.9317 | L14: 723766456 | M14: 723778560 | N14: 12104 | O14: 1.7e-05 | P14: 1.6519 | Q14: 1.6519 | R14: 286 | S14: 1 | T14: 4096 | U14: 4096 | V14: 4 | W14: 1048576 | X14: 4096 | Y14: 4096 | Z14: 3 | AA14: 128 | AB14: 4096 | AC14: 1MB | AI14: 723766456 | AJ14: 723778560
A15: debs_solar_panels | B15: standalone | C15: LossyStore | D15: LossyStore | F15: 4096 | G15: 42700000 | H15: 28 | I15: 1195600000 | J15: 131.329 | K15: 93.4674 | L15: 646044488 | M15: 646112362 | N15: 67874 | O15: 0.000105 | P15: 1.8506 | Q15: 1.8505 | R15: 286 | S15: 1 | T15: 4096 | U15: 4096 | V15: 4 | W15: 1048576 | X15: 4096 | Y15: 4096 | Z15: 3 | AA15: 128 | AB15: 4096 | AC15: 1MB | AK15: 646044488 | AL15: 646112362
A16: debs_solar_panels | B16: standalone | C16: LossyStore | D16: LossyStore | E16: 0.1 | F16: 4096 | G16: 42700000 | H16: 28 | I16: 1195600000 | J16: 131.199 | K16: 93.7355 | L16: 415720791 | M16: 415788665 | N16: 67874 | O16: 0.000163 | P16: 2.876 | Q16: 2.8755 | R16: 286 | S16: 1 | T16: 4096 | U16: 4096 | V16: 4 | W16: 1048576 | X16: 4096 | Y16: 4096 | Z16: 3 | AA16: 128 | AB16: 4096 | AC16: 1MB | AK16: 415720791 | AL16: 415788665
A17: debs_solar_panels | B17: standalone | C17: LossyStore | D17: LossyStore | E17: 1 | F17: 4096 | G17: 42700000 | H17: 28 | I17: 1195600000 | J17: 130.127 | K17: 93.2298 | L17: 396405219 | M17: 396473093 | N17: 67874 | O17: 0.000171 | P17: 3.0161 | Q17: 3.0156 | R17: 286 | S17: 1 | T17: 4096 | U17: 4096 | V17: 4 | W17: 1048576 | X17: 4096 | Y17: 4096 | Z17: 3 | AA17: 128 | AB17: 4096 | AC17: 1MB | AK17: 396405219 | AL17: 396473093
A18: debs_solar_panels | B18: standalone | C18: LossyStore | D18: LossyStore | E18: 5 | F18: 4096 | G18: 42700000 | H18: 28 | I18: 1195600000 | J18: 131.186 | K18: 92.9201 | L18: 378222961 | M18: 378290835 | N18: 67874 | O18: 0.000179 | P18: 3.1611 | Q18: 3.1605 | R18: 286 | S18: 1 | T18: 4096 | U18: 4096 | V18: 4 | W18: 1048576 | X18: 4096 | Y18: 4096 | Z18: 3 | AA18: 128 | AB18: 4096 | AC18: 1MB | AK18: 378222961 | AL18: 378290835
A19: debs_solar_panels | B19: standalone | C19: FileStore | D19: FileStore | F19: 4096 | G19: 42700000 | H19: 28 | I19: 1195600000 | J19: 128.535 | K19: 92.8939 | L19: 1195600000 | M19: 1195621236 | N19: 21236 | O19: 1.8e-05 | P19: 1 | Q19: 1 | R19: 286 | S19: 1 | T19: 4096 | U19: 4096 | V19: 4 | W19: 1048576 | X19: 4096 | Y19: 4096 | Z19: 3 | AA19: 128 | AB19: 4096 | AC19: 1MB | AG19: 1195600000 | AH19: 1195621236
A20: debs_solar_panels | B20: standalone | C20: CompressedStore | D20: CompressedStore | F20: 16384 | G20: 42700000 | H20: 28 | I20: 1195600000 | J20: 133.374 | K20: 90.8952 | L20: 723744906 | M20: 723748236 | N20: 3330 | O20: 5e-06 | P20: 1.652 | Q20: 1.652 | R20: 72 | S20: 1 | T20: 16384 | U20: 4096 | V20: 4 | W20: 1048576 | X20: 16384 | Y20: 16384 | Z20: 3 | AA20: 128 | AB20: 4096 | AC20: 1MB | AI20: 723744906 | AJ20: 723748236
A21: debs_solar_panels | B21: standalone | C21: LossyStore | D21: LossyStore | F21: 16384 | G21: 42700000 | H21: 28 | I21: 1195600000 | J21: 130.474 | K21: 90.354 | L21: 651538342 | M21: 651555712 | N21: 17370 | O21: 2.7e-05 | P21: 1.835 | Q21: 1.835 | R21: 72 | S21: 1 | T21: 16384 | U21: 4096 | V21: 4 | W21: 1048576 | X21: 16384 | Y21: 16384 | Z21: 3 | AA21: 128 | AB21: 4096 | AC21: 1MB | AK21: 651538342 | AL21: 651555712
A22: debs_solar_panels | B22: standalone | C22: LossyStore | D22: LossyStore | E22: 0.1 | F22: 16384 | G22: 42700000 | H22: 28 | I22: 1195600000 | J22: 128.903 | K22: 92.9823 | L22: 422734809 | M22: 422752179 | N22: 17370 | O22: 4.1e-05 | P22: 2.8283 | Q22: 2.8281 | R22: 72 | S22: 1 | T22: 16384 | U22: 4096 | V22: 4 | W22: 1048576 | X22: 16384 | Y22: 16384 | Z22: 3 | AA22: 128 | AB22: 4096 | AC22: 1MB | AK22: 422734809 | AL22: 422752179
A23: debs_solar_panels | B23: standalone | C23: LossyStore | D23: LossyStore | E23: 1 | F23: 16384 | G23: 42700000 | H23: 28 | I23: 1195600000 | J23: 124.07 | K23: 90.1519 | L23: 402258660 | M23: 402276030 | N23: 17370 | O23: 4.3e-05 | P23: 2.9722 | Q23: 2.9721 | R23: 72 | S23: 1 | T23: 16384 | U23: 4096 | V23: 4 | W23: 1048576 | X23: 16384 | Y23: 16384 | Z23: 3 | AA23: 128 | AB23: 4096 | AC23: 1MB | AK23: 402258660 | AL23: 402276030
A24: debs_solar_panels | B24: standalone | C24: LossyStore | D24: LossyStore | E24: 5 | F24: 16384 | G24: 42700000 | H24: 28 | I24: 1195600000 | J24: 124.873 | K24: 88.5981 | L24: 380795246 | M24: 380812616 | N24: 17370 | O24: 4.6e-05 | P24: 3.1397 | Q24: 3.1396 | R24: 72 | S24: 1 | T24: 16384 | U24: 4096 | V24: 4 | W24: 1048576 | X24: 16384 | Y24: 16384 | Z24: 3 | AA24: 128 | AB24: 4096 | AC24: 1MB | AK24: 380795246 | AL24: 380812616
A25: debs_solar_panels | B25: standalone | C25: FileStore | D25: FileStore | F25: 16384 | G25: 42700000 | H25: 28 | I25: 1195600000 | J25: 125.987 | K25: 113.633 | L25: 1195600000 | M25: 1195605876 | N25: 5876 | O25: 5e-06 | P25: 1 | Q25: 1 | R25: 72 | S25: 1 | T25: 16384 | U25: 4096 | V25: 4 | W25: 1048576 | X25: 16384 | Y25: 16384 | Z25: 3 | AA25: 128 | AB25: 4096 | AC25: 1MB | AG25: 1195600000 | AH25: 1195605876

Sheet Chained
A1: dataset | B1: configuration | C1: store_order | D1: tail_tier | E1: bound_pct | F1: unit_kb | G1: rows | H1: row_width_bytes | I1: bytes_in | J1: encode_s | K1: decode_s | L1: data_out | M1: disk_bytes | N1: framing_bytes | O1: framing_ratio | P1: ratio_on_data | Q1: ratio_on_disk | R1: units | S1: runs | T1: filestore_segment_kb | U1: filestore_total_mb | V1: filestore_files_at_capacity | W1: filestore_flush_threshold_kb | X1: lossystore_group_kb | Y1: compressedstore_segment_kb | Z1: compressedstore_level | AA1: memorystore_max_buffer_count | AB1: pool_buffer_bytes | AC1: flush_threshold | AD1: merge_factor | AE1: MemoryStore_data | AF1: MemoryStore_disk | AG1: FileStore_data | AH1: FileStore_disk | AI1: CompressedStore_data | AJ1: CompressedStore_disk | AK1: LossyStore_data | AL1: LossyStore_disk
A2: debs_solar_panels | B2: chained | C2: MemoryStore->FileStore->CompressedStore | D2: CompressedStore | F2: 256 | G2: 42700000 | H2: 28 | I2: 1195600000 | J2: 129.515 | K2: 88.0938 | L2: 725795022 | M2: 725983378 | N2: 188356 | O2: 0.000259 | P2: 1.6473 | Q2: 1.6469 | R2: 4570 | S2: 1 | T2: 256 | U2: 64 | V2: 16 | W2: 4096 | X2: 256 | Y2: 256 | Z2: 3 | AA2: 2048 | AB2: 4096 | AC2: 1MB | AD2: 1 | AG2: 2526160 | AH2: 2527178 | AI2: 723268862 | AJ2: 723456200
A3: debs_solar_panels | B3: chained | C3: MemoryStore->FileStore->LossyStore | D3: LossyStore | F3: 256 | G3: 42700000 | H3: 28 | I3: 1195600000 | J3: 128.966 | K3: 88.8711 | L3: 643127122 | M3: 644204678 | N3: 1077556 | O3: 0.001673 | P3: 1.859 | Q3: 1.8559 | R3: 4570 | S3: 1 | T3: 256 | U3: 64 | V3: 16 | W3: 4096 | X3: 256 | Y3: 256 | Z3: 3 | AA3: 2048 | AB3: 4096 | AC3: 1MB | AD3: 1 | AG3: 2526160 | AH3: 2527178 | AK3: 640600962 | AL3: 641677500
A4: debs_solar_panels | B4: chained | C4: MemoryStore->FileStore->LossyStore | D4: LossyStore | E4: 0.1 | F4: 256 | G4: 42700000 | H4: 28 | I4: 1195600000 | J4: 132.679 | K4: 89.9404 | L4: 396052713 | M4: 397130269 | N4: 1077556 | O4: 0.002713 | P4: 3.0188 | Q4: 3.0106 | R4: 4570 | S4: 1 | T4: 256 | U4: 64 | V4: 16 | W4: 4096 | X4: 256 | Y4: 256 | Z4: 3 | AA4: 2048 | AB4: 4096 | AC4: 1MB | AD4: 1 | AG4: 2526160 | AH4: 2527178 | AK4: 393526553 | AL4: 394603091
A5: debs_solar_panels | B5: chained | C5: MemoryStore->FileStore->LossyStore | D5: LossyStore | E5: 1 | F5: 256 | G5: 42700000 | H5: 28 | I5: 1195600000 | J5: 132.177 | K5: 87.4643 | L5: 375426954 | M5: 376504510 | N5: 1077556 | O5: 0.002862 | P5: 3.1846 | Q5: 3.1755 | R5: 4570 | S5: 1 | T5: 256 | U5: 64 | V5: 16 | W5: 4096 | X5: 256 | Y5: 256 | Z5: 3 | AA5: 2048 | AB5: 4096 | AC5: 1MB | AD5: 1 | AG5: 2526160 | AH5: 2527178 | AK5: 372900794 | AL5: 373977332
A6: debs_solar_panels | B6: chained | C6: MemoryStore->FileStore->LossyStore | D6: LossyStore | E6: 5 | F6: 256 | G6: 42700000 | H6: 28 | I6: 1195600000 | J6: 127.816 | K6: 85.8785 | L6: 362598723 | M6: 363676279 | N6: 1077556 | O6: 0.002963 | P6: 3.2973 | Q6: 3.2875 | R6: 4570 | S6: 1 | T6: 256 | U6: 64 | V6: 16 | W6: 4096 | X6: 256 | Y6: 256 | Z6: 3 | AA6: 2048 | AB6: 4096 | AC6: 1MB | AD6: 1 | AG6: 2526160 | AH6: 2527178 | AK6: 360072563 | AL6: 361149101
A7: debs_solar_panels | B7: chained | C7: MemoryStore->FileStore->CompressedStore | D7: CompressedStore | F7: 1024 | G7: 42700000 | H7: 28 | I7: 1195600000 | J7: 129.685 | K7: 84.4911 | L7: 724881093 | M7: 724928749 | N7: 47656 | O7: 6.6e-05 | P7: 1.6494 | Q7: 1.6493 | R7: 1143 | S7: 1 | T7: 1024 | U7: 64 | V7: 16 | W7: 4096 | X7: 1024 | Y7: 1024 | Z7: 3 | AA7: 2048 | AB7: 4096 | AC7: 1MB | AD7: 1 | AG7: 2526160 | AH7: 2526698 | AI7: 722354933 | AJ7: 722402051
A8: debs_solar_panels | B8: chained | C8: MemoryStore->FileStore->LossyStore | D8: LossyStore | F8: 1024 | G8: 42700000 | H8: 28 | I8: 1195600000 | J8: 127.873 | K8: 85.3306 | L8: 640970521 | M8: 641240477 | N8: 269956 | O8: 0.000421 | P8: 1.8653 | Q8: 1.8645 | R8: 1143 | S8: 1 | T8: 1024 | U8: 64 | V8: 16 | W8: 4096 | X8: 1024 | Y8: 1024 | Z8: 3 | AA8: 2048 | AB8: 4096 | AC8: 1MB | AD8: 1 | AG8: 2526160 | AH8: 2526698 | AK8: 638444361 | AL8: 638713779
A9: debs_solar_panels | B9: chained | C9: MemoryStore->FileStore->LossyStore | D9: LossyStore | E9: 0.1 | F9: 1024 | G9: 42700000 | H9: 28 | I9: 1195600000 | J9: 127.29 | K9: 85.748 | L9: 406985912 | M9: 407255868 | N9: 269956 | O9: 0.000663 | P9: 2.9377 | Q9: 2.9357 | R9: 1143 | S9: 1 | T9: 1024 | U9: 64 | V9: 16 | W9: 4096 | X9: 1024 | Y9: 1024 | Z9: 3 | AA9: 2048 | AB9: 4096 | AC9: 1MB | AD9: 1 | AG9: 2526160 | AH9: 2526698 | AK9: 404459752 | AL9: 404729170
A10: debs_solar_panels | B10: chained | C10: MemoryStore->FileStore->LossyStore | D10: LossyStore | E10: 1 | F10: 1024 | G10: 42700000 | H10: 28 | I10: 1195600000 | J10: 125.771 | K10: 84.8461 | L10: 386990332 | M10: 387260288 | N10: 269956 | O10: 0.000697 | P10: 3.0895 | Q10: 3.0873 | R10: 1143 | S10: 1 | T10: 1024 | U10: 64 | V10: 16 | W10: 4096 | X10: 1024 | Y10: 1024 | Z10: 3 | AA10: 2048 | AB10: 4096 | AC10: 1MB | AD10: 1 | AG10: 2526160 | AH10: 2526698 | AK10: 384464172 | AL10: 384733590
A11: debs_solar_panels | B11: chained | C11: MemoryStore->FileStore->LossyStore | D11: LossyStore | E11: 5 | F11: 1024 | G11: 42700000 | H11: 28 | I11: 1195600000 | J11: 126.538 | K11: 86.7 | L11: 371882724 | M11: 372152680 | N11: 269956 | O11: 0.000725 | P11: 3.215 | Q11: 3.2127 | R11: 1143 | S11: 1 | T11: 1024 | U11: 64 | V11: 16 | W11: 4096 | X11: 1024 | Y11: 1024 | Z11: 3 | AA11: 2048 | AB11: 4096 | AC11: 1MB | AD11: 1 | AG11: 2526160 | AH11: 2526698 | AK11: 369356564 | AL11: 369625982
A12: debs_solar_panels | B12: chained | C12: MemoryStore->FileStore->CompressedStore | D12: CompressedStore | F12: 4096 | G12: 42700000 | H12: 28 | I12: 1195600000 | J12: 131.466 | K12: 86.88 | L12: 724779693 | M12: 724799185 | N12: 19492 | O12: 2.7e-05 | P12: 1.6496 | Q12: 1.6496 | R12: 457 | S12: 1 | T12: 4096 | U12: 64 | V12: 16 | W12: 4096 | X12: 4096 | Y12: 4096 | Z12: 3 | AA12: 2048 | AB12: 4096 | AC12: 1MB | AD12: 1 | AG12: 2526160 | AH12: 2526578 | AI12: 722253533 | AJ12: 722272607
A13: debs_solar_panels | B13: chained | C13: MemoryStore->FileStore->LossyStore | D13: LossyStore | F13: 4096 | G13: 42700000 | H13: 28 | I13: 1195600000 | J13: 129.174 | K13: 87.3531 | L13: 645940219 | M13: 646048631 | N13: 108412 | O13: 0.000168 | P13: 1.8509 | Q13: 1.8506 | R13: 457 | S13: 1 | T13: 4096 | U13: 64 | V13: 16 | W13: 4096 | X13: 4096 | Y13: 4096 | Z13: 3 | AA13: 2048 | AB13: 4096 | AC13: 1MB | AD13: 1 | AG13: 2526160 | AH13: 2526578 | AK13: 643414059 | AL13: 643522053
A14: debs_solar_panels | B14: chained | C14: MemoryStore->FileStore->LossyStore | D14: LossyStore | E14: 0.1 | F14: 4096 | G14: 42700000 | H14: 28 | I14: 1195600000 | J14: 127.933 | K14: 88.0187 | L14: 415297579 | M14: 415405991 | N14: 108412 | O14: 0.000261 | P14: 2.8789 | Q14: 2.8781 | R14: 457 | S14: 1 | T14: 4096 | U14: 64 | V14: 16 | W14: 4096 | X14: 4096 | Y14: 4096 | Z14: 3 | AA14: 2048 | AB14: 4096 | AC14: 1MB | AD14: 1 | AG14: 2526160 | AH14: 2526578 | AK14: 412771419 | AL14: 412879413
A15: debs_solar_panels | B15: chained | C15: MemoryStore->FileStore->LossyStore | D15: LossyStore | E15: 1 | F15: 4096 | G15: 42700000 | H15: 28 | I15: 1195600000 | J15: 127.973 | K15: 88.0725 | L15: 395938822 | M15: 396047234 | N15: 108412 | O15: 0.000274 | P15: 3.0197 | Q15: 3.0188 | R15: 457 | S15: 1 | T15: 4096 | U15: 64 | V15: 16 | W15: 4096 | X15: 4096 | Y15: 4096 | Z15: 3 | AA15: 2048 | AB15: 4096 | AC15: 1MB | AD15: 1 | AG15: 2526160 | AH15: 2526578 | AK15: 393412662 | AL15: 393520656
A16: debs_solar_panels | B16: chained | C16: MemoryStore->FileStore->LossyStore | D16: LossyStore | E16: 5 | F16: 4096 | G16: 42700000 | H16: 28 | I16: 1195600000 | J16: 127.441 | K16: 87.7365 | L16: 378271929 | M16: 378380341 | N16: 108412 | O16: 0.000287 | P16: 3.1607 | Q16: 3.1598 | R16: 457 | S16: 1 | T16: 4096 | U16: 64 | V16: 16 | W16: 4096 | X16: 4096 | Y16: 4096 | Z16: 3 | AA16: 2048 | AB16: 4096 | AC16: 1MB | AD16: 1 | AG16: 2526160 | AH16: 2526578 | AK16: 375745769 | AL16: 375853763
A17: debs_solar_panels | B17: chained | C17: MemoryStore->FileStore->CompressedStore | D17: CompressedStore | F17: 16384 | G17: 42700000 | H17: 28 | I17: 1195600000 | J17: 133.402 | K17: 87.7869 | L17: 725160709 | M17: 725166999 | N17: 6290 | O17: 9e-06 | P17: 1.6487 | Q17: 1.6487 | R17: 135 | S17: 1 | T17: 16384 | U17: 64 | V17: 16 | W17: 4096 | X17: 16384 | Y17: 16384 | Z17: 3 | AA17: 2048 | AB17: 4096 | AC17: 1MB | AD17: 1 | AG17: 3572716 | AH17: 3573134 | AI17: 721587993 | AJ17: 721593865
A18: debs_solar_panels | B18: chained | C18: MemoryStore->FileStore->LossyStore | D18: LossyStore | F18: 16384 | G18: 42700000 | H18: 28 | I18: 1195600000 | J18: 130.266 | K18: 86.4633 | L18: 652557626 | M18: 652590046 | N18: 32420 | O18: 5e-05 | P18: 1.8322 | Q18: 1.8321 | R18: 135 | S18: 1 | T18: 16384 | U18: 64 | V18: 16 | W18: 4096 | X18: 16384 | Y18: 16384 | Z18: 3 | AA18: 2048 | AB18: 4096 | AC18: 1MB | AD18: 1 | AG18: 3572716 | AH18: 3573134 | AK18: 648984910 | AL18: 649016912
A19: debs_solar_panels | B19: chained | C19: MemoryStore->FileStore->LossyStore | D19: LossyStore | E19: 0.1 | F19: 16384 | G19: 42700000 | H19: 28 | I19: 1195600000 | J19: 129.132 | K19: 87.6786 | L19: 424017513 | M19: 424049933 | N19: 32420 | O19: 7.6e-05 | P19: 2.8197 | Q19: 2.8195 | R19: 135 | S19: 1 | T19: 16384 | U19: 64 | V19: 16 | W19: 4096 | X19: 16384 | Y19: 16384 | Z19: 3 | AA19: 2048 | AB19: 4096 | AC19: 1MB | AD19: 1 | AG19: 3572716 | AH19: 3573134 | AK19: 420444797 | AL19: 420476799
A20: debs_solar_panels | B20: chained | C20: MemoryStore->FileStore->LossyStore | D20: LossyStore | E20: 1 | F20: 16384 | G20: 42700000 | H20: 28 | I20: 1195600000 | J20: 128.957 | K20: 87.0142 | L20: 403629532 | M20: 403661952 | N20: 32420 | O20: 8e-05 | P20: 2.9621 | Q20: 2.9619 | R20: 135 | S20: 1 | T20: 16384 | U20: 64 | V20: 16 | W20: 4096 | X20: 16384 | Y20: 16384 | Z20: 3 | AA20: 2048 | AB20: 4096 | AC20: 1MB | AD20: 1 | AG20: 3572716 | AH20: 3573134 | AK20: 400056816 | AL20: 400088818
A21: debs_solar_panels | B21: chained | C21: MemoryStore->FileStore->LossyStore | D21: LossyStore | E21: 5 | F21: 16384 | G21: 42700000 | H21: 28 | I21: 1195600000 | J21: 129.461 | K21: 87.0299 | L21: 382807287 | M21: 382839707 | N21: 32420 | O21: 8.5e-05 | P21: 3.1232 | Q21: 3.123 | R21: 135 | S21: 1 | T21: 16384 | U21: 64 | V21: 16 | W21: 4096 | X21: 16384 | Y21: 16384 | Z21: 3 | AA21: 2048 | AB21: 4096 | AC21: 1MB | AD21: 1 | AG21: 3572716 | AH21: 3573134 | AK21: 379234571 | AL21: 379266573

Sheet Float Column
A1: dataset | B1: column | C1: type | D1: is_quantisable | E1: bound_pct | F1: groups | G1: bytes | H1: bytes_per_row | I1: vs_lossless_bytes | J1: vs_lossless_pct | K1: codec | L1: worst_recorded_error
A2: debs_solar_panels | B2: producerId | C2: INT32 | D2: no | E2: 0 | F2: 18241 | G2: 144297189 | H2: 3.3793 | I2: 0 | J2: 0 | K2: ForBitpack | L2: 0
A3: debs_solar_panels | B3: groupId | C3: INT32 | D3: no | E3: 0 | F3: 18241 | G3: 16197189 | H3: 0.3793 | I3: 0 | J3: 0 | K3: ForBitpack | L3: 0
A4: debs_solar_panels | B4: producedPower | C4: FLOAT64 | D4: yes | E4: 0 | F4: 18241 | G4: 326573665 | H4: 7.6481 | I4: 0 | J4: 0 | K4: Raw | L4: 0
A5: debs_solar_panels | B5: ts | C5: UINT64 | D5: no | E5: 0 | F5: 18241 | G5: 149623209 | H5: 3.5041 | I5: 0 | J5: 0 | K5: ForBitpack | L5: 0
A6: debs_solar_panels | B6: producerId | C6: INT32 | D6: no | E6: 0.01 | F6: 18241 | G6: 144297189 | H6: 3.3793 | I6: 0 | J6: 0 | K6: ForBitpack | L6: 0
A7: debs_solar_panels | B7: groupId | C7: INT32 | D7: no | E7: 0.01 | F7: 18241 | G7: 16197189 | H7: 0.3793 | I7: 0 | J7: 0 | K7: ForBitpack | L7: 0
A8: debs_solar_panels | B8: producedPower | C8: FLOAT64 | D8: yes | E8: 0.01 | F8: 18241 | G8: 86385645 | H8: 2.0231 | I8: -240188020 | J8: -73.55 | K8: Quantized | L8: 9.9999994e-05
A9: debs_solar_panels | B9: ts | C9: UINT64 | D9: no | E9: 0.01 | F9: 18241 | G9: 149623209 | H9: 3.5041 | I9: 0 | J9: 0 | K9: ForBitpack | L9: 0
A10: debs_solar_panels | B10: producerId | C10: INT32 | D10: no | E10: 0.1 | F10: 18241 | G10: 144297189 | H10: 3.3793 | I10: 0 | J10: 0 | K10: ForBitpack | L10: 0
A11: debs_solar_panels | B11: groupId | C11: INT32 | D11: no | E11: 0.1 | F11: 18241 | G11: 16197189 | H11: 0.3793 | I11: 0 | J11: 0 | K11: ForBitpack | L11: 0
A12: debs_solar_panels | B12: producedPower | C12: FLOAT64 | D12: yes | E12: 0.1 | F12: 18241 | G12: 71537477 | H12: 1.6754 | I12: -255036188 | J12: -78.09 | K12: Quantized | L12: 0.00099999997
A13: debs_solar_panels | B13: ts | C13: UINT64 | D13: no | E13: 0.1 | F13: 18241 | G13: 149623209 | H13: 3.5041 | I13: 0 | J13: 0 | K13: ForBitpack | L13: 0
... A37: debs_solar_panels | B37: ts | C37: UINT64 | D37: no | E37: 20 | F37: 18241 | G37: 149623209 | H37: 3.5041 | I37: 0 | J37: 0 | K37: ForBitpack | L37: 0

Sheet Lossy Breakdown
A1: dataset | B1: column | C1: bound_pct | D1: rows | E1: groups | F1: raw_bytes | G1: raw_bits_per_value | H1: quantised_code_bytes | I1: quantised_bits_per_value | J1: quantise_ratio | K1: header_bytes | L1: bitpacked_bytes | M1: bitpacked_bits_per_value | N1: bitpack_ratio | O1: zstd_bytes | P1: zstd_bits_per_value | Q1: final_ratio | R1: zstd_saved_bytes | S1: zstd_saved_pct | T1: zstd_kept_groups | U1: zstd_kept_share | V1: x_from_quantise_bitpack | W1: x_from_zstd
A2: debs_solar_panels | B2: producedPower | C2: 0 | D2: 42700000 | E2: 18241 | F2: 341600000 | G2: 64 | H2: 341271662 | I2: 63.9385 | J2: 1.001 | K2: 328338 | L2: 341600000 | M2: 64 | N2: 1 | O2: 321229325 | P2: 60.1835 | Q2: 1.0634 | R2: 20370675 | S2: 5.963 | T2: 18241 | U2: 1 | V2: 1 | W2: 1.0634
A3: debs_solar_panels | B3: producedPower | C3: 0.01 | D3: 42700000 | E3: 18241 | F3: 341600000 | G3: 64 | H3: 85234514 | I3: 15.969 | J3: 4.0078 | K3: 328338 | L3: 85562852 | M3: 16.0305 | N3: 3.9924 | O3: 81041305 | P3: 15.1834 | Q3: 4.2151 | R3: 4521547 | S3: 5.284 | T3: 17517 | U3: 0.9603 | V3: 3.9924 | W3: 1.0558
A4: debs_solar_panels | B4: producedPower | C4: 0.1 | D4: 42700000 | E4: 18241 | F4: 341600000 | G4: 64 | H4: 66595030 | I4: 12.4768 | J4: 5.1295 | K4: 328338 | L4: 66923368 | M4: 12.5383 | N4: 5.1043 | O4: 66193137 | P4: 12.4015 | Q4: 5.1607 | R4: 730231 | S4: 1.091 | T4: 9573 | U4: 0.5248 | V4: 5.1043 | W4: 1.011
A5: debs_solar_panels | B5: producedPower | C5: 0.5 | D5: 42700000 | E5: 18241 | F5: 341600000 | G5: 64 | H5: 53828432 | I5: 10.085 | J5: 6.3461 | K5: 328338 | L5: 54156770 | M5: 10.1465 | N5: 6.3076 | O5: 53564603 | P5: 10.0355 | Q5: 6.3773 | R5: 592167 | S5: 1.093 | T5: 8159 | U5: 0.4473 | V5: 6.3076 | W5: 1.0111
A6: debs_solar_panels | B6: producedPower | C6: 1 | D6: 42700000 | E6: 18241 | F6: 341600000 | G6: 64 | H6: 48500834 | I6: 9.0868 | J6: 7.0432 | K6: 328338 | L6: 48829172 | M6: 9.1483 | N6: 6.9958 | O6: 48616972 | P6: 9.1086 | Q6: 7.0264 | R6: 212200 | S6: 0.435 | T6: 2339 | U6: 0.1282 | V6: 6.9958 | W6: 1.0044
A7: debs_solar_panels | B7: producedPower | C7: 2 | D7: 42700000 | E7: 18241 | F7: 341600000 | G7: 64 | H7: 43182864 | I7: 8.0905 | J7: 7.9105 | K7: 328338 | L7: 43511202 | M7: 8.152 | N7: 7.8509 | O7: 36004290 | P7: 6.7455 | Q7: 9.4878 | R7: 7506912 | S7: 17.253 | T7: 16654 | U7: 0.913 | V7: 7.8509 | W7: 1.2085
A8: debs_solar_panels | B8: producedPower | C8: 5 | D8: 42700000 | E8: 18241 | F8: 341600000 | G8: 64 | H8: 37377846 | I8: 7.0029 | J8: 9.1391 | K8: 328338 | L8: 37706184 | M8: 7.0644 | N8: 9.0595 | O8: 37195067 | P8: 6.9686 | Q8: 9.184 | R8: 511117 | S8: 1.356 | T8: 7141 | U8: 0.3915 | V8: 9.0595 | W8: 1.0137
A9: debs_solar_panels | B9: producedPower | C9: 10 | D9: 42700000 | E9: 18241 | F9: 341600000 | G9: 64 | H9: 32080591 | I9: 6.0104 | J9: 10.6482 | K9: 328338 | L9: 32408929 | M9: 6.0719 | N9: 10.5403 | O9: 28583755 | P9: 5.3553 | Q9: 11.9508 | R9: 3825174 | S9: 11.803 | T9: 18240 | U9: 0.9999 | V9: 10.5403 | W9: 1.1338
A10: debs_solar_panels | B10: producedPower | C10: 20 | D10: 42700000 | E10: 18241 | F10: 341600000 | G10: 64 | H10: 26828141 | I10: 5.0263 | J10: 12.7329 | K10: 328338 | L10: 27156479 | M10: 5.0879 | N10: 12.579 | O10: 25041378 | P10: 4.6916 | Q10: 13.6414 | R10: 2115101 | S10: 7.789 | T10: 18240 | U10: 0.9999 | V10: 12.579 | W10: 1.0845

Sheet A1 Ratio by Unit
A1: What the unit size buys
A2: The unit is the granule a tier seals on: FileStore's segment, LossyStore's group, CompressedStore's segment. All three move together in this sweep.
A4: STANDALONE - ratio_on_data (bytes_in / data_out)
A5: One store, no tiering. Higher is better.
A6: Configuration | B6: 256 KB | C6: 1024 KB | D6: 4096 KB | E6: 16384 KB
A7: FileStore | B7: =SUMIFS(Standalone!$P:$P,Standalone!$C:$C,"FileStore",Standalone!$E:$E,"",Standalone!$F:$F,256) -> 1 | C7: =SUMIFS(Standalone!$P:$P,Standalone!$C:$C,"FileStore",Standalone!$E:$E,"",Standalone!$F:$F,1024) -> 1 | D7: =SUMIFS(Standalone!$P:$P,Standalone!$C:$C,"FileStore",Standalone!$E:$E,"",Standalone!$F:$F,4096) -> 1 | E7: =SUMIFS(Standalone!$P:$P,Standalone!$C:$C,"FileStore",Standalone!$E:$E,"",Standalone!$F:$F,16384) -> 1
A8: CompressedStore | B8: =SUMIFS(Standalone!$P:$P,Standalone!$C:$C,"CompressedStore",Standalone!$E:$E,"",Standalone!$F:$F,256) -> 1.6504 | C8: =SUMIFS(Standalone!$P:$P,Standalone!$C:$C,"CompressedStore",Standalone!$E:$E,"",Standalone!$F:$F,1024) -> 1.6517 | D8: =SUMIFS(Standalone!$P:$P,Standalone!$C:$C,"CompressedStore",Standalone!$E:$E,"",Standalone!$F:$F,4096) -> 1.6519 | E8: =SUMIFS(Standalone!$P:$P,Standalone!$C:$C,"CompressedStore",Standalone!$E:$E,"",Standalone!$F:$F,16384) -> 1.652
A9: LossyStore lossless | B9: =SUMIFS(Standalone!$P:$P,Standalone!$C:$C,"LossyStore",Standalone!$E:$E,"",Standalone!$F:$F,256) -> 1.8617 | C9: =SUMIFS(Standalone!$P:$P,Standalone!$C:$C,"LossyStore",Standalone!$E:$E,"",Standalone!$F:$F,1024) -> 1.8687 | D9: =SUMIFS(Standalone!$P:$P,Standalone!$C:$C,"LossyStore",Standalone!$E:$E,"",Standalone!$F:$F,4096) -> 1.8506 | E9: =SUMIFS(Standalone!$P:$P,Standalone!$C:$C,"LossyStore",Standalone!$E:$E,"",Standalone!$F:$F,16384) -> 1.835
A10: LossyStore 0.1% | B10: =SUMIFS(Standalone!$P:$P,Standalone!$C:$C,"LossyStore",Standalone!$E:$E,0.1,Standalone!$F:$F,256) -> 3.0306 | C10: =SUMIFS(Standalone!$P:$P,Standalone!$C:$C,"LossyStore",Standalone!$E:$E,0.1,Standalone!$F:$F,1024) -> 2.9498 | D10: =SUMIFS(Standalone!$P:$P,Standalone!$C:$C,"LossyStore",Standalone!$E:$E,0.1,Standalone!$F:$F,4096) -> 2.876 | E10: =SUMIFS(Standalone!$P:$P,Standalone!$C:$C,"LossyStore",Standalone!$E:$E,0.1,Standalone!$F:$F,16384) -> 2.8283
A11: LossyStore 1% | B11: =SUMIFS(Standalone!$P:$P,Standalone!$C:$C,"LossyStore",Standalone!$E:$E,1,Standalone!$F:$F,256) -> 3.1981 | C11: =SUMIFS(Standalone!$P:$P,Standalone!$C:$C,"LossyStore",Standalone!$E:$E,1,Standalone!$F:$F,1024) -> 3.1034 | D11: =SUMIFS(Standalone!$P:$P,Standalone!$C:$C,"LossyStore",Standalone!$E:$E,1,Standalone!$F:$F,4096) -> 3.0161 | E11: =SUMIFS(Standalone!$P:$P,Standalone!$C:$C,"LossyStore",Standalone!$E:$E,1,Standalone!$F:$F,16384) -> 2.9722
A12: LossyStore 5% | B12: =SUMIFS(Standalone!$P:$P,Standalone!$C:$C,"LossyStore",Standalone!$E:$E,5,Standalone!$F:$F,256) -> 3.3119 | C12: =SUMIFS(Standalone!$P:$P,Standalone!$C:$C,"LossyStore",Standalone!$E:$E,5,Standalone!$F:$F,1024) -> 3.23 | D12: =SUMIFS(Standalone!$P:$P,Standalone!$C:$C,"LossyStore",Standalone!$E:$E,5,Standalone!$F:$F,4096) -> 3.1611 | E12: =SUMIFS(Standalone!$P:$P,Standalone!$C:$C,"LossyStore",Standalone!$E:$E,5,Standalone!$F:$F,16384) -> 3.1397
A14: WHAT THIS SHOWS | B14: Each line is one store configuration; the x axis is the granule it seals on, 64x from left to right.
A15: WHAT TO LOOK FOR | B15: The three BOUNDED lossy lines all slope DOWN -- smaller units compress better. That is backwards from the usual intuition and is Anomaly 1. CompressedStore is a flat line at 1.65: zstd does not care about the block size here. FileStore is flat at 1.0 by definition, it is the baseline.
A17: STANDALONE - ratio_on_disk (framing included)
A18: Same, but counting file headers, preallocated tables and per-unit descriptors. FIVE decimals on purpose -- see the note below.
A19: Configuration | B19: 256 KB | C19: 1024 KB | D19: 4096 KB | E19: 16384 KB
A20: FileStore | B20: =SUMIFS(Standalone!$Q:$Q,Standalone!$C:$C,"FileStore",Standalone!$E:$E,"",Standalone!$F:$F,256) -> 0.9997 | C20: =SUMIFS(Standalone!$Q:$Q,Standalone!$C:$C,"FileStore",Standalone!$E:$E,"",Standalone!$F:$F,1024) -> 0.9999 | D20: =SUMIFS(Standalone!$Q:$Q,Standalone!$C:$C,"FileStore",Standalone!$E:$E,"",Standalone!$F:$F,4096) -> 1 | E20: =SUMIFS(Standalone!$Q:$Q,Standalone!$C:$C,"FileStore",Standalone!$E:$E,"",Standalone!$F:$F,16384) -> 1
A21: CompressedStore | B21: =SUMIFS(Standalone!$Q:$Q,Standalone!$C:$C,"CompressedStore",Standalone!$E:$E,"",Standalone!$F:$F,256) -> 1.65 | C21: =SUMIFS(Standalone!$Q:$Q,Standalone!$C:$C,"CompressedStore",Standalone!$E:$E,"",Standalone!$F:$F,1024) -> 1.6516 | D21: =SUMIFS(Standalone!$Q:$Q,Standalone!$C:$C,"CompressedStore",Standalone!$E:$E,"",Standalone!$F:$F,4096) -> 1.6519 | E21: =SUMIFS(Standalone!$Q:$Q,Standalone!$C:$C,"CompressedStore",Standalone!$E:$E,"",Standalone!$F:$F,16384) -> 1.652
A22: LossyStore lossless | B22: =SUMIFS(Standalone!$Q:$Q,Standalone!$C:$C,"LossyStore",Standalone!$E:$E,"",Standalone!$F:$F,256) -> 1.8586 | C22: =SUMIFS(Standalone!$Q:$Q,Standalone!$C:$C,"LossyStore",Standalone!$E:$E,"",Standalone!$F:$F,1024) -> 1.8679 | D22: =SUMIFS(Standalone!$Q:$Q,Standalone!$C:$C,"LossyStore",Standalone!$E:$E,"",Standalone!$F:$F,4096) -> 1.8505 | E22: =SUMIFS(Standalone!$Q:$Q,Standalone!$C:$C,"LossyStore",Standalone!$E:$E,"",Standalone!$F:$F,16384) -> 1.835
A23: LossyStore 0.1% | B23: =SUMIFS(Standalone!$Q:$Q,Standalone!$C:$C,"LossyStore",Standalone!$E:$E,0.1,Standalone!$F:$F,256) -> 3.0224 | C23: =SUMIFS(Standalone!$Q:$Q,Standalone!$C:$C,"LossyStore",Standalone!$E:$E,0.1,Standalone!$F:$F,1024) -> 2.9478 | D23: =SUMIFS(Standalone!$Q:$Q,Standalone!$C:$C,"LossyStore",Standalone!$E:$E,0.1,Standalone!$F:$F,4096) -> 2.8755 | E23: =SUMIFS(Standalone!$Q:$Q,Standalone!$C:$C,"LossyStore",Standalone!$E:$E,0.1,Standalone!$F:$F,16384) -> 2.8281
A24: LossyStore 1% | B24: =SUMIFS(Standalone!$Q:$Q,Standalone!$C:$C,"LossyStore",Standalone!$E:$E,1,Standalone!$F:$F,256) -> 3.1889 | C24: =SUMIFS(Standalone!$Q:$Q,Standalone!$C:$C,"LossyStore",Standalone!$E:$E,1,Standalone!$F:$F,1024) -> 3.1013 | D24: =SUMIFS(Standalone!$Q:$Q,Standalone!$C:$C,"LossyStore",Standalone!$E:$E,1,Standalone!$F:$F,4096) -> 3.0156 | E24: =SUMIFS(Standalone!$Q:$Q,Standalone!$C:$C,"LossyStore",Standalone!$E:$E,1,Standalone!$F:$F,16384) -> 2.9721
A25: LossyStore 5% | B25: =SUMIFS(Standalone!$Q:$Q,Standalone!$C:$C,"LossyStore",Standalone!$E:$E,5,Standalone!$F:$F,256) -> 3.3021 | C25: =SUMIFS(Standalone!$Q:$Q,Standalone!$C:$C,"LossyStore",Standalone!$E:$E,5,Standalone!$F:$F,1024) -> 3.2277 | D25: =SUMIFS(Standalone!$Q:$Q,Standalone!$C:$C,"LossyStore",Standalone!$E:$E,5,Standalone!$F:$F,4096) -> 3.1605 | E25: =SUMIFS(Standalone!$Q:$Q,Standalone!$C:$C,"LossyStore",Standalone!$E:$E,5,Standalone!$F:$F,16384) -> 3.1396
A27: WHAT THIS SHOWS | B27: What the data actually costs to keep, as opposed to what the codec produced.
A28: WHAT TO LOOK FOR | B28: It sits almost exactly on top of the previous chart. On WIND these two diverged by up to 10.8% at a 16 KB unit; here the gap is under 0.3% everywhere, because 1.2 GB is far too much data for per-unit framing to matter.
A29: WHY FILESTORE LOOKS LIKE EXACTLY 1: it is not. Its framing is 328,436 B at 256 KB falling to 5,876 B at 16384 KB, so the ratio is 0.99973 .. 0.99999. At three decimal places that rounds to 1.000 and the framing disappears. This table therefore shows five. A ratio is the wrong instrument for an overhead this small against 1.2 GB -- the byte table below is the honest one.
A31: FRAMING IN BYTES - disk_bytes minus data_out
A32: The same overhead stated absolutely, where nothing is lost to rounding.
A33: Configuration | B33: 256 KB | C33: 1024 KB | D33: 4096 KB | E33: 16384 KB
A34: FileStore | B34: =SUMIFS(Standalone!$N:$N,Standalone!$C:$C,"FileStore",Standalone!$E:$E,"",Standalone!$F:$F,256) -> 328436 | C34: =SUMIFS(Standalone!$N:$N,Standalone!$C:$C,"FileStore",Standalone!$E:$E,"",Standalone!$F:$F,1024) -> 82676 | D34: =SUMIFS(Standalone!$N:$N,Standalone!$C:$C,"FileStore",Standalone!$E:$E,"",Standalone!$F:$F,4096) -> 21236 | E34: =SUMIFS(Standalone!$N:$N,Standalone!$C:$C,"FileStore",Standalone!$E:$E,"",Standalone!$F:$F,16384) -> 5876
A35: CompressedStore | B35: =SUMIFS(Standalone!$N:$N,Standalone!$C:$C,"CompressedStore",Standalone!$E:$E,"",Standalone!$F:$F,256) -> 187379 | C35: =SUMIFS(Standalone!$N:$N,Standalone!$C:$C,"CompressedStore",Standalone!$E:$E,"",Standalone!$F:$F,1024) -> 47159 | D35: =SUMIFS(Standalone!$N:$N,Standalone!$C:$C,"CompressedStore",Standalone!$E:$E,"",Standalone!$F:$F,4096) -> 12104 | E35: =SUMIFS(Standalone!$N:$N,Standalone!$C:$C,"CompressedStore",Standalone!$E:$E,"",Standalone!$F:$F,16384) -> 3330
A36: LossyStore lossless | B36: =SUMIFS(Standalone!$N:$N,Standalone!$C:$C,"LossyStore",Standalone!$E:$E,"",Standalone!$F:$F,256) -> 1076774 | C36: =SUMIFS(Standalone!$N:$N,Standalone!$C:$C,"LossyStore",Standalone!$E:$E,"",Standalone!$F:$F,1024) -> 269654 | D36: =SUMIFS(Standalone!$N:$N,Standalone!$C:$C,"LossyStore",Standalone!$E:$E,"",Standalone!$F:$F,4096) -> 67874 | E36: =SUMIFS(Standalone!$N:$N,Standalone!$C:$C,"LossyStore",Standalone!$E:$E,"",Standalone!$F:$F,16384) -> 17370
A37: LossyStore 0.1% | B37: =SUMIFS(Standalone!$N:$N,Standalone!$C:$C,"LossyStore",Standalone!$E:$E,0.1,Standalone!$F:$F,256) -> 1076774 | C37: =SUMIFS(Standalone!$N:$N,Standalone!$C:$C,"LossyStore",Standalone!$E:$E,0.1,Standalone!$F:$F,1024) -> 269654 | D37: =SUMIFS(Standalone!$N:$N,Standalone!$C:$C,"LossyStore",Standalone!$E:$E,0.1,Standalone!$F:$F,4096) -> 67874 | E37: =SUMIFS(Standalone!$N:$N,Standalone!$C:$C,"LossyStore",Standalone!$E:$E,0.1,Standalone!$F:$F,16384) -> 17370
A38: LossyStore 1% | B38: =SUMIFS(Standalone!$N:$N,Standalone!$C:$C,"LossyStore",Standalone!$E:$E,1,Standalone!$F:$F,256) -> 1076774 | C38: =SUMIFS(Standalone!$N:$N,Standalone!$C:$C,"LossyStore",Standalone!$E:$E,1,Standalone!$F:$F,1024) -> 269654 | D38: =SUMIFS(Standalone!$N:$N,Standalone!$C:$C,"LossyStore",Standalone!$E:$E,1,Standalone!$F:$F,4096) -> 67874 | E38: =SUMIFS(Standalone!$N:$N,Standalone!$C:$C,"LossyStore",Standalone!$E:$E,1,Standalone!$F:$F,16384) -> 17370
A39: LossyStore 5% | B39: =SUMIFS(Standalone!$N:$N,Standalone!$C:$C,"LossyStore",Standalone!$E:$E,5,Standalone!$F:$F,256) -> 1076774 | C39: =SUMIFS(Standalone!$N:$N,Standalone!$C:$C,"LossyStore",Standalone!$E:$E,5,Standalone!$F:$F,1024) -> 269654 | D39: =SUMIFS(Standalone!$N:$N,Standalone!$C:$C,"LossyStore",Standalone!$E:$E,5,Standalone!$F:$F,4096) -> 67874 | E39: =SUMIFS(Standalone!$N:$N,Standalone!$C:$C,"LossyStore",Standalone!$E:$E,5,Standalone!$F:$F,16384) -> 17370
A41: WHAT THIS SHOWS | B41: Actual bytes of bookkeeping per configuration, on a log axis because the range is 1000x.
A42: WHAT TO LOOK FOR | B42: Every line falls ~4x per step, tracking the unit count exactly -- framing is per-unit, so four times fewer units means four times less of it. LossyStore pays the most (236 B per group: a 36 B group header plus 50 B per column), FileStore the least. Even LossyStore's worst case here, about 1.1 MB, is 0.09% of the file.
A44: CHAINED - ratio_on_data (the whole chain)
A45: MemoryStore -> FileStore -> tail. Counts whatever FileStore is still holding raw.
A46: Configuration | B46: 256 KB | C46: 1024 KB | D46: 4096 KB | E46: 16384 KB
A47: -> CompressedStore | B47: =SUMIFS(Chained!$P:$P,Chained!$C:$C,"MemoryStore->FileStore->CompressedStore",Chained!$E:$E,"",Chained!$F:$F,256) -> 1.6473 | C47: =SUMIFS(Chained!$P:$P,Chained!$C:$C,"MemoryStore->FileStore->CompressedStore",Chained!$E:$E,"",Chained!$F:$F,1024) -> 1.6494 | D47: =SUMIFS(Chained!$P:$P,Chained!$C:$C,"MemoryStore->FileStore->CompressedStore",Chained!$E:$E,"",Chained!$F:$F,4096) -> 1.6496 | E47: =SUMIFS(Chained!$P:$P,Chained!$C:$C,"MemoryStore->FileStore->CompressedStore",Chained!$E:$E,"",Chained!$F:$F,16384) -> 1.6487
...

Sheet Dataset
A1: What the solar data looks like
A2: From dataset_analysis.py over the whole 1.49 GB CSV: exact distinct counts via a disk-backed sort, extents and decimal places in one streaming pass.
A4: FACTS
A5: dataset | B5: debs_solar_panels
A6: source_file | B6: large/debs/SOLAR_PANELS_TOPIC_1G.csv
A7: csv_bytes | B7: 1489260482
A8: rows | B8: 42700000
A9: columns | B9: 4
A10: stored_row_width_bytes | B10: 28
A11: stored_bytes_total | B11: 1195600000
A12: truncated | B12: no - the whole shipped file
A13: timestamp_sorted | B13: True
A14: timestamp_distinct_deltas | B14: >4096
A15: timestamp_delta_pattern | B15: irregular - over 4096 distinct deltas, no repeating cycle; min 0, max 743465, mean 40342.3
A16: timestamp_delta_min | B16: 0
A17: timestamp_delta_max | B17: 743465
A18: timestamp_delta_mean | B18: 40342.3
A19: timestamp_range | B19: 1680357514 .. 1724294922528
A21: PER COLUMN
A22: dataset | B22: column | C22: sql_type | D22: payload_bytes | E22: null_indicator_bytes | F22: stored_bytes_per_value | G22: distinct_values | H22: distinct_pct | I22: min | J22: max | K22: decimal_places | L22: quantisable_by_accuracy_bound | M22: example
A23: debs_solar_panels | B23: producerId | C23: INT32 | D23: 4 | E23: 1 | F23: 5 | G23: 42700000 | H23: 100 | I23: 0 | J23: 42699999 | L23: no | M23: 20043650
A24: debs_solar_panels | B24: groupId | C24: INT32 | D24: 4 | E24: 1 | F24: 5 | G24: 4 | H24: 0 | I24: 0 | J24: 3 | L24: no | M24: 0
A25: debs_solar_panels | B25: producedPower | C25: FLOAT64 | D25: 8 | E25: 1 | F25: 9 | G25: 41802464 | H25: 97.9 | I25: 2.5e-05 | J25: 1000 | K25: 1:395/2:3867/3:38507/4:383836/5:3845749/6:38427646 | L25: yes | M25: 931.60384
A26: debs_solar_panels | B26: timestamp | C26: UINT64 | D26: 8 | E26: 1 | F26: 9 | G26: 42699472 | H26: 100 | I26: 1680357514 | J26: 1724294922528 | L26: no | M26: 1680357514
A28: WHY THIS MATTERS FOR COMPRESSION
A29: producerId | B29: 42,700,000 distinct over exactly 0..42,699,999 -- a shuffled permutation of the row numbers. No dictionary, no run length, and delta-of-delta is worse than useless on a shuffled sequence. Bitpacking alone: 32 bits -> 26.
A30: groupId | B30: 4 distinct. Two bits of real information, and the one column that compresses freely.
A31: producedPower | B31: 97.90% distinct at six decimal places. The ONLY quantisable column, so every byte an accuracy bound saves comes out of this one.
A32: timestamp | B32: Monotonic, so deltas are positive -- but over 4096 distinct deltas with no cycle, mean 40,342 and max 743,465. Delta plus bitpack takes 64 bits to about 20.
A33: Against wind | B33: Wind had 26 distinct producerIds and exactly TWO distinct timestamp deltas. That is why its ratios are 2-2.5x these, and why it shows a zigzag that solar does not.

Sheet A2 Chaining Cost
A1: What the tier chain costs
A2: FileStore migrates to the tail once it has accumulated its flush threshold, and keeps the remainder UNCOMPRESSED. That remainder is what a chain costs.
A4: BYTES FILESTORE IS STILL HOLDING, RAW
A5: Read straight off the store files.
A6: Configuration | B6: 256 KB | C6: 1024 KB | D6: 4096 KB | E6: 16384 KB
A7: -> CompressedStore | B7: =SUMIFS(Chained!$AG:$AG,Chained!$C:$C,"MemoryStore->FileStore->CompressedStore",Chained!$E:$E,"",Chained!$F:$F,256) -> 2526160 | C7: =SUMIFS(Chained!$AG:$AG,Chained!$C:$C,"MemoryStore->FileStore->CompressedStore",Chained!$E:$E,"",Chained!$F:$F,1024) -> 2526160 | D7: =SUMIFS(Chained!$AG:$AG,Chained!$C:$C,"MemoryStore->FileStore->CompressedStore",Chained!$E:$E,"",Chained!$F:$F,4096) -> 2526160 | E7: =SUMIFS(Chained!$AG:$AG,Chained!$C:$C,"MemoryStore->FileStore->CompressedStore",Chained!$E:$E,"",Chained!$F:$F,16384) -> 3572716
A8: -> LossyStore lossless | B8: =SUMIFS(Chained!$AG:$AG,Chained!$C:$C,"MemoryStore->FileStore->LossyStore",Chained!$E:$E,"",Chained!$F:$F,256) -> 2526160 | C8: =SUMIFS(Chained!$AG:$AG,Chained!$C:$C,"MemoryStore->FileStore->LossyStore",Chained!$E:$E,"",Chained!$F:$F,1024) -> 2526160 | D8: =SUMIFS(Chained!$AG:$AG,Chained!$C:$C,"MemoryStore->FileStore->LossyStore",Chained!$E:$E,"",Chained!$F:$F,4096) -> 2526160 | E8: =SUMIFS(Chained!$AG:$AG,Chained!$C:$C,"MemoryStore->FileStore->LossyStore",Chained!$E:$E,"",Chained!$F:$F,16384) -> 3572716
A9: -> LossyStore 0.1% | B9: =SUMIFS(Chained!$AG:$AG,Chained!$C:$C,"MemoryStore->FileStore->LossyStore",Chained!$E:$E,0.1,Chained!$F:$F,256) -> 2526160 | C9: =SUMIFS(Chained!$AG:$AG,Chained!$C:$C,"MemoryStore->FileStore->LossyStore",Chained!$E:$E,0.1,Chained!$F:$F,1024) -> 2526160 | D9: =SUMIFS(Chained!$AG:$AG,Chained!$C:$C,"MemoryStore->FileStore->LossyStore",Chained!$E:$E,0.1,Chained!$F:$F,4096) -> 2526160 | E9: =SUMIFS(Chained!$AG:$AG,Chained!$C:$C,"MemoryStore->FileStore->LossyStore",Chained!$E:$E,0.1,Chained!$F:$F,16384) -> 3572716
A10: -> LossyStore 1% | B10: =SUMIFS(Chained!$AG:$AG,Chained!$C:$C,"MemoryStore->FileStore->LossyStore",Chained!$E:$E,1,Chained!$F:$F,256) -> 2526160 | C10: =SUMIFS(Chained!$AG:$AG,Chained!$C:$C,"MemoryStore->FileStore->LossyStore",Chained!$E:$E,1,Chained!$F:$F,1024) -> 2526160 | D10: =SUMIFS(Chained!$AG:$AG,Chained!$C:$C,"MemoryStore->FileStore->LossyStore",Chained!$E:$E,1,Chained!$F:$F,4096) -> 2526160 | E10: =SUMIFS(Chained!$AG:$AG,Chained!$C:$C,"MemoryStore->FileStore->LossyStore",Chained!$E:$E,1,Chained!$F:$F,16384) -> 3572716
A11: -> LossyStore 5% | B11: =SUMIFS(Chained!$AG:$AG,Chained!$C:$C,"MemoryStore->FileStore->LossyStore",Chained!$E:$E,5,Chained!$F:$F,256) -> 2526160 | C11: =SUMIFS(Chained!$AG:$AG,Chained!$C:$C,"MemoryStore->FileStore->LossyStore",Chained!$E:$E,5,Chained!$F:$F,1024) -> 2526160 | D11: =SUMIFS(Chained!$AG:$AG,Chained!$C:$C,"MemoryStore->FileStore->LossyStore",Chained!$E:$E,5,Chained!$F:$F,4096) -> 2526160 | E11: =SUMIFS(Chained!$AG:$AG,Chained!$C:$C,"MemoryStore->FileStore->LossyStore",Chained!$E:$E,5,Chained!$F:$F,16384) -> 3572716
A12: As a share of the whole stream:
A13: Configuration | B13: 256 KB | C13: 1024 KB | D13: 4096 KB | E13: 16384 KB
A14: -> CompressedStore | B14: =B7/1195600000 -> 0.0021128806 | C14: =C7/1195600000 -> 0.0021128806 | D14: =D7/1195600000 -> 0.0021128806 | E14: =E7/1195600000 -> 0.0029882201
A15: -> LossyStore lossless | B15: =B8/1195600000 -> 0.0021128806 | C15: =C8/1195600000 -> 0.0021128806 | D15: =D8/1195600000 -> 0.0021128806 | E15: =E8/1195600000 -> 0.0029882201
A16: -> LossyStore 0.1% | B16: =B9/1195600000 -> 0.0021128806 | C16: =C9/1195600000 -> 0.0021128806 | D16: =D9/1195600000 -> 0.0021128806 | E16: =E9/1195600000 -> 0.0029882201
A17: -> LossyStore 1% | B17: =B10/1195600000 -> 0.0021128806 | C17: =C10/1195600000 -> 0.0021128806 | D17: =D10/1195600000 -> 0.0021128806 | E17: =E10/1195600000 -> 0.0029882201
A18: -> LossyStore 5% | B18: =B11/1195600000 -> 0.0021128806 | C18: =C11/1195600000 -> 0.0021128806 | D18: =D11/1195600000 -> 0.0021128806 | E18: =E11/1195600000 -> 0.0029882201
A20: WHAT THIS SHOWS | B20: The fraction of the 1.2 GB that never reached a compressing tier.
A21: WHAT TO LOOK FOR | B21: Everything is between 0.35% and 0.93%, so the chain compresses essentially all of it. The bars step up at 16384 KB because the leftover is one SEGMENT and the segment got bigger -- not because the chain behaved differently.
A24: CHAINED RATIO / STANDALONE RATIO
A25: 1.000 would mean the chain gave up nothing at all against a single store.
A26: Configuration | B26: 256 KB | C26: 1024 KB | D26: 4096 KB | E26: 16384 KB
A27: -> CompressedStore | B27: =IFERROR((SUMIFS(Chained!$P:$P,Chained!$C:$C,"MemoryStore->FileStore->CompressedStore",Chained!$E:$E,"",Chained!$F:$F,256))/(SUMIFS(Standalone!$P:$P,Standalone!$C:$C,"CompressedStore",Standalone!$E:$E,"",Standalone!$F:$F,256)),0) -> 0.99812167 | C27: =IFERROR((SUMIFS(Chained!$P:$P,Chained!$C:$C,"MemoryStore->FileStore->CompressedStore",Chained!$E:$E,"",Chained!$F:$F,1024))/(SUMIFS(Standalone!$P:$P,Standalone!$C:$C,"CompressedStore",Standalone!$E:$E,"",Standalone!$F:$F,1024)),0) -> 0.9986075 | D27: =IFERROR((SUMIFS(Chained!$P:$P,Chained!$C:$C,"MemoryStore->FileStore->CompressedStore",Chained!$E:$E,"",Chained!$F:$F,4096))/(SUMIFS(Standalone!$P:$P,Standalone!$C:$C,"CompressedStore",Standalone!$E:$E,"",Standalone!$F:$F,4096)),0) -> 0.99860766 | E27: =IFERROR((SUMIFS(Chained!$P:$P,Chained!$C:$C,"MemoryStore->FileStore->CompressedStore",Chained!$E:$E,"",Chained!$F:$F,16384))/(SUMIFS(Standalone!$P:$P,Standalone!$C:$C,"CompressedStore",Standalone!$E:$E,"",Standalone!$F:$F,16384)),0) -> 0.99800242
A28: -> LossyStore lossless | B28: =IFERROR((SUMIFS(Chained!$P:$P,Chained!$C:$C,"MemoryStore->FileStore->LossyStore",Chained!$E:$E,"",Chained!$F:$F,256))/(SUMIFS(Standalone!$P:$P,Standalone!$C:$C,"LossyStore",Standalone!$E:$E,"",Standalone!$F:$F,256)),0) -> 0.99854971 | C28: =IFERROR((SUMIFS(Chained!$P:$P,Chained!$C:$C,"MemoryStore->FileStore->LossyStore",Chained!$E:$E,"",Chained!$F:$F,1024))/(SUMIFS(Standalone!$P:$P,Standalone!$C:$C,"LossyStore",Standalone!$E:$E,"",Standalone!$F:$F,1024)),0) -> 0.99818055 | D28: =IFERROR((SUMIFS(Chained!$P:$P,Chained!$C:$C,"MemoryStore->FileStore->LossyStore",Chained!$E:$E,"",Chained!$F:$F,4096))/(SUMIFS(Standalone!$P:$P,Standalone!$C:$C,"LossyStore",Standalone!$E:$E,"",Standalone!$F:$F,4096)),0) -> 1.0001621 | E28: =IFERROR((SUMIFS(Chained!$P:$P,Chained!$C:$C,"MemoryStore->FileStore->LossyStore",Chained!$E:$E,"",Chained!$F:$F,16384))/(SUMIFS(Standalone!$P:$P,Standalone!$C:$C,"LossyStore",Standalone!$E:$E,"",Standalone!$F:$F,16384)),0) -> 0.99847411
A29: -> LossyStore 0.1% | B29: =IFERROR((SUMIFS(Chained!$P:$P,Chained!$C:$C,"MemoryStore->FileStore->LossyStore",Chained!$E:$E,0.1,Chained!$F:$F,256))/(SUMIFS(Standalone!$P:$P,Standalone!$C:$C,"LossyStore",Standalone!$E:$E,0.1,Standalone!$F:$F,256)),0) -> 0.99610638 | C29: =IFERROR((SUMIFS(Chained!$P:$P,Chained!$C:$C,"MemoryStore->FileStore->LossyStore",Chained!$E:$E,0.1,Chained!$F:$F,1024))/(SUMIFS(Standalone!$P:$P,Standalone!$C:$C,"LossyStore",Standalone!$E:$E,0.1,Standalone!$F:$F,1024)),0) -> 0.99589803 | D29: =IFERROR((SUMIFS(Chained!$P:$P,Chained!$C:$C,"MemoryStore->FileStore->LossyStore",Chained!$E:$E,0.1,Chained!$F:$F,4096))/(SUMIFS(Standalone!$P:$P,Standalone!$C:$C,"LossyStore",Standalone!$E:$E,0.1,Standalone!$F:$F,4096)),0) -> 1.0010083 | E29: =IFERROR((SUMIFS(Chained!$P:$P,Chained!$C:$C,"MemoryStore->FileStore->LossyStore",Chained!$E:$E,0.1,Chained!$F:$F,16384))/(SUMIFS(Standalone!$P:$P,Standalone!$C:$C,"LossyStore",Standalone!$E:$E,0.1,Standalone!$F:$F,16384)),0) -> 0.9969593
A30: -> LossyStore 1% | B30: =IFERROR((SUMIFS(Chained!$P:$P,Chained!$C:$C,"MemoryStore->FileStore->LossyStore",Chained!$E:$E,1,Chained!$F:$F,256))/(SUMIFS(Standalone!$P:$P,Standalone!$C:$C,"LossyStore",Standalone!$E:$E,1,Standalone!$F:$F,256)),0) -> 0.99577874 | C30: =IFERROR((SUMIFS(Chained!$P:$P,Chained!$C:$C,"MemoryStore->FileStore->LossyStore",Chained!$E:$E,1,Chained!$F:$F,1024))/(SUMIFS(Standalone!$P:$P,Standalone!$C:$C,"LossyStore",Standalone!$E:$E,1,Standalone!$F:$F,1024)),0) -> 0.99552104 | D30: =IFERROR((SUMIFS(Chained!$P:$P,Chained!$C:$C,"MemoryStore->FileStore->LossyStore",Chained!$E:$E,1,Chained!$F:$F,4096))/(SUMIFS(Standalone!$P:$P,Standalone!$C:$C,"LossyStore",Standalone!$E:$E,1,Standalone!$F:$F,4096)),0) -> 1.0011936 | E30: =IFERROR((SUMIFS(Chained!$P:$P,Chained!$C:$C,"MemoryStore->FileStore->LossyStore",Chained!$E:$E,1,Chained!$F:$F,16384))/(SUMIFS(Standalone!$P:$P,Standalone!$C:$C,"LossyStore",Standalone!$E:$E,1,Standalone!$F:$F,16384)),0) -> 0.99660184
A31: -> LossyStore 5% | B31: =IFERROR((SUMIFS(Chained!$P:$P,Chained!$C:$C,"MemoryStore->FileStore->LossyStore",Chained!$E:$E,5,Chained!$F:$F,256))/(SUMIFS(Standalone!$P:$P,Standalone!$C:$C,"LossyStore",Standalone!$E:$E,5,Standalone!$F:$F,256)),0) -> 0.99559165 | C31: =IFERROR((SUMIFS(Chained!$P:$P,Chained!$C:$C,"MemoryStore->FileStore->LossyStore",Chained!$E:$E,5,Chained!$F:$F,1024))/(SUMIFS(Standalone!$P:$P,Standalone!$C:$C,"LossyStore",Standalone!$E:$E,5,Standalone!$F:$F,1024)),0) -> 0.99535604 | D31: =IFERROR((SUMIFS(Chained!$P:$P,Chained!$C:$C,"MemoryStore->FileStore->LossyStore",Chained!$E:$E,5,Chained!$F:$F,4096))/(SUMIFS(Standalone!$P:$P,Standalone!$C:$C,"LossyStore",Standalone!$E:$E,5,Standalone!$F:$F,4096)),0) -> 0.99987346 | E31: =IFERROR((SUMIFS(Chained!$P:$P,Chained!$C:$C,"MemoryStore->FileStore->LossyStore",Chained!$E:$E,5,Chained!$F:$F,16384))/(SUMIFS(Standalone!$P:$P,Standalone!$C:$C,"LossyStore",Standalone!$E:$E,5,Standalone!$F:$F,16384)),0) -> 0.99474472
A33: WHAT THIS SHOWS | B33: How much of a single store's compression the three-tier chain keeps.
A34: WHAT TO LOOK FOR | B34: Everything is 0.995 to 1.001, so chaining is free at this scale. On WIND the same figure was 0.67 to 0.87 -- the chain gave up 13-33%. The difference is NOT the code: the flush threshold is a fixed 4 MB, which is 6.6% of wind's 5.6 MB but 0.2% of solar's 1.2 GB. Three cells read slightly ABOVE 1.000, which should be impossible; see Anomaly 3.

Sheet A3 Accuracy and Float
A1: What the accuracy bound buys
A2: The bound reaches floating point columns and nothing else. Here that is exactly one column of four, producedPower.
A4: STANDALONE LOSSYSTORE - ratio by bound
A5: Configuration | B5: 256 KB | C5: 1024 KB | D5: 4096 KB | E5: 16384 KB
A6: LossyStore lossless | B6: =SUMIFS(Standalone!$P:$P,Standalone!$C:$C,"LossyStore",Standalone!$E:$E,"",Standalone!$F:$F,256) -> 1.8617 | C6: =SUMIFS(Standalone!$P:$P,Standalone!$C:$C,"LossyStore",Standalone!$E:$E,"",Standalone!$F:$F,1024) -> 1.8687 | D6: =SUMIFS(Standalone!$P:$P,Standalone!$C:$C,"LossyStore",Standalone!$E:$E,"",Standalone!$F:$F,4096) -> 1.8506 | E6: =SUMIFS(Standalone!$P:$P,Standalone!$C:$C,"LossyStore",Standalone!$E:$E,"",Standalone!$F:$F,16384) -> 1.835
A7: LossyStore 0.1% | B7: =SUMIFS(Standalone!$P:$P,Standalone!$C:$C,"LossyStore",Standalone!$E:$E,0.1,Standalone!$F:$F,256) -> 3.0306 | C7: =SUMIFS(Standalone!$P:$P,Standalone!$C:$C,"LossyStore",Standalone!$E:$E,0.1,Standalone!$F:$F,1024) -> 2.9498 | D7: =SUMIFS(Standalone!$P:$P,Standalone!$C:$C,"LossyStore",Standalone!$E:$E,0.1,Standalone!$F:$F,4096) -> 2.876 | E7: =SUMIFS(Standalone!$P:$P,Standalone!$C:$C,"LossyStore",Standalone!$E:$E,0.1,Standalone!$F:$F,16384) -> 2.8283
A8: LossyStore 1% | B8: =SUMIFS(Standalone!$P:$P,Standalone!$C:$C,"LossyStore",Standalone!$E:$E,1,Standalone!$F:$F,256) -> 3.1981 | C8: =SUMIFS(Standalone!$P:$P,Standalone!$C:$C,"LossyStore",Standalone!$E:$E,1,Standalone!$F:$F,1024) -> 3.1034 | D8: =SUMIFS(Standalone!$P:$P,Standalone!$C:$C,"LossyStore",Standalone!$E:$E,1,Standalone!$F:$F,4096) -> 3.0161 | E8: =SUMIFS(Standalone!$P:$P,Standalone!$C:$C,"LossyStore",Standalone!$E:$E,1,Standalone!$F:$F,16384) -> 2.9722
A9: LossyStore 5% | B9: =SUMIFS(Standalone!$P:$P,Standalone!$C:$C,"LossyStore",Standalone!$E:$E,5,Standalone!$F:$F,256) -> 3.3119 | C9: =SUMIFS(Standalone!$P:$P,Standalone!$C:$C,"LossyStore",Standalone!$E:$E,5,Standalone!$F:$F,1024) -> 3.23 | D9: =SUMIFS(Standalone!$P:$P,Standalone!$C:$C,"LossyStore",Standalone!$E:$E,5,Standalone!$F:$F,4096) -> 3.1611 | E9: =SUMIFS(Standalone!$P:$P,Standalone!$C:$C,"LossyStore",Standalone!$E:$E,5,Standalone!$F:$F,16384) -> 3.1397
A11: WHAT THIS SHOWS | B11: Four lines: lossless, then 0.1%, 1% and 5% error allowances, each across the unit-size sweep.
A12: WHAT TO LOOK FOR | B12: The gap between the lossless line and the others is what quantisation buys -- roughly 1.6x to 1.8x. The lines do not cross, so a wider bound always beats a tighter one at whole-store level. That is NOT true column by column: see the float table below and Anomaly 2.
A14: GAIN OVER LOSSLESS AT THE SAME UNIT SIZE
A15: Bounded ratio divided by the lossless ratio. 1.00 would mean the bound bought nothing.
A16: Configuration | B16: 256 KB | C16: 1024 KB | D16: 4096 KB | E16: 16384 KB
A17: LossyStore 0.1% | B17: =B7/B6 -> 1.627867 | C17: =C7/C6 -> 1.5785305 | D17: =D7/D6 -> 1.5540906 | E17: =E7/E6 -> 1.5413079
A18: LossyStore 1% | B18: =B8/B6 -> 1.7178385 | C18: =C8/C6 -> 1.6607267 | D18: =D8/D6 -> 1.6297957 | E18: =E8/E6 -> 1.6197275
A19: LossyStore 5% | B19: =B9/B6 -> 1.7789655 | C19: =C9/C6 -> 1.7284743 | D19: =D9/D6 -> 1.7081487 | E19: =E9/E6 -> 1.7110082
A22: WHAT THIS SHOWS | B22: How much better each bound is than storing the same data losslessly.
A23: WHAT TO LOOK FOR | B23: The gain SHRINKS as the unit grows -- 1.78x at 256 KB down to 1.71x at 16384 KB for the 5% bound, and the same direction at 0.1% and 1%. Both the lossless and the bounded ratios fall with unit size, but the bounded ones fall faster (-5.2% against -1.4% over the sweep), so quantisation is worth relatively LESS at coarse granularity. That points the same way as Anomaly 1: on this data, small units and tight bounds.
A26: THE FLOAT COLUMN ALONE - producedPower, all 9 bounds
A27: Measured at the DEFAULT unit size, write-only. The three other columns are the control: if a bound moved them, something would be wrong.
A28: bound % | B28: bytes | C28: bytes/row | D28: vs lossless | E28: codec | F28: worst error | G28: error ceiling
A29: 0 | B29: 326573665 | C29: 7.6481 | D29: =IFERROR(B29/B29-1,0) -> 0 | E29: Raw | F29: 0 | G29: =A29/100 -> 0
A30: 0.01 | B30: 86385645 | C30: 2.0231 | D30: =IFERROR(B30/B29-1,0) -> -0.73547884 | E30: Quantized | F30: 9.9999994e-05 | G30: =A30/100 -> 0.0001
A31: 0.1 | B31: 71537477 | C31: 1.6754 | D31: =IFERROR(B31/B29-1,0) -> -0.78094536 | E31: Quantized | F31: 0.00099999997 | G31: =A31/100 -> 0.001
A32: 0.5 | B32: 58908943 | C32: 1.3796 | D32: =IFERROR(B32/B29-1,0) -> -0.81961515 | E32: Quantized | F32: 0.0049999997 | G32: =A32/100 -> 0.005
A33: 1 | B33: 53961312 | C33: 1.2637 | D33: =IFERROR(B33/B29-1,0) -> -0.83476527 | E33: Quantized | F33: 0.0099999996 | G33: =A33/100 -> 0.01
A34: 2 | B34: 41348630 | C34: 0.9684 | D34: =IFERROR(B34/B29-1,0) -> -0.87338651 | E34: Quantized | F34: 0.019999999 | G34: =A34/100 -> 0.02
A35: 5 | B35: 42539407 | C35: 0.9962 | D35: =IFERROR(B35/B29-1,0) -> -0.86974024 | E35: Quantized | F35: 0.049999999 | G35: =A35/100 -> 0.05
A36: 10 | B36: 33928095 | C36: 0.7946 | D36: =IFERROR(B36/B29-1,0) -> -0.89610891 | E36: Quantized | F36: 0.099999995 | G36: =A36/100 -> 0.1
A37: 20 | B37: 30385718 | C37: 0.7116 | D37: =IFERROR(B37/B29-1,0) -> -0.90695601 | E37: Quantized | F37: 0.19999999 | G37: =A37/100 -> 0.2
