Workbook

Sheet Data Description
A1: Replay store compression benchmarks
A2: Every figure below was measured through the real SQL query path, not by calling the stores directly.
A4: Dataset
A5: dataset | B5: debs_wind_turbines
A6: source_file | B6: large/debs/WIND_TURBINES_TOPIC_5M.csv
A7: csv_bytes | B7: 5278962
A8: rows | B8: 200001
A9: columns | B9: 4
A10: stored_row_width_bytes | B10: 28
A11: stored_bytes_total | B11: 5600028
A12: truncated | B12: no - the whole shipped file
A13: timestamp_sorted | B13: True
A14: timestamp_distinct_deltas | B14: 2
A15: timestamp_delta_pattern | B15: 0x133334; 60000x66666
A16: timestamp_range | B16: 1000000000000 .. 1003999960000
A18: Columns
A19: dataset | B19: column | C19: sql_type | D19: payload_bytes | E19: null_indicator_bytes | F19: stored_bytes_per_value | G19: distinct_values | H19: distinct_pct | I19: min | J19: max | K19: decimal_places | L19: quantisable_by_accuracy_bound | M19: example
A20: debs_wind_turbines | B20: producerId | C20: INT32 | D20: 4 | E20: 1 | F20: 5 | G20: 26 | H20: 0.01 | I20: 0 | J20: 25 | L20: no | M20: 6
A21: debs_wind_turbines | B21: groupId | C21: INT32 | D21: 4 | E21: 1 | F21: 5 | G21: 4 | H21: 0 | I21: 0 | J21: 3 | L21: no | M21: 1
A22: debs_wind_turbines | B22: producedPower | C22: FLOAT64 | D22: 8 | E22: 1 | F22: 9 | G22: 80200 | H22: 40.1 | I22: 0.01 | J22: 900 | K22: 1:19865/2:180136 | L22: yes | M22: 725.07
A23: debs_wind_turbines | B23: timestamp | C23: UINT64 | D23: 8 | E23: 1 | F23: 9 | G23: 66667 | H23: 33.33 | I23: 1000000000000 | J23: 1004000000000 | L23: no | M23: 1000000000000
A25: What the measured columns mean
A26: bytes_in | B26: rows x stored row width. Fixed by the schema, so it is the control, not a measurement.
A27: data_out | B27: the encoded data alone, every byte of framing removed -- what the codec produced.
A28: disk_bytes | B28: the file size. For a chain, every tier's files added together.
A29: framing_bytes | B29: disk_bytes - data_out: file headers, preallocated tables, per-unit descriptors.
A30: framing_ratio | B30: framing_bytes / disk_bytes.
A31: ratio_on_data | B31: bytes_in / data_out. Compares codecs without format overhead in the way.
A32: ratio_on_disk | B32: bytes_in / disk_bytes. What the data actually costs to keep.
A33: tail_in_bytes | B33: bytes_in minus what MemoryStore and FileStore are still holding -- the bytes that actually reached the compressing tier. Chained sheet only.
A34: ratio_on_tail | B34: tail_in_bytes / the tail's data. What the codec achieved on what it was GIVEN, with the uncompressed remainder in FileStore taken out. Compare codecs with this; budget a deployment with ratio_on_data.
A35: encode_s | B35: wall time of the write query, median of the repeats.
A36: decode_s | B36: wall time of the read-back query, median of the repeats.
A37: unit_kb | B37: the granule each tier seals on: FileStore segment, LossyStore group, CompressedStore segment.
... A39: green figures | B39: formulas computed by the sheet; black figures are measurements.
A41: Caveats that affect how these read
A42: decode_s measures the unit size against a FIXED 4 KB read buffer, not the unit size alone. CompressedStore re-decompresses a whole segment per read() call, so a 1 MB segment is decompressed 257 times to fill 4 KB buffers. Given a larger destination it decodes in 0.47 s.
A43: LossyStore's size is not monotonic in unit size on this dataset. The timestamp column uses ForBitpack, its bit width tracks the group's span, and this data's period-3 delta pattern aligns to a byte boundary only at certain widths. It is an artifact of this data's regularity, so the 16 KB result should not be read as a recommendation.
A44: Wind turbine data is unusually compressible: 2 distinct timestamp deltas, 40% repeated floats. Treat its ratios as a best case.
A45: A CHAIN does not compress everything. FileStore migrates once it has accumulated its flush threshold, 4 MB here, and keeps the sub-threshold remainder -- 367,248 bytes, 6.6% of the stream -- uncompressed. ratio_on_data counts that remainder and is what the chain costs; ratio_on_tail excludes it and is what the codec did.
...

Sheet Standalone
A1: store_order | B1: bound_pct | C1: unit_kb | D1: filestore_segment_kb | E1: lossystore_group_kb | F1: compressedstore_segment_kb | G1: filestore_flush_threshold_kb | H1: flush_threshold | I1: rows | J1: row_width_bytes | K1: bytes_in | L1: encode_s | M1: decode_s | N1: data_out | O1: disk_bytes | P1: framing_bytes | Q1: framing_ratio | R1: ratio_on_data | S1: ratio_on_disk | T1: units | U1: runs
A2: CompressedStore | C2: 16 | D2: 16 | E2: 16 | F2: 16 | G2: 4096 | H2: 1MB | I2: 200001 | J2: 28 | K2: =I2*J2 -> 5600028 | L2: 0.7031 | M2: 0.4097 | N2: 1768681 | O2: 1783081 | P2: =IF(O2=0,0,O2-N2) -> 14400 | Q2: =IFERROR(P2/O2,0) -> 0.0080759091 | R2: =IFERROR(K2/N2,0) -> 3.1662171 | S2: =IFERROR(K2/O2,0) -> 3.140647 | T2: 342 | U2: 3
A3: LossyStore | C3: 16 | D3: 16 | E3: 16 | F3: 16 | G3: 4096 | H3: 1MB | I3: 200001 | J3: 28 | K3: =I3*J3 -> 5600028 | L3: 0.7157 | M3: 0.4167 | N3: 1206685 | O3: 1287775 | P3: =IF(O3=0,0,O3-N3) -> 81090 | Q3: =IFERROR(P3/O3,0) -> 0.062969075 | R3: =IFERROR(K3/N3,0) -> 4.6408367 | S3: =IFERROR(K3/O3,0) -> 4.3486075 | T3: 342 | U3: 3
A4: LossyStore | B4: 0.1 | C4: 16 | D4: 16 | E4: 16 | F4: 16 | G4: 4096 | H4: 1MB | I4: 200001 | J4: 28 | K4: =I4*J4 -> 5600028 | L4: 0.7184 | M4: 0.4371 | N4: 808854 | O4: 889944 | P4: =IF(O4=0,0,O4-N4) -> 81090 | Q4: =IFERROR(P4/O4,0) -> 0.091118093 | R4: =IFERROR(K4/N4,0) -> 6.9234102 | S4: =IFERROR(K4/O4,0) -> 6.2925622 | T4: 342 | U4: 3
A5: LossyStore | B5: 1 | C5: 16 | D5: 16 | E5: 16 | F5: 16 | G5: 4096 | H5: 1MB | I5: 200001 | J5: 28 | K5: =I5*J5 -> 5600028 | L5: 0.695 | M5: 0.4221 | N5: 730085 | O5: 811175 | P5: =IF(O5=0,0,O5-N5) -> 81090 | Q5: =IFERROR(P5/O5,0) -> 0.099966099 | R5: =IFERROR(K5/N5,0) -> 7.6703781 | S5: =IFERROR(K5/O5,0) -> 6.9036003 | T5: 342 | U5: 3
A6: LossyStore | B6: 5 | C6: 16 | D6: 16 | E6: 16 | F6: 16 | G6: 4096 | H6: 1MB | I6: 200001 | J6: 28 | K6: =I6*J6 -> 5600028 | L6: 0.7438 | M6: 0.4027 | N6: 672699 | O6: 753789 | P6: =IF(O6=0,0,O6-N6) -> 81090 | Q6: =IFERROR(P6/O6,0) -> 0.10757652 | R6: =IFERROR(K6/N6,0) -> 8.3247158 | S6: =IFERROR(K6/O6,0) -> 7.4291718 | T6: 342 | U6: 3
A7: MemoryStore | C7: 16 | D7: 16 | E7: 16 | F7: 16 | G7: 4096 | H7: 1MB | I7: 200001 | J7: 28 | K7: =I7*J7 -> 5600028 | L7: 0.6759 | M7: 0.4095 | N7: 5600028 | O7: 0 | P7: =IF(O7=0,0,O7-N7) -> 0 | Q7: =IFERROR(P7/O7,0) -> 0 | R7: =IFERROR(K7/N7,0) -> 1 | S7: =IFERROR(K7/O7,0) -> 0 | T7: 0 | U7: 3
A8: FileStore | C8: 16 | D8: 16 | E8: 16 | F8: 16 | G8: 4096 | H8: 1MB | I8: 200001 | J8: 28 | K8: =I8*J8 -> 5600028 | L8: 0.6804 | M8: 0.399 | N8: 5600028 | O8: 5621264 | P8: =IF(O8=0,0,O8-N8) -> 21236 | Q8: =IFERROR(P8/O8,0) -> 0.003777798 | R8: =IFERROR(K8/N8,0) -> 1 | S8: =IFERROR(K8/O8,0) -> 0.9962222 | T8: 342 | U8: 3
A9: CompressedStore | C9: 64 | D9: 64 | E9: 64 | F9: 64 | G9: 4096 | H9: 1MB | I9: 200001 | J9: 28 | K9: =I9*J9 -> 5600028 | L9: 0.7695 | M9: 0.4426 | N9: 1719557 | O9: 1723461 | P9: =IF(O9=0,0,O9-N9) -> 3904 | Q9: =IFERROR(P9/O9,0) -> 0.0022652094 | R9: =IFERROR(K9/N9,0) -> 3.256669 | S9: =IFERROR(K9/O9,0) -> 3.249292 | T9: 86 | U9: 3
A10: LossyStore | C10: 64 | D10: 64 | E10: 64 | F10: 64 | G10: 4096 | H10: 1MB | I10: 200001 | J10: 28 | K10: =I10*J10 -> 5600028 | L10: 0.6977 | M10: 0.4176 | N10: 1499024 | O10: 1519698 | P10: =IF(O10=0,0,O10-N10) -> 20674 | Q10: =IFERROR(P10/O10,0) -> 0.013604019 | R10: =IFERROR(K10/N10,0) -> 3.7357827 | S10: =IFERROR(K10/O10,0) -> 3.6849611 | T10: 86 | U10: 3
A11: LossyStore | B11: 0.1 | C11: 64 | D11: 64 | E11: 64 | F11: 64 | G11: 4096 | H11: 1MB | I11: 200001 | J11: 28 | K11: =I11*J11 -> 5600028 | L11: 0.7177 | M11: 0.4269 | N11: 1136554 | O11: 1157228 | P11: =IF(O11=0,0,O11-N11) -> 20674 | Q11: =IFERROR(P11/O11,0) -> 0.017865105 | R11: =IFERROR(K11/N11,0) -> 4.9271992 | S11: =IFERROR(K11/O11,0) -> 4.8391743 | T11: 86 | U11: 3
A12: LossyStore | B12: 1 | C12: 64 | D12: 64 | E12: 64 | F12: 64 | G12: 4096 | H12: 1MB | I12: 200001 | J12: 28 | K12: =I12*J12 -> 5600028 | L12: 0.6953 | M12: 0.426 | N12: 1053788 | O12: 1074462 | P12: =IF(O12=0,0,O12-N12) -> 20674 | Q12: =IFERROR(P12/O12,0) -> 0.019241257 | R12: =IFERROR(K12/N12,0) -> 5.3141884 | S12: =IFERROR(K12/O12,0) -> 5.2119368 | T12: 86 | U12: 3
A13: LossyStore | B13: 5 | C13: 64 | D13: 64 | E13: 64 | F13: 64 | G13: 4096 | H13: 1MB | I13: 200001 | J13: 28 | K13: =I13*J13 -> 5600028 | L13: 0.7093 | M13: 0.4334 | N13: 1000058 | O13: 1020732 | P13: =IF(O13=0,0,O13-N13) -> 20674 | Q13: =IFERROR(P13/O13,0) -> 0.020254092 | R13: =IFERROR(K13/N13,0) -> 5.5997032 | S13: =IFERROR(K13/O13,0) -> 5.4862863 | T13: 86 | U13: 3
A14: MemoryStore | C14: 64 | D14: 64 | E14: 64 | F14: 64 | G14: 4096 | H14: 1MB | I14: 200001 | J14: 28 | K14: =I14*J14 -> 5600028 | L14: 0.6934 | M14: 0.4331 | N14: 5600028 | O14: 0 | P14: =IF(O14=0,0,O14-N14) -> 0 | Q14: =IFERROR(P14/O14,0) -> 0 | R14: =IFERROR(K14/N14,0) -> 1 | S14: =IFERROR(K14/O14,0) -> 0 | T14: 0 | U14: 3
A15: FileStore | C15: 64 | D15: 64 | E15: 64 | F15: 64 | G15: 4096 | H15: 1MB | I15: 200001 | J15: 28 | K15: =I15*J15 -> 5600028 | L15: 0.6688 | M15: 0.4381 | N15: 5600028 | O15: 5605904 | P15: =IF(O15=0,0,O15-N15) -> 5876 | Q15: =IFERROR(P15/O15,0) -> 0.0010481806 | R15: =IFERROR(K15/N15,0) -> 1 | S15: =IFERROR(K15/O15,0) -> 0.99895182 | T15: 86 | U15: 3
A16: CompressedStore | C16: 256 | D16: 256 | E16: 256 | F16: 256 | G16: 4096 | H16: 1MB | I16: 200001 | J16: 28 | K16: =I16*J16 -> 5600028 | L16: 0.6936 | M16: 0.5869 | N16: 1713493 | O16: 1714773 | P16: =IF(O16=0,0,O16-N16) -> 1280 | Q16: =IFERROR(P16/O16,0) -> 0.00074645449 | R16: =IFERROR(K16/N16,0) -> 3.2681943 | S16: =IFERROR(K16/O16,0) -> 3.2657547 | T16: 22 | U16: 3
A17: LossyStore | C17: 256 | D17: 256 | E17: 256 | F17: 256 | G17: 4096 | H17: 1MB | I17: 200001 | J17: 28 | K17: =I17*J17 -> 5600028 | L17: 0.7072 | M17: 0.7512 | N17: 1365416 | O17: 1370986 | P17: =IF(O17=0,0,O17-N17) -> 5570 | Q17: =IFERROR(P17/O17,0) -> 0.0040627694 | R17: =IFERROR(K17/N17,0) -> 4.1013347 | S17: =IFERROR(K17/O17,0) -> 4.0846719 | T17: 22 | U17: 3
A18: LossyStore | B18: 0.1 | C18: 256 | D18: 256 | E18: 256 | F18: 256 | G18: 4096 | H18: 1MB | I18: 200001 | J18: 28 | K18: =I18*J18 -> 5600028 | L18: 0.7142 | M18: 0.8139 | N18: 1018407 | O18: 1023977 | P18: =IF(O18=0,0,O18-N18) -> 5570 | Q18: =IFERROR(P18/O18,0) -> 0.0054395753 | R18: =IFERROR(K18/N18,0) -> 5.4988114 | S18: =IFERROR(K18/O18,0) -> 5.4689002 | T18: 22 | U18: 3
A19: LossyStore | B19: 1 | C19: 256 | D19: 256 | E19: 256 | F19: 256 | G19: 4096 | H19: 1MB | I19: 200001 | J19: 28 | K19: =I19*J19 -> 5600028 | L19: 0.717 | M19: 0.8083 | N19: 920140 | O19: 925710 | P19: =IF(O19=0,0,O19-N19) -> 5570 | Q19: =IFERROR(P19/O19,0) -> 0.0060170032 | R19: =IFERROR(K19/N19,0) -> 6.0860608 | S19: =IFERROR(K19/O19,0) -> 6.049441 | T19: 22 | U19: 3
A20: LossyStore | B20: 5 | C20: 256 | D20: 256 | E20: 256 | F20: 256 | G20: 4096 | H20: 1MB | I20: 200001 | J20: 28 | K20: =I20*J20 -> 5600028 | L20: 0.7075 | M20: 0.8157 | N20: 861047 | O20: 866617 | P20: =IF(O20=0,0,O20-N20) -> 5570 | Q20: =IFERROR(P20/O20,0) -> 0.0064272914 | R20: =IFERROR(K20/N20,0) -> 6.5037425 | S20: =IFERROR(K20/O20,0) -> 6.4619411 | T20: 22 | U20: 3
A21: MemoryStore | C21: 256 | D21: 256 | E21: 256 | F21: 256 | G21: 4096 | H21: 1MB | I21: 200001 | J21: 28 | K21: =I21*J21 -> 5600028 | L21: 0.7453 | M21: 0.4162 | N21: 5600028 | O21: 0 | P21: =IF(O21=0,0,O21-N21) -> 0 | Q21: =IFERROR(P21/O21,0) -> 0 | R21: =IFERROR(K21/N21,0) -> 1 | S21: =IFERROR(K21/O21,0) -> 0 | T21: 0 | U21: 3
A22: FileStore | C22: 256 | D22: 256 | E22: 256 | F22: 256 | G22: 4096 | H22: 1MB | I22: 200001 | J22: 28 | K22: =I22*J22 -> 5600028 | L22: 0.7324 | M22: 0.431 | N22: 5600028 | O22: 5602064 | P22: =IF(O22=0,0,O22-N22) -> 2036 | Q22: =IFERROR(P22/O22,0) -> 0.00036343748 | R22: =IFERROR(K22/N22,0) -> 1 | S22: =IFERROR(K22/O22,0) -> 0.99963656 | T22: 22 | U22: 3
A23: CompressedStore | C23: 1024 | D23: 1024 | E23: 1024 | F23: 1024 | G23: 4096 | H23: 1MB | I23: 200001 | J23: 28 | K23: =I23*J23 -> 5600028 | L23: 0.6715 | M23: 2.1232 | N23: 1714576 | O23: 1715200 | P23: =IF(O23=0,0,O23-N23) -> 624 | Q23: =IFERROR(P23/O23,0) -> 0.00036380597 | R23: =IFERROR(K23/N23,0) -> 3.2661299 | S23: =IFERROR(K23/O23,0) -> 3.2649417 | T23: 6 | U23: 3
A24: LossyStore | C24: 1024 | D24: 1024 | E24: 1024 | F24: 1024 | G24: 4096 | H24: 1MB | I24: 200001 | J24: 28 | K24: =I24*J24 -> 5600028 | L24: 0.6909 | M24: 2.8006 | N24: 1560562 | O24: 1562356 | P24: =IF(O24=0,0,O24-N24) -> 1794 | Q24: =IFERROR(P24/O24,0) -> 0.0011482658 | R24: =IFERROR(K24/N24,0) -> 3.5884688 | S24: =IFERROR(K24/O24,0) -> 3.5843483 | T24: 6 | U24: 3
A25: LossyStore | B25: 0.1 | C25: 1024 | D25: 1024 | E25: 1024 | F25: 1024 | G25: 4096 | H25: 1MB | I25: 200001 | J25: 28 | K25: =I25*J25 -> 5600028 | L25: 0.6916 | M25: 2.7759 | N25: 1213496 | O25: 1215290 | P25: =IF(O25=0,0,O25-N25) -> 1794 | Q25: =IFERROR(P25/O25,0) -> 0.0014761909 | R25: =IFERROR(K25/N25,0) -> 4.614789 | S25: =IFERROR(K25/O25,0) -> 4.6079767 | T25: 6 | U25: 3
A26: LossyStore | B26: 1 | C26: 1024 | D26: 1024 | E26: 1024 | F26: 1024 | G26: 4096 | H26: 1MB | I26: 200001 | J26: 28 | K26: =I26*J26 -> 5600028 | L26: 0.6803 | M26: 2.8354 | N26: 1120901 | O26: 1122695 | P26: =IF(O26=0,0,O26-N26) -> 1794 | Q26: =IFERROR(P26/O26,0) -> 0.0015979407 | R26: =IFERROR(K26/N26,0) -> 4.9960059 | S26: =IFERROR(K26/O26,0) -> 4.9880226 | T26: 6 | U26: 3
A27: LossyStore | B27: 5 | C27: 1024 | D27: 1024 | E27: 1024 | F27: 1024 | G27: 4096 | H27: 1MB | I27: 200001 | J27: 28 | K27: =I27*J27 -> 5600028 | L27: 0.6819 | M27: 2.8947 | N27: 1051816 | O27: 1053610 | P27: =IF(O27=0,0,O27-N27) -> 1794 | Q27: =IFERROR(P27/O27,0) -> 0.0017027173 | R27: =IFERROR(K27/N27,0) -> 5.3241518 | S27: =IFERROR(K27/O27,0) -> 5.3150862 | T27: 6 | U27: 3
A28: MemoryStore | C28: 1024 | D28: 1024 | E28: 1024 | F28: 1024 | G28: 4096 | H28: 1MB | I28: 200001 | J28: 28 | K28: =I28*J28 -> 5600028 | L28: 0.653 | M28: 0.4373 | N28: 5600028 | O28: 0 | P28: =IF(O28=0,0,O28-N28) -> 0 | Q28: =IFERROR(P28/O28,0) -> 0 | R28: =IFERROR(K28/N28,0) -> 1 | S28: =IFERROR(K28/O28,0) -> 0 | T28: 0 | U28: 3
A29: FileStore | C29: 1024 | D29: 1024 | E29: 1024 | F29: 1024 | G29: 4096 | H29: 1MB | I29: 200001 | J29: 28 | K29: =I29*J29 -> 5600028 | L29: 0.6875 | M29: 0.4065 | N29: 5600028 | O29: 5601104 | P29: =IF(O29=0,0,O29-N29) -> 1076 | Q29: =IFERROR(P29/O29,0) -> 0.00019210499 | R29: =IFERROR(K29/N29,0) -> 1 | S29: =IFERROR(K29/O29,0) -> 0.9998079 | T29: 6 | U29: 3
A30: CompressedStore | C30: 4096 | D30: 4096 | E30: 4096 | F30: 4096 | G30: 4096 | H30: 1MB | I30: 200001 | J30: 28 | K30: =I30*J30 -> 5600028 | L30: 0.6797 | M30: 7.5978 | N30: 1712535 | O30: 1712995 | P30: =IF(O30=0,0,O30-N30) -> 460 | Q30: =IFERROR(P30/O30,0) -> 0.00026853552 | R30: =IFERROR(K30/N30,0) -> 3.2700225 | S30: =IFERROR(K30/O30,0) -> 3.2691444 | T30: 2 | U30: 3
A31: LossyStore | C31: 4096 | D31: 4096 | E31: 4096 | F31: 4096 | G31: 4096 | H31: 1MB | I31: 200001 | J31: 28 | K31: =I31*J31 -> 5600028 | L31: 0.7017 | M31: 10.9161 | N31: 1245607 | O31: 1246457 | P31: =IF(O31=0,0,O31-N31) -> 850 | Q31: =IFERROR(P31/O31,0) -> 0.00068193287 | R31: =IFERROR(K31/N31,0) -> 4.4958225 | S31: =IFERROR(K31/O31,0) -> 4.4927567 | T31: 2 | U31: 3
A32: LossyStore | B32: 0.1 | C32: 4096 | D32: 4096 | E32: 4096 | F32: 4096 | G32: 4096 | H32: 1MB | I32: 200001 | J32: 28 | K32: =I32*J32 -> 5600028 | L32: 0.6805 | M32: 11.3982 | N32: 897067 | O32: 897917 | P32: =IF(O32=0,0,O32-N32) -> 850 | Q32: =IFERROR(P32/O32,0) -> 0.00094663538 | R32: =IFERROR(K32/N32,0) -> 6.2425973 | S32: =IFERROR(K32/O32,0) -> 6.2366878 | T32: 2 | U32: 3
A33: LossyStore | B33: 1 | C33: 4096 | D33: 4096 | E33: 4096 | F33: 4096 | G33: 4096 | H33: 1MB | I33: 200001 | J33: 28 | K33: =I33*J33 -> 5600028 | L33: 0.6573 | M33: 13.3751 | N33: 807007 | O33: 807857 | P33: =IF(O33=0,0,O33-N33) -> 850 | Q33: =IFERROR(P33/O33,0) -> 0.0010521664 | R33: =IFERROR(K33/N33,0) -> 6.9392558 | S33: =IFERROR(K33/O33,0) -> 6.9319545 | T33: 2 | U33: 3
A34: LossyStore | B34: 5 | C34: 4096 | D34: 4096 | E34: 4096 | F34: 4096 | G34: 4096 | H34: 1MB | I34: 200001 | J34: 28 | K34: =I34*J34 -> 5600028 | L34: 0.6817 | M34: 11.3411 | N34: 735159 | O34: 736009 | P34: =IF(O34=0,0,O34-N34) -> 850 | Q34: =IFERROR(P34/O34,0) -> 0.0011548772 | R34: =IFERROR(K34/N34,0) -> 7.6174379 | S34: =IFERROR(K34/O34,0) -> 7.6086407 | T34: 2 | U34: 3
A35: MemoryStore | C35: 4096 | D35: 4096 | E35: 4096 | F35: 4096 | G35: 4096 | H35: 1MB | I35: 200001 | J35: 28 | K35: =I35*J35 -> 5600028 | L35: 0.6585 | M35: 0.427 | N35: 5600028 | O35: 0 | P35: =IF(O35=0,0,O35-N35) -> 0 | Q35: =IFERROR(P35/O35,0) -> 0 | R35: =IFERROR(K35/N35,0) -> 1 | S35: =IFERROR(K35/O35,0) -> 0 | T35: 0 | U35: 3
A36: FileStore | C36: 4096 | D36: 4096 | E36: 4096 | F36: 4096 | G36: 4096 | H36: 1MB | I36: 200001 | J36: 28 | K36: =I36*J36 -> 5600028 | L36: 0.6623 | M36: 0.4198 | N36: 5600028 | O36: 5600864 | P36: =IF(O36=0,0,O36-N36) -> 836 | Q36: =IFERROR(P36/O36,0) -> 0.00014926269 | R36: =IFERROR(K36/N36,0) -> 1 | S36: =IFERROR(K36/O36,0) -> 0.99985074 | T36: 2 | U36: 3

Sheet Chained
A1: store_order | B1: bound_pct | C1: unit_kb | D1: filestore_segment_kb | E1: lossystore_group_kb | F1: compressedstore_segment_kb | G1: filestore_flush_threshold_kb | H1: flush_threshold | I1: rows | J1: row_width_bytes | K1: bytes_in | L1: encode_s | M1: decode_s | N1: data_out | O1: disk_bytes | P1: framing_bytes | Q1: framing_ratio | R1: ratio_on_data | S1: ratio_on_disk | T1: tail_in_bytes | U1: ratio_on_tail | V1: units | W1: runs | X1: MemoryStore_data | Y1: MemoryStore_disk | Z1: FileStore_data | AA1: FileStore_disk | AB1: CompressedStore_data | AC1: CompressedStore_disk | AD1: LossyStore_data | AE1: LossyStore_disk
A2: MemoryStore->FileStore->CompressedStore | C2: 16 | D2: 16 | E2: 16 | F2: 16 | G2: 4096 | H2: 1MB | I2: 200001 | J2: 28 | K2: =I2*J2 -> 5600028 | L2: 0.8098 | M2: 0.4267 | N2: 2007323 | O2: 2028856 | P2: =IF(O2=0,0,O2-N2) -> 21533 | Q2: =IFERROR(P2/O2,0) -> 0.01061337 | R2: =IFERROR(K2/N2,0) -> 2.7897992 | S2: =IFERROR(K2/O2,0) -> 2.76019 | T2: =K2-X2-Z2 -> 5232780 | U2: =IFERROR(T2/(AB2+AD2),0) -> 3.1905736 | V2: 275 | W2: 3 | Z2: 367248 | AA2: 377866 | AB2: 1640075 | AC2: 1650990
A3: MemoryStore->FileStore->LossyStore | C3: 16 | D3: 16 | E3: 16 | F3: 16 | G3: 4096 | H3: 1MB | I3: 200001 | J3: 28 | K3: =I3*J3 -> 5600028 | L3: 0.7906 | M3: 0.4572 | N3: 1476829 | O3: 1548477 | P3: =IF(O3=0,0,O3-N3) -> 71648 | Q3: =IFERROR(P3/O3,0) -> 0.04626998 | R3: =IFERROR(K3/N3,0) -> 3.7919272 | S3: =IFERROR(K3/O3,0) -> 3.6164748 | T3: =K3-X3-Z3 -> 5232780 | U3: =IFERROR(T3/(AB3+AD3),0) -> 4.7159964 | V3: 275 | W3: 3 | Z3: 367248 | AA3: 377866 | AD3: 1109581 | AE3: 1170611
A4: MemoryStore->FileStore->LossyStore | B4: 0.1 | C4: 16 | D4: 16 | E4: 16 | F4: 16 | G4: 4096 | H4: 1MB | I4: 200001 | J4: 28 | K4: =I4*J4 -> 5600028 | L4: 0.738 | M4: 0.4081 | N4: 1111309 | O4: 1182957 | P4: =IF(O4=0,0,O4-N4) -> 71648 | Q4: =IFERROR(P4/O4,0) -> 0.060566868 | R4: =IFERROR(K4/N4,0) -> 5.0391277 | S4: =IFERROR(K4/O4,0) -> 4.7339235 | T4: =K4-X4-Z4 -> 5232780 | U4: =IFERROR(T4/(AB4+AD4),0) -> 7.0327298 | V4: 275 | W4: 3 | Z4: 367248 | AA4: 377866 | AD4: 744061 | AE4: 805091
A5: MemoryStore->FileStore->LossyStore | B5: 1 | C5: 16 | D5: 16 | E5: 16 | F5: 16 | G5: 4096 | H5: 1MB | I5: 200001 | J5: 28 | K5: =I5*J5 -> 5600028 | L5: 0.6896 | M5: 0.4378 | N5: 1037711 | O5: 1109359 | P5: =IF(O5=0,0,O5-N5) -> 71648 | Q5: =IFERROR(P5/O5,0) -> 0.064585044 | R5: =IFERROR(K5/N5,0) -> 5.3965198 | S5: =IFERROR(K5/O5,0) -> 5.0479854 | T5: =K5-X5-Z5 -> 5232780 | U5: =IFERROR(T5/(AB5+AD5),0) -> 7.804726 | V5: 275 | W5: 3 | Z5: 367248 | AA5: 377866 | AD5: 670463 | AE5: 731493
A6: MemoryStore->FileStore->LossyStore | B6: 5 | C6: 16 | D6: 16 | E6: 16 | F6: 16 | G6: 4096 | H6: 1MB | I6: 200001 | J6: 28 | K6: =I6*J6 -> 5600028 | L6: 0.8259 | M6: 0.4572 | N6: 985610 | O6: 1057258 | P6: =IF(O6=0,0,O6-N6) -> 71648 | Q6: =IFERROR(P6/O6,0) -> 0.067767754 | R6: =IFERROR(K6/N6,0) -> 5.6817889 | S6: =IFERROR(K6/O6,0) -> 5.2967469 | T6: =K6-X6-Z6 -> 5232780 | U6: =IFERROR(T6/(AB6+AD6),0) -> 8.4623247 | V6: 275 | W6: 3 | Z6: 367248 | AA6: 377866 | AD6: 618362 | AE6: 679392
A7: MemoryStore->FileStore->CompressedStore | C7: 64 | D7: 64 | E7: 64 | F7: 64 | G7: 4096 | H7: 1MB | I7: 200001 | J7: 28 | K7: =I7*J7 -> 5600028 | L7: 0.6931 | M7: 0.4137 | N7: 1973692 | O7: 1980124 | P7: =IF(O7=0,0,O7-N7) -> 6432 | Q7: =IFERROR(P7/O7,0) -> 0.0032482814 | R7: =IFERROR(K7/N7,0) -> 2.8373363 | S7: =IFERROR(K7/O7,0) -> 2.8281199 | T7: =K7-X7-Z7 -> 5232780 | U7: =IFERROR(T7/(AB7+AD7),0) -> 3.2573684 | V7: 82 | W7: 3 | Z7: 367248 | AA7: 370186 | AB7: 1606444 | AC7: 1609938
A8: MemoryStore->FileStore->LossyStore | C8: 64 | D8: 64 | E8: 64 | F8: 64 | G8: 4096 | H8: 1MB | I8: 200001 | J8: 28 | K8: =I8*J8 -> 5600028 | L8: 0.7005 | M8: 0.4227 | N8: 1766946 | O8: 1788198 | P8: =IF(O8=0,0,O8-N8) -> 21252 | Q8: =IFERROR(P8/O8,0) -> 0.01188459 | R8: =IFERROR(K8/N8,0) -> 3.1693261 | S8: =IFERROR(K8/O8,0) -> 3.1316599 | T8: =K8-X8-Z8 -> 5232780 | U8: =IFERROR(T8/(AB8+AD8),0) -> 3.7385064 | V8: 82 | W8: 3 | Z8: 367248 | AA8: 370186 | AD8: 1399698 | AE8: 1418012
A9: MemoryStore->FileStore->LossyStore | B9: 0.1 | C9: 64 | D9: 64 | E9: 64 | F9: 64 | G9: 4096 | H9: 1MB | I9: 200001 | J9: 28 | K9: =I9*J9 -> 5600028 | L9: 0.6785 | M9: 0.4285 | N9: 1428231 | O9: 1449483 | P9: =IF(O9=0,0,O9-N9) -> 21252 | Q9: =IFERROR(P9/O9,0) -> 0.014661779 | R9: =IFERROR(K9/N9,0) -> 3.920954 | S9: =IFERROR(K9/O9,0) -> 3.8634658 | T9: =K9-X9-Z9 -> 5232780 | U9: =IFERROR(T9/(AB9+AD9),0) -> 4.9320112 | V9: 82 | W9: 3 | Z9: 367248 | AA9: 370186 | AD9: 1060983 | AE9: 1079297
A10: MemoryStore->FileStore->LossyStore | B10: 1 | C10: 64 | D10: 64 | E10: 64 | F10: 64 | G10: 4096 | H10: 1MB | I10: 200001 | J10: 28 | K10: =I10*J10 -> 5600028 | L10: 0.721 | M10: 0.43 | N10: 1351087 | O10: 1372339 | P10: =IF(O10=0,0,O10-N10) -> 21252 | Q10: =IFERROR(P10/O10,0) -> 0.01548597 | R10: =IFERROR(K10/N10,0) -> 4.1448315 | S10: =IFERROR(K10/O10,0) -> 4.0806448 | T10: =K10-X10-Z10 -> 5232780 | U10: =IFERROR(T10/(AB10+AD10),0) -> 5.3187361 | V10: 82 | W10: 3 | Z10: 367248 | AA10: 370186 | AD10: 983839 | AE10: 1002153
A11: MemoryStore->FileStore->LossyStore | B11: 5 | C11: 64 | D11: 64 | E11: 64 | F11: 64 | G11: 4096 | H11: 1MB | I11: 200001 | J11: 28 | K11: =I11*J11 -> 5600028 | L11: 0.7187 | M11: 0.4455 | N11: 1300852 | O11: 1322104 | P11: =IF(O11=0,0,O11-N11) -> 21252 | Q11: =IFERROR(P11/O11,0) -> 0.016074378 | R11: =IFERROR(K11/N11,0) -> 4.3048925 | S11: =IFERROR(K11/O11,0) -> 4.235694 | T11: =K11-X11-Z11 -> 5232780 | U11: =IFERROR(T11/(AB11+AD11),0) -> 5.6049246 | V11: 82 | W11: 3 | Z11: 367248 | AA11: 370186 | AD11: 933604 | AE11: 951918
A12: MemoryStore->FileStore->CompressedStore | C12: 256 | D12: 256 | E12: 256 | F12: 256 | G12: 4096 | H12: 1MB | I12: 200001 | J12: 28 | K12: =I12*J12 -> 5600028 | L12: 0.7665 | M12: 0.5411 | N12: 1970269 | O12: 1972485 | P12: =IF(O12=0,0,O12-N12) -> 2216 | Q12: =IFERROR(P12/O12,0) -> 0.0011234559 | R12: =IFERROR(K12/N12,0) -> 2.8422657 | S12: =IFERROR(K12/O12,0) -> 2.8390725 | T12: =K12-X12-Z12 -> 5232780 | U12: =IFERROR(T12/(AB12+AD12),0) -> 3.264324 | V12: 22 | W12: 3 | Z12: 367248 | AA12: 368266 | AB12: 1603021 | AC12: 1604219
A13: MemoryStore->FileStore->LossyStore | C13: 256 | D13: 256 | E13: 256 | F13: 256 | G13: 4096 | H13: 1MB | I13: 200001 | J13: 28 | K13: =I13*J13 -> 5600028 | L13: 0.7332 | M13: 0.7253 | N13: 1640906 | O13: 1647022 | P13: =IF(O13=0,0,O13-N13) -> 6116 | Q13: =IFERROR(P13/O13,0) -> 0.0037133687 | R13: =IFERROR(K13/N13,0) -> 3.4127659 | S13: =IFERROR(K13/O13,0) -> 3.400093 | T13: =K13-X13-Z13 -> 5232780 | U13: =IFERROR(T13/(AB13+AD13),0) -> 4.1084655 | V13: 22 | W13: 3 | Z13: 367248 | AA13: 368266 | AD13: 1273658 | AE13: 1278756
A14: MemoryStore->FileStore->LossyStore | B14: 0.1 | C14: 256 | D14: 256 | E14: 256 | F14: 256 | G14: 4096 | H14: 1MB | I14: 200001 | J14: 28 | K14: =I14*J14 -> 5600028 | L14: 0.7297 | M14: 0.7409 | N14: 1317019 | O14: 1323135 | P14: =IF(O14=0,0,O14-N14) -> 6116 | Q14: =IFERROR(P14/O14,0) -> 0.0046223552 | R14: =IFERROR(K14/N14,0) -> 4.252048 | S14: =IFERROR(K14/O14,0) -> 4.2323935 | T14: =K14-X14-Z14 -> 5232780 | U14: =IFERROR(T14/(AB14+AD14),0) -> 5.5095176 | V14: 22 | W14: 3 | Z14: 367248 | AA14: 368266 | AD14: 949771 | AE14: 954869
A15: MemoryStore->FileStore->LossyStore | B15: 1 | C15: 256 | D15: 256 | E15: 256 | F15: 256 | G15: 4096 | H15: 1MB | I15: 200001 | J15: 28 | K15: =I15*J15 -> 5600028 | L15: 0.7884 | M15: 0.7474 | N15: 1224905 | O15: 1231021 | P15: =IF(O15=0,0,O15-N15) -> 6116 | Q15: =IFERROR(P15/O15,0) -> 0.0049682337 | R15: =IFERROR(K15/N15,0) -> 4.571806 | S15: =IFERROR(K15/O15,0) -> 4.5490922 | T15: =K15-X15-Z15 -> 5232780 | U15: =IFERROR(T15/(AB15+AD15),0) -> 6.1012503 | V15: 22 | W15: 3 | Z15: 367248 | AA15: 368266 | AD15: 857657 | AE15: 862755
A16: MemoryStore->FileStore->LossyStore | B16: 5 | C16: 256 | D16: 256 | E16: 256 | F16: 256 | G16: 4096 | H16: 1MB | I16: 200001 | J16: 28 | K16: =I16*J16 -> 5600028 | L16: 0.747 | M16: 0.728 | N16: 1169459 | O16: 1175575 | P16: =IF(O16=0,0,O16-N16) -> 6116 | Q16: =IFERROR(P16/O16,0) -> 0.0052025604 | R16: =IFERROR(K16/N16,0) -> 4.7885629 | S16: =IFERROR(K16/O16,0) -> 4.7636501 | T16: =K16-X16-Z16 -> 5232780 | U16: =IFERROR(T16/(AB16+AD16),0) -> 6.5229472 | V16: 22 | W16: 3 | Z16: 367248 | AA16: 368266 | AD16: 802211 | AE16: 807309
A17: MemoryStore->FileStore->CompressedStore | C17: 1024 | D17: 1024 | E17: 1024 | F17: 1024 | G17: 4096 | H17: 1MB | I17: 200001 | J17: 28 | K17: =I17*J17 -> 5600028 | L17: 0.6616 | M17: 1.9656 | N17: 1969527 | O17: 1970648 | P17: =IF(O17=0,0,O17-N17) -> 1121 | Q17: =IFERROR(P17/O17,0) -> 0.00056884842 | R17: =IFERROR(K17/N17,0) -> 2.8433365 | S17: =IFERROR(K17/O17,0) -> 2.8417191 | T17: =K17-X17-Z17 -> 5232780 | U17: =IFERROR(T17/(AB17+AD17),0) -> 3.2658357 | V17: 6 | W17: 3 | Z17: 367248 | AA17: 367786 | AB17: 1602279 | AC17: 1602862
A18: MemoryStore->FileStore->LossyStore | C18: 1024 | D18: 1024 | E18: 1024 | F18: 1024 | G18: 4096 | H18: 1MB | I18: 200001 | J18: 28 | K18: =I18*J18 -> 5600028 | L18: 0.6727 | M18: 2.6513 | N18: 1837806 | O18: 1839902 | P18: =IF(O18=0,0,O18-N18) -> 2096 | Q18: =IFERROR(P18/O18,0) -> 0.0011391911 | R18: =IFERROR(K18/N18,0) -> 3.0471268 | S18: =IFERROR(K18/O18,0) -> 3.0436556 | T18: =K18-X18-Z18 -> 5232780 | U18: =IFERROR(T18/(AB18+AD18),0) -> 3.5583636 | V18: 6 | W18: 3 | Z18: 367248 | AA18: 367786 | AD18: 1470558 | AE18: 1472116
A19: MemoryStore->FileStore->LossyStore | B19: 0.1 | C19: 1024 | D19: 1024 | E19: 1024 | F19: 1024 | G19: 4096 | H19: 1MB | I19: 200001 | J19: 28 | K19: =I19*J19 -> 5600028 | L19: 0.7111 | M19: 2.8274 | N19: 1513483 | O19: 1515579 | P19: =IF(O19=0,0,O19-N19) -> 2096 | Q19: =IFERROR(P19/O19,0) -> 0.0013829698 | R19: =IFERROR(K19/N19,0) -> 3.7000931 | S19: =IFERROR(K19/O19,0) -> 3.694976 | T19: =K19-X19-Z19 -> 5232780 | U19: =IFERROR(T19/(AB19+AD19),0) -> 4.5651895 | V19: 6 | W19: 3 | Z19: 367248 | AA19: 367786 | AD19: 1146235 | AE19: 1147793
A20: MemoryStore->FileStore->LossyStore | B20: 1 | C20: 1024 | D20: 1024 | E20: 1024 | F20: 1024 | G20: 4096 | H20: 1MB | I20: 200001 | J20: 28 | K20: =I20*J20 -> 5600028 | L20: 0.7151 | M20: 2.8611 | N20: 1427426 | O20: 1429522 | P20: =IF(O20=0,0,O20-N20) -> 2096 | Q20: =IFERROR(P20/O20,0) -> 0.0014662244 | R20: =IFERROR(K20/N20,0) -> 3.9231652 | S20: =IFERROR(K20/O20,0) -> 3.917413 | T20: =K20-X20-Z20 -> 5232780 | U20: =IFERROR(T20/(AB20+AD20),0) -> 4.9357561 | V20: 6 | W20: 3 | Z20: 367248 | AA20: 367786 | AD20: 1060178 | AE20: 1061736
A21: MemoryStore->FileStore->LossyStore | B21: 5 | C21: 1024 | D21: 1024 | E21: 1024 | F21: 1024 | G21: 4096 | H21: 1MB | I21: 200001 | J21: 28 | K21: =I21*J21 -> 5600028 | L21: 0.6936 | M21: 2.7618 | N21: 1362215 | O21: 1364311 | P21: =IF(O21=0,0,O21-N21) -> 2096 | Q21: =IFERROR(P21/O21,0) -> 0.0015363066 | R21: =IFERROR(K21/N21,0) -> 4.1109722 | S21: =IFERROR(K21/O21,0) -> 4.1046565 | T21: =K21-X21-Z21 -> 5232780 | U21: =IFERROR(T21/(AB21+AD21),0) -> 5.2592498 | V21: 6 | W21: 3 | Z21: 367248 | AA21: 367786 | AD21: 994967 | AE21: 996525
A22: MemoryStore->FileStore->CompressedStore | C22: 4096 | D22: 4096 | E22: 4096 | F22: 4096 | G22: 4096 | H22: 1MB | I22: 200001 | J22: 28 | K22: =I22*J22 -> 5600028 | L22: 0.732 | M22: 7.3734 | N22: 1967475 | O22: 1968353 | P22: =IF(O22=0,0,O22-N22) -> 878 | Q22: =IFERROR(P22/O22,0) -> 0.0004460582 | R22: =IFERROR(K22/N22,0) -> 2.846302 | S22: =IFERROR(K22/O22,0) -> 2.8450324 | T22: =K22-X22-Z22 -> 5232780 | U22: =IFERROR(T22/(AB22+AD22),0) -> 3.2700236 | V22: 3 | W22: 3 | Z22: 367248 | AA22: 367666 | AB22: 1600227 | AC22: 1600687
A23: MemoryStore->FileStore->LossyStore | C23: 4096 | D23: 4096 | E23: 4096 | F23: 4096 | G23: 4096 | H23: 1MB | I23: 200001 | J23: 28 | K23: =I23*J23 -> 5600028 | L23: 0.7086 | M23: 10.7313 | N23: 1508426 | O23: 1509694 | P23: =IF(O23=0,0,O23-N23) -> 1268 | Q23: =IFERROR(P23/O23,0) -> 0.00083990531 | R23: =IFERROR(K23/N23,0) -> 3.7124977 | S23: =IFERROR(K23/O23,0) -> 3.7093795 | T23: =K23-X23-Z23 -> 5232780 | U23: =IFERROR(T23/(AB23+AD23),0) -> 4.5854196 | V23: 3 | W23: 3 | Z23: 367248 | AA23: 367666 | AD23: 1141178 | AE23: 1142028
A24: MemoryStore->FileStore->LossyStore | B24: 0.1 | C24: 4096 | D24: 4096 | E24: 4096 | F24: 4096 | G24: 4096 | H24: 1MB | I24: 200001 | J24: 28 | K24: =I24*J24 -> 5600028 | L24: 0.711 | M24: 10.959 | N24: 1182778 | O24: 1184046 | P24: =IF(O24=0,0,O24-N24) -> 1268 | Q24: =IFERROR(P24/O24,0) -> 0.0010709043 | R24: =IFERROR(K24/N24,0) -> 4.73464 | S24: =IFERROR(K24/O24,0) -> 4.7295696 | T24: =K24-X24-Z24 -> 5232780 | U24: =IFERROR(T24/(AB24+AD24),0) -> 6.4164163 | V24: 3 | W24: 3 | Z24: 367248 | AA24: 367666 | AD24: 815530 | AE24: 816380
A25: MemoryStore->FileStore->LossyStore | B25: 1 | C25: 4096 | D25: 4096 | E25: 4096 | F25: 4096 | G25: 4096 | H25: 1MB | I25: 200001 | J25: 28 | K25: =I25*J25 -> 5600028 | L25: 0.6913 | M25: 13.0422 | N25: 1098533 | O25: 1099801 | P25: =IF(O25=0,0,O25-N25) -> 1268 | Q25: =IFERROR(P25/O25,0) -> 0.0011529358 | R25: =IFERROR(K25/N25,0) -> 5.0977331 | S25: =IFERROR(K25/O25,0) -> 5.0918557 | T25: =K25-X25-Z25 -> 5232780 | U25: =IFERROR(T25/(AB25+AD25),0) -> 7.155596 | V25: 3 | W25: 3 | Z25: 367248 | AA25: 367666 | AD25: 731285 | AE25: 732135
A26: MemoryStore->FileStore->LossyStore | B26: 5 | C26: 4096 | D26: 4096 | E26: 4096 | F26: 4096 | G26: 4096 | H26: 1MB | I26: 200001 | J26: 28 | K26: =I26*J26 -> 5600028 | L26: 0.7192 | M26: 10.9258 | N26: 1031479 | O26: 1032747 | P26: =IF(O26=0,0,O26-N26) -> 1268 | Q26: =IFERROR(P26/O26,0) -> 0.0012277934 | R26: =IFERROR(K26/N26,0) -> 5.4291246 | S26: =IFERROR(K26/O26,0) -> 5.4224587 | T26: =K26-X26-Z26 -> 5232780 | U26: =IFERROR(T26/(AB26+AD26),0) -> 7.8779521 | V26: 3 | W26: 3 | Z26: 367248 | AA26: 367666 | AD26: 664231 | AE26: 665081

Sheet Float Column
A1: column | B1: type | C1: is_quantisable | D1: bound_pct | E1: groups | F1: bytes | G1: bytes_per_row | H1: vs_lossless_bytes | I1: vs_lossless_pct | J1: codec | K1: worst_recorded_error | L1: bound_as_fraction | M1: error_within_bound
A2: producerId | B2: INT32 | C2: no | D2: 0 | E2: 86 | F2: 150881 | G2: =F2/200001 -> 0.75440123 | H2: =F2-F2 -> 0 | I2: =IFERROR((F2-F2)/F2,0) -> 0 | J2: ForBitpack | K2: 0 | L2: =D2/100 -> 0 | M2: =IF(K2<=L2,"within","EXCEEDED") -> within
A3: groupId | B3: INT32 | C3: no | D3: 0 | E3: 86 | F3: 75870 | G3: =F3/200001 -> 0.3793481 | H3: =F3-F3 -> 0 | I3: =IFERROR((F3-F3)/F3,0) -> 0 | J3: ForBitpack | K3: 0 | L3: =D3/100 -> 0 | M3: =IF(K3<=L3,"within","EXCEEDED") -> within
A4: producedPower | B4: FLOAT64 | C4: yes | D4: 0 | E4: 86 | F4: 697848 | G4: =F4/200001 -> 3.4892226 | H4: =F4-F4 -> 0 | I4: =IFERROR((F4-F4)/F4,0) -> 0 | J4: Raw | K4: 0 | L4: =D4/100 -> 0 | M4: =IF(K4<=L4,"within","EXCEEDED") -> within
A5: ts | B5: UINT64 | C5: no | D5: 0 | E5: 86 | F5: 574425 | G5: =F5/200001 -> 2.8721106 | H5: =F5-F5 -> 0 | I5: =IFERROR((F5-F5)/F5,0) -> 0 | J5: ForBitpack | K5: 0 | L5: =D5/100 -> 0 | M5: =IF(K5<=L5,"within","EXCEEDED") -> within
A6: producerId | B6: INT32 | C6: no | D6: 0.01 | E6: 86 | F6: 150881 | G6: =F6/200001 -> 0.75440123 | H6: =F6-F2 -> 0 | I6: =IFERROR((F6-F2)/F2,0) -> 0 | J6: ForBitpack | K6: 0 | L6: =D6/100 -> 0.0001 | M6: =IF(K6<=L6,"within","EXCEEDED") -> within
A7: groupId | B7: INT32 | C7: no | D7: 0.01 | E7: 86 | F7: 75870 | G7: =F7/200001 -> 0.3793481 | H7: =F7-F3 -> 0 | I7: =IFERROR((F7-F3)/F3,0) -> 0 | J7: ForBitpack | K7: 0 | L7: =D7/100 -> 0.0001 | M7: =IF(K7<=L7,"within","EXCEEDED") -> within
A8: producedPower | B8: FLOAT64 | C8: yes | D8: 0.01 | E8: 86 | F8: 404387 | G8: =F8/200001 -> 2.0219249 | H8: =F8-F4 -> -293461 | I8: =IFERROR((F8-F4)/F4,0) -> -0.42052281 | J8: Quantized | K8: 9.9997912e-05 | L8: =D8/100 -> 0.0001 | M8: =IF(K8<=L8,"within","EXCEEDED") -> within
A9: ts | B9: UINT64 | C9: no | D9: 0.01 | E9: 86 | F9: 574425 | G9: =F9/200001 -> 2.8721106 | H9: =F9-F5 -> 0 | I9: =IFERROR((F9-F5)/F5,0) -> 0 | J9: ForBitpack | K9: 0 | L9: =D9/100 -> 0.0001 | M9: =IF(K9<=L9,"within","EXCEEDED") -> within
A10: producerId | B10: INT32 | C10: no | D10: 0.1 | E10: 86 | F10: 150881 | G10: =F10/200001 -> 0.75440123 | H10: =F10-F2 -> 0 | I10: =IFERROR((F10-F2)/F2,0) -> 0 | J10: ForBitpack | K10: 0 | L10: =D10/100 -> 0.001 | M10: =IF(K10<=L10,"within","EXCEEDED") -> within
A11: groupId | B11: INT32 | C11: no | D11: 0.1 | E11: 86 | F11: 75870 | G11: =F11/200001 -> 0.3793481 | H11: =F11-F3 -> 0 | I11: =IFERROR((F11-F3)/F3,0) -> 0 | J11: ForBitpack | K11: 0 | L11: =D11/100 -> 0.001 | M11: =IF(K11<=L11,"within","EXCEEDED") -> within
A12: producedPower | B12: FLOAT64 | C12: yes | D12: 0.1 | E12: 86 | F12: 335378 | G12: =F12/200001 -> 1.6768816 | H12: =F12-F4 -> -362470 | I12: =IFERROR((F12-F4)/F4,0) -> -0.5194111 | J12: Quantized | K12: 0.00099998949 | L12: =D12/100 -> 0.001 | M12: =IF(K12<=L12,"within","EXCEEDED") -> within
A13: ts | B13: UINT64 | C13: no | D13: 0.1 | E13: 86 | F13: 574425 | G13: =F13/200001 -> 2.8721106 | H13: =F13-F5 -> 0 | I13: =IFERROR((F13-F5)/F5,0) -> 0 | J13: ForBitpack | K13: 0 | L13: =D13/100 -> 0.001 | M13: =IF(K13<=L13,"within","EXCEEDED") -> within
A14: producerId | B14: INT32 | C14: no | D14: 0.5 | E14: 86 | F14: 150881 | G14: =F14/200001 -> 0.75440123 | H14: =F14-F2 -> 0 | I14: =IFERROR((F14-F2)/F2,0) -> 0 | J14: ForBitpack | K14: 0 | L14: =D14/100 -> 0.005 | M14: =IF(K14<=L14,"within","EXCEEDED") -> within
A15: groupId | B15: INT32 | C15: no | D15: 0.5 | E15: 86 | F15: 75870 | G15: =F15/200001 -> 0.3793481 | H15: =F15-F3 -> 0 | I15: =IFERROR((F15-F3)/F3,0) -> 0 | J15: ForBitpack | K15: 0 | L15: =D15/100 -> 0.005 | M15: =IF(K15<=L15,"within","EXCEEDED") -> within
A16: producedPower | B16: FLOAT64 | C16: yes | D16: 0.5 | E16: 86 | F16: 275907 | G16: =F16/200001 -> 1.3795281 | H16: =F16-F4 -> -421941 | I16: =IFERROR((F16-F4)/F4,0) -> -0.60463167 | J16: Quantized | K16: 0.0049998424 | L16: =D16/100 -> 0.005 | M16: =IF(K16<=L16,"within","EXCEEDED") -> within
A17: ts | B17: UINT64 | C17: no | D17: 0.5 | E17: 86 | F17: 574425 | G17: =F17/200001 -> 2.8721106 | H17: =F17-F5 -> 0 | I17: =IFERROR((F17-F5)/F5,0) -> 0 | J17: ForBitpack | K17: 0 | L17: =D17/100 -> 0.005 | M17: =IF(K17<=L17,"within","EXCEEDED") -> within
A18: producerId | B18: INT32 | C18: no | D18: 1 | E18: 86 | F18: 150881 | G18: =F18/200001 -> 0.75440123 | H18: =F18-F2 -> 0 | I18: =IFERROR((F18-F2)/F2,0) -> 0 | J18: ForBitpack | K18: 0 | L18: =D18/100 -> 0.01 | M18: =IF(K18<=L18,"within","EXCEEDED") -> within
A19: groupId | B19: INT32 | C19: no | D19: 1 | E19: 86 | F19: 75870 | G19: =F19/200001 -> 0.3793481 | H19: =F19-F3 -> 0 | I19: =IFERROR((F19-F3)/F3,0) -> 0 | J19: ForBitpack | K19: 0 | L19: =D19/100 -> 0.01 | M19: =IF(K19<=L19,"within","EXCEEDED") -> within
A20: producedPower | B20: FLOAT64 | C20: yes | D20: 1 | E20: 86 | F20: 252612 | G20: =F20/200001 -> 1.2630537 | H20: =F20-F4 -> -445236 | I20: =IFERROR((F20-F4)/F4,0) -> -0.63801286 | J20: Quantized | K20: 0.0099999791 | L20: =D20/100 -> 0.01 | M20: =IF(K20<=L20,"within","EXCEEDED") -> within
A21: ts | B21: UINT64 | C21: no | D21: 1 | E21: 86 | F21: 574425 | G21: =F21/200001 -> 2.8721106 | H21: =F21-F5 -> 0 | I21: =IFERROR((F21-F5)/F5,0) -> 0 | J21: ForBitpack | K21: 0 | L21: =D21/100 -> 0.01 | M21: =IF(K21<=L21,"within","EXCEEDED") -> within
A22: producerId | B22: INT32 | C22: no | D22: 2 | E22: 86 | F22: 150881 | G22: =F22/200001 -> 0.75440123 | H22: =F22-F2 -> 0 | I22: =IFERROR((F22-F2)/F2,0) -> 0 | J22: ForBitpack | K22: 0 | L22: =D22/100 -> 0.02 | M22: =IF(K22<=L22,"within","EXCEEDED") -> within
A23: groupId | B23: INT32 | C23: no | D23: 2 | E23: 86 | F23: 75870 | G23: =F23/200001 -> 0.3793481 | H23: =F23-F3 -> 0 | I23: =IFERROR((F23-F3)/F3,0) -> 0 | J23: ForBitpack | K23: 0 | L23: =D23/100 -> 0.02 | M23: =IF(K23<=L23,"within","EXCEEDED") -> within
A24: producedPower | B24: FLOAT64 | C24: yes | D24: 2 | E24: 86 | F24: 192392 | G24: =F24/200001 -> 0.96195519 | H24: =F24-F4 -> -505456 | I24: =IFERROR((F24-F4)/F4,0) -> -0.72430673 | J24: Quantized | K24: 0.019999969 | L24: =D24/100 -> 0.02 | M24: =IF(K24<=L24,"within","EXCEEDED") -> within
A25: ts | B25: UINT64 | C25: no | D25: 2 | E25: 86 | F25: 574425 | G25: =F25/200001 -> 2.8721106 | H25: =F25-F5 -> 0 | I25: =IFERROR((F25-F5)/F5,0) -> 0 | J25: ForBitpack | K25: 0 | L25: =D25/100 -> 0.02 | M25: =IF(K25<=L25,"within","EXCEEDED") -> within
A26: producerId | B26: INT32 | C26: no | D26: 5 | E26: 86 | F26: 150881 | G26: =F26/200001 -> 0.75440123 | H26: =F26-F2 -> 0 | I26: =IFERROR((F26-F2)/F2,0) -> 0 | J26: ForBitpack | K26: 0 | L26: =D26/100 -> 0.05 | M26: =IF(K26<=L26,"within","EXCEEDED") -> within
A27: groupId | B27: INT32 | C27: no | D27: 5 | E27: 86 | F27: 75870 | G27: =F27/200001 -> 0.3793481 | H27: =F27-F3 -> 0 | I27: =IFERROR((F27-F3)/F3,0) -> 0 | J27: ForBitpack | K27: 0 | L27: =D27/100 -> 0.05 | M27: =IF(K27<=L27,"within","EXCEEDED") -> within
A28: producedPower | B28: FLOAT64 | C28: yes | D28: 5 | E28: 86 | F28: 198882 | G28: =F28/200001 -> 0.99440503 | H28: =F28-F4 -> -498966 | I28: =IFERROR((F28-F4)/F4,0) -> -0.71500671 | J28: Quantized | K28: 0.049999162 | L28: =D28/100 -> 0.05 | M28: =IF(K28<=L28,"within","EXCEEDED") -> within
A29: ts | B29: UINT64 | C29: no | D29: 5 | E29: 86 | F29: 574425 | G29: =F29/200001 -> 2.8721106 | H29: =F29-F5 -> 0 | I29: =IFERROR((F29-F5)/F5,0) -> 0 | J29: ForBitpack | K29: 0 | L29: =D29/100 -> 0.05 | M29: =IF(K29<=L29,"within","EXCEEDED") -> within
A30: producerId | B30: INT32 | C30: no | D30: 10 | E30: 86 | F30: 150881 | G30: =F30/200001 -> 0.75440123 | H30: =F30-F2 -> 0 | I30: =IFERROR((F30-F2)/F2,0) -> 0 | J30: ForBitpack | K30: 0 | L30: =D30/100 -> 0.1 | M30: =IF(K30<=L30,"within","EXCEEDED") -> within
A31: groupId | B31: INT32 | C31: no | D31: 10 | E31: 86 | F31: 75870 | G31: =F31/200001 -> 0.3793481 | H31: =F31-F3 -> 0 | I31: =IFERROR((F31-F3)/F3,0) -> 0 | J31: ForBitpack | K31: 0 | L31: =D31/100 -> 0.1 | M31: =IF(K31<=L31,"within","EXCEEDED") -> within
A32: producedPower | B32: FLOAT64 | C32: yes | D32: 10 | E32: 86 | F32: 158442 | G32: =F32/200001 -> 0.79220604 | H32: =F32-F4 -> -539406 | I32: =IFERROR((F32-F4)/F4,0) -> -0.77295629 | J32: Quantized | K32: 0.099998702 | L32: =D32/100 -> 0.1 | M32: =IF(K32<=L32,"within","EXCEEDED") -> within
A33: ts | B33: UINT64 | C33: no | D33: 10 | E33: 86 | F33: 574425 | G33: =F33/200001 -> 2.8721106 | H33: =F33-F5 -> 0 | I33: =IFERROR((F33-F5)/F5,0) -> 0 | J33: ForBitpack | K33: 0 | L33: =D33/100 -> 0.1 | M33: =IF(K33<=L33,"within","EXCEEDED") -> within
A34: producerId | B34: INT32 | C34: no | D34: 20 | E34: 86 | F34: 150881 | G34: =F34/200001 -> 0.75440123 | H34: =F34-F2 -> 0 | I34: =IFERROR((F34-F2)/F2,0) -> 0 | J34: ForBitpack | K34: 0 | L34: =D34/100 -> 0.2 | M34: =IF(K34<=L34,"within","EXCEEDED") -> within
A35: groupId | B35: INT32 | C35: no | D35: 20 | E35: 86 | F35: 75870 | G35: =F35/200001 -> 0.3793481 | H35: =F35-F3 -> 0 | I35: =IFERROR((F35-F3)/F3,0) -> 0 | J35: ForBitpack | K35: 0 | L35: =D35/100 -> 0.2 | M35: =IF(K35<=L35,"within","EXCEEDED") -> within
A36: producedPower | B36: FLOAT64 | C36: yes | D36: 20 | E36: 86 | F36: 142123 | G36: =F36/200001 -> 0.71061145 | H36: =F36-F4 -> -555725 | I36: =IFERROR((F36-F4)/F4,0) -> -0.79634104 | J36: Quantized | K36: 0.19999696 | L36: =D36/100 -> 0.2 | M36: =IF(K36<=L36,"within","EXCEEDED") -> within
A37: ts | B37: UINT64 | C37: no | D37: 20 | E37: 86 | F37: 574425 | G37: =F37/200001 -> 2.8721106 | H37: =F37-F5 -> 0 | I37: =IFERROR((F37-F5)/F5,0) -> 0 | J37: ForBitpack | K37: 0 | L37: =D37/100 -> 0.2 | M37: =IF(K37<=L37,"within","EXCEEDED") -> within

Sheet Ratios by Size
A1: Compression ratio against unit size
A2: Every cell is a SUMIFS against the Standalone or Chained sheet. Green means computed by the sheet, so correcting a measurement moves it.
A4: STANDALONE - bytes_in / data_out
A5: One store, no tiering. Nothing is held back uncompressed.
A6: Configuration | B6: 16 KB | C6: 64 KB | D6: 256 KB | E6: 1024 KB | F6: 4096 KB
A7: MemoryStore | B7: =SUMIFS(Standalone!$R:$R,Standalone!$A:$A,"MemoryStore",Standalone!$B:$B,"",Standalone!$C:$C,16) -> 1 | C7: =SUMIFS(Standalone!$R:$R,Standalone!$A:$A,"MemoryStore",Standalone!$B:$B,"",Standalone!$C:$C,64) -> 1 | D7: =SUMIFS(Standalone!$R:$R,Standalone!$A:$A,"MemoryStore",Standalone!$B:$B,"",Standalone!$C:$C,256) -> 1 | E7: =SUMIFS(Standalone!$R:$R,Standalone!$A:$A,"MemoryStore",Standalone!$B:$B,"",Standalone!$C:$C,1024) -> 1 | F7: =SUMIFS(Standalone!$R:$R,Standalone!$A:$A,"MemoryStore",Standalone!$B:$B,"",Standalone!$C:$C,4096) -> 1
A8: FileStore | B8: =SUMIFS(Standalone!$R:$R,Standalone!$A:$A,"FileStore",Standalone!$B:$B,"",Standalone!$C:$C,16) -> 1 | C8: =SUMIFS(Standalone!$R:$R,Standalone!$A:$A,"FileStore",Standalone!$B:$B,"",Standalone!$C:$C,64) -> 1 | D8: =SUMIFS(Standalone!$R:$R,Standalone!$A:$A,"FileStore",Standalone!$B:$B,"",Standalone!$C:$C,256) -> 1 | E8: =SUMIFS(Standalone!$R:$R,Standalone!$A:$A,"FileStore",Standalone!$B:$B,"",Standalone!$C:$C,1024) -> 1 | F8: =SUMIFS(Standalone!$R:$R,Standalone!$A:$A,"FileStore",Standalone!$B:$B,"",Standalone!$C:$C,4096) -> 1
A9: CompressedStore | B9: =SUMIFS(Standalone!$R:$R,Standalone!$A:$A,"CompressedStore",Standalone!$B:$B,"",Standalone!$C:$C,16) -> 3.1662171 | C9: =SUMIFS(Standalone!$R:$R,Standalone!$A:$A,"CompressedStore",Standalone!$B:$B,"",Standalone!$C:$C,64) -> 3.256669 | D9: =SUMIFS(Standalone!$R:$R,Standalone!$A:$A,"CompressedStore",Standalone!$B:$B,"",Standalone!$C:$C,256) -> 3.2681943 | E9: =SUMIFS(Standalone!$R:$R,Standalone!$A:$A,"CompressedStore",Standalone!$B:$B,"",Standalone!$C:$C,1024) -> 3.2661299 | F9: =SUMIFS(Standalone!$R:$R,Standalone!$A:$A,"CompressedStore",Standalone!$B:$B,"",Standalone!$C:$C,4096) -> 3.2700225
A10: LossyStore lossless | B10: =SUMIFS(Standalone!$R:$R,Standalone!$A:$A,"LossyStore",Standalone!$B:$B,"",Standalone!$C:$C,16) -> 4.6408367 | C10: =SUMIFS(Standalone!$R:$R,Standalone!$A:$A,"LossyStore",Standalone!$B:$B,"",Standalone!$C:$C,64) -> 3.7357827 | D10: =SUMIFS(Standalone!$R:$R,Standalone!$A:$A,"LossyStore",Standalone!$B:$B,"",Standalone!$C:$C,256) -> 4.1013347 | E10: =SUMIFS(Standalone!$R:$R,Standalone!$A:$A,"LossyStore",Standalone!$B:$B,"",Standalone!$C:$C,1024) -> 3.5884688 | F10: =SUMIFS(Standalone!$R:$R,Standalone!$A:$A,"LossyStore",Standalone!$B:$B,"",Standalone!$C:$C,4096) -> 4.4958225
A11: LossyStore 0.1% | B11: =SUMIFS(Standalone!$R:$R,Standalone!$A:$A,"LossyStore",Standalone!$B:$B,0.1,Standalone!$C:$C,16) -> 6.9234102 | C11: =SUMIFS(Standalone!$R:$R,Standalone!$A:$A,"LossyStore",Standalone!$B:$B,0.1,Standalone!$C:$C,64) -> 4.9271992 | D11: =SUMIFS(Standalone!$R:$R,Standalone!$A:$A,"LossyStore",Standalone!$B:$B,0.1,Standalone!$C:$C,256) -> 5.4988114 | E11: =SUMIFS(Standalone!$R:$R,Standalone!$A:$A,"LossyStore",Standalone!$B:$B,0.1,Standalone!$C:$C,1024) -> 4.614789 | F11: =SUMIFS(Standalone!$R:$R,Standalone!$A:$A,"LossyStore",Standalone!$B:$B,0.1,Standalone!$C:$C,4096) -> 6.2425973
A12: LossyStore 1% | B12: =SUMIFS(Standalone!$R:$R,Standalone!$A:$A,"LossyStore",Standalone!$B:$B,1,Standalone!$C:$C,16) -> 7.6703781 | C12: =SUMIFS(Standalone!$R:$R,Standalone!$A:$A,"LossyStore",Standalone!$B:$B,1,Standalone!$C:$C,64) -> 5.3141884 | D12: =SUMIFS(Standalone!$R:$R,Standalone!$A:$A,"LossyStore",Standalone!$B:$B,1,Standalone!$C:$C,256) -> 6.0860608 | E12: =SUMIFS(Standalone!$R:$R,Standalone!$A:$A,"LossyStore",Standalone!$B:$B,1,Standalone!$C:$C,1024) -> 4.9960059 | F12: =SUMIFS(Standalone!$R:$R,Standalone!$A:$A,"LossyStore",Standalone!$B:$B,1,Standalone!$C:$C,4096) -> 6.9392558
A13: LossyStore 5% | B13: =SUMIFS(Standalone!$R:$R,Standalone!$A:$A,"LossyStore",Standalone!$B:$B,5,Standalone!$C:$C,16) -> 8.3247158 | C13: =SUMIFS(Standalone!$R:$R,Standalone!$A:$A,"LossyStore",Standalone!$B:$B,5,Standalone!$C:$C,64) -> 5.5997032 | D13: =SUMIFS(Standalone!$R:$R,Standalone!$A:$A,"LossyStore",Standalone!$B:$B,5,Standalone!$C:$C,256) -> 6.5037425 | E13: =SUMIFS(Standalone!$R:$R,Standalone!$A:$A,"LossyStore",Standalone!$B:$B,5,Standalone!$C:$C,1024) -> 5.3241518 | F13: =SUMIFS(Standalone!$R:$R,Standalone!$A:$A,"LossyStore",Standalone!$B:$B,5,Standalone!$C:$C,4096) -> 7.6174379
A15: CHAINED - ratio_on_data (the whole chain)
A16: Counts the sub-threshold remainder FileStore keeps uncompressed, so this is what the chain costs on disk.
A17: Configuration | B17: 16 KB | C17: 64 KB | D17: 256 KB | E17: 1024 KB | F17: 4096 KB
A18: -> CompressedStore | B18: =SUMIFS(Chained!$R:$R,Chained!$A:$A,"MemoryStore->FileStore->CompressedStore",Chained!$B:$B,"",Chained!$C:$C,16) -> 2.7897992 | C18: =SUMIFS(Chained!$R:$R,Chained!$A:$A,"MemoryStore->FileStore->CompressedStore",Chained!$B:$B,"",Chained!$C:$C,64) -> 2.8373363 | D18: =SUMIFS(Chained!$R:$R,Chained!$A:$A,"MemoryStore->FileStore->CompressedStore",Chained!$B:$B,"",Chained!$C:$C,256) -> 2.8422657 | E18: =SUMIFS(Chained!$R:$R,Chained!$A:$A,"MemoryStore->FileStore->CompressedStore",Chained!$B:$B,"",Chained!$C:$C,1024) -> 2.8433365 | F18: =SUMIFS(Chained!$R:$R,Chained!$A:$A,"MemoryStore->FileStore->CompressedStore",Chained!$B:$B,"",Chained!$C:$C,4096) -> 2.846302
A19: -> LossyStore lossless | B19: =SUMIFS(Chained!$R:$R,Chained!$A:$A,"MemoryStore->FileStore->LossyStore",Chained!$B:$B,"",Chained!$C:$C,16) -> 3.7919272 | C19: =SUMIFS(Chained!$R:$R,Chained!$A:$A,"MemoryStore->FileStore->LossyStore",Chained!$B:$B,"",Chained!$C:$C,64) -> 3.1693261 | D19: =SUMIFS(Chained!$R:$R,Chained!$A:$A,"MemoryStore->FileStore->LossyStore",Chained!$B:$B,"",Chained!$C:$C,256) -> 3.4127659 | E19: =SUMIFS(Chained!$R:$R,Chained!$A:$A,"MemoryStore->FileStore->LossyStore",Chained!$B:$B,"",Chained!$C:$C,1024) -> 3.0471268 | F19: =SUMIFS(Chained!$R:$R,Chained!$A:$A,"MemoryStore->FileStore->LossyStore",Chained!$B:$B,"",Chained!$C:$C,4096) -> 3.7124977
A20: -> LossyStore 0.1% | B20: =SUMIFS(Chained!$R:$R,Chained!$A:$A,"MemoryStore->FileStore->LossyStore",Chained!$B:$B,0.1,Chained!$C:$C,16) -> 5.0391277 | C20: =SUMIFS(Chained!$R:$R,Chained!$A:$A,"MemoryStore->FileStore->LossyStore",Chained!$B:$B,0.1,Chained!$C:$C,64) -> 3.920954 | D20: =SUMIFS(Chained!$R:$R,Chained!$A:$A,"MemoryStore->FileStore->LossyStore",Chained!$B:$B,0.1,Chained!$C:$C,256) -> 4.252048 | E20: =SUMIFS(Chained!$R:$R,Chained!$A:$A,"MemoryStore->FileStore->LossyStore",Chained!$B:$B,0.1,Chained!$C:$C,1024) -> 3.7000931 | F20: =SUMIFS(Chained!$R:$R,Chained!$A:$A,"MemoryStore->FileStore->LossyStore",Chained!$B:$B,0.1,Chained!$C:$C,4096) -> 4.73464
A21: -> LossyStore 1% | B21: =SUMIFS(Chained!$R:$R,Chained!$A:$A,"MemoryStore->FileStore->LossyStore",Chained!$B:$B,1,Chained!$C:$C,16) -> 5.3965198 | C21: =SUMIFS(Chained!$R:$R,Chained!$A:$A,"MemoryStore->FileStore->LossyStore",Chained!$B:$B,1,Chained!$C:$C,64) -> 4.1448315 | D21: =SUMIFS(Chained!$R:$R,Chained!$A:$A,"MemoryStore->FileStore->LossyStore",Chained!$B:$B,1,Chained!$C:$C,256) -> 4.571806 | E21: =SUMIFS(Chained!$R:$R,Chained!$A:$A,"MemoryStore->FileStore->LossyStore",Chained!$B:$B,1,Chained!$C:$C,1024) -> 3.9231652 | F21: =SUMIFS(Chained!$R:$R,Chained!$A:$A,"MemoryStore->FileStore->LossyStore",Chained!$B:$B,1,Chained!$C:$C,4096) -> 5.0977331
A22: -> LossyStore 5% | B22: =SUMIFS(Chained!$R:$R,Chained!$A:$A,"MemoryStore->FileStore->LossyStore",Chained!$B:$B,5,Chained!$C:$C,16) -> 5.6817889 | C22: =SUMIFS(Chained!$R:$R,Chained!$A:$A,"MemoryStore->FileStore->LossyStore",Chained!$B:$B,5,Chained!$C:$C,64) -> 4.3048925 | D22: =SUMIFS(Chained!$R:$R,Chained!$A:$A,"MemoryStore->FileStore->LossyStore",Chained!$B:$B,5,Chained!$C:$C,256) -> 4.7885629 | E22: =SUMIFS(Chained!$R:$R,Chained!$A:$A,"MemoryStore->FileStore->LossyStore",Chained!$B:$B,5,Chained!$C:$C,1024) -> 4.1109722 | F22: =SUMIFS(Chained!$R:$R,Chained!$A:$A,"MemoryStore->FileStore->LossyStore",Chained!$B:$B,5,Chained!$C:$C,4096) -> 5.4291246
A24: CHAINED - ratio_on_tail (the codec alone)
A25: Excludes that remainder: what the tail achieved on the bytes it was actually handed. Compare codecs with this row set.
A26: Configuration | B26: 16 KB | C26: 64 KB | D26: 256 KB | E26: 1024 KB | F26: 4096 KB
A27: -> CompressedStore | B27: =SUMIFS(Chained!$U:$U,Chained!$A:$A,"MemoryStore->FileStore->CompressedStore",Chained!$B:$B,"",Chained!$C:$C,16) -> 3.1905736 | C27: =SUMIFS(Chained!$U:$U,Chained!$A:$A,"MemoryStore->FileStore->CompressedStore",Chained!$B:$B,"",Chained!$C:$C,64) -> 3.2573684 | D27: =SUMIFS(Chained!$U:$U,Chained!$A:$A,"MemoryStore->FileStore->CompressedStore",Chained!$B:$B,"",Chained!$C:$C,256) -> 3.264324 | E27: =SUMIFS(Chained!$U:$U,Chained!$A:$A,"MemoryStore->FileStore->CompressedStore",Chained!$B:$B,"",Chained!$C:$C,1024) -> 3.2658357 | F27: =SUMIFS(Chained!$U:$U,Chained!$A:$A,"MemoryStore->FileStore->CompressedStore",Chained!$B:$B,"",Chained!$C:$C,4096) -> 3.2700236
A28: -> LossyStore lossless | B28: =SUMIFS(Chained!$U:$U,Chained!$A:$A,"MemoryStore->FileStore->LossyStore",Chained!$B:$B,"",Chained!$C:$C,16) -> 4.7159964 | C28: =SUMIFS(Chained!$U:$U,Chained!$A:$A,"MemoryStore->FileStore->LossyStore",Chained!$B:$B,"",Chained!$C:$C,64) -> 3.7385064 | D28: =SUMIFS(Chained!$U:$U,Chained!$A:$A,"MemoryStore->FileStore->LossyStore",Chained!$B:$B,"",Chained!$C:$C,256) -> 4.1084655 | E28: =SUMIFS(Chained!$U:$U,Chained!$A:$A,"MemoryStore->FileStore->LossyStore",Chained!$B:$B,"",Chained!$C:$C,1024) -> 3.5583636 | F28: =SUMIFS(Chained!$U:$U,Chained!$A:$A,"MemoryStore->FileStore->LossyStore",Chained!$B:$B,"",Chained!$C:$C,4096) -> 4.5854196
A29: -> LossyStore 0.1% | B29: =SUMIFS(Chained!$U:$U,Chained!$A:$A,"MemoryStore->FileStore->LossyStore",Chained!$B:$B,0.1,Chained!$C:$C,16) -> 7.0327298 | C29: =SUMIFS(Chained!$U:$U,Chained!$A:$A,"MemoryStore->FileStore->LossyStore",Chained!$B:$B,0.1,Chained!$C:$C,64) -> 4.9320112 | D29: =SUMIFS(Chained!$U:$U,Chained!$A:$A,"MemoryStore->FileStore->LossyStore",Chained!$B:$B,0.1,Chained!$C:$C,256) -> 5.5095176 | E29: =SUMIFS(Chained!$U:$U,Chained!$A:$A,"MemoryStore->FileStore->LossyStore",Chained!$B:$B,0.1,Chained!$C:$C,1024) -> 4.5651895 | F29: =SUMIFS(Chained!$U:$U,Chained!$A:$A,"MemoryStore->FileStore->LossyStore",Chained!$B:$B,0.1,Chained!$C:$C,4096) -> 6.4164163
A30: -> LossyStore 1% | B30: =SUMIFS(Chained!$U:$U,Chained!$A:$A,"MemoryStore->FileStore->LossyStore",Chained!$B:$B,1,Chained!$C:$C,16) -> 7.804726 | C30: =SUMIFS(Chained!$U:$U,Chained!$A:$A,"MemoryStore->FileStore->LossyStore",Chained!$B:$B,1,Chained!$C:$C,64) -> 5.3187361 | D30: =SUMIFS(Chained!$U:$U,Chained!$A:$A,"MemoryStore->FileStore->LossyStore",Chained!$B:$B,1,Chained!$C:$C,256) -> 6.1012503 | E30: =SUMIFS(Chained!$U:$U,Chained!$A:$A,"MemoryStore->FileStore->LossyStore",Chained!$B:$B,1,Chained!$C:$C,1024) -> 4.9357561 | F30: =SUMIFS(Chained!$U:$U,Chained!$A:$A,"MemoryStore->FileStore->LossyStore",Chained!$B:$B,1,Chained!$C:$C,4096) -> 7.155596
A31: -> LossyStore 5% | B31: =SUMIFS(Chained!$U:$U,Chained!$A:$A,"MemoryStore->FileStore->LossyStore",Chained!$B:$B,5,Chained!$C:$C,16) -> 8.4623247 | C31: =SUMIFS(Chained!$U:$U,Chained!$A:$A,"MemoryStore->FileStore->LossyStore",Chained!$B:$B,5,Chained!$C:$C,64) -> 5.6049246 | D31: =SUMIFS(Chained!$U:$U,Chained!$A:$A,"MemoryStore->FileStore->LossyStore",Chained!$B:$B,5,Chained!$C:$C,256) -> 6.5229472 | E31: =SUMIFS(Chained!$U:$U,Chained!$A:$A,"MemoryStore->FileStore->LossyStore",Chained!$B:$B,5,Chained!$C:$C,1024) -> 5.2592498 | F31: =SUMIFS(Chained!$U:$U,Chained!$A:$A,"MemoryStore->FileStore->LossyStore",Chained!$B:$B,5,Chained!$C:$C,4096) -> 7.8779521
A33: COST OF TIERING - ratio_on_tail / ratio_on_data
A34: How much of the codec's work the uncompressed remainder gives back. 1.00 would mean the chain kept everything the codec achieved.
A35: Configuration | B35: 16 KB | C35: 64 KB | D35: 256 KB | E35: 1024 KB | F35: 4096 KB
A36: -> CompressedStore | B36: =IFERROR(B27/B18,0) -> 1.1436571 | C36: =IFERROR(C27/C18,0) -> 1.1480375 | D36: =IFERROR(D27/D18,0) -> 1.1484936 | E36: =IFERROR(E27/E18,0) -> 1.1485928 | F36: =IFERROR(F27/F18,0) -> 1.1488674
A37: -> LossyStore lossless | B37: =IFERROR(B28/B19,0) -> 1.2436938 | C37: =IFERROR(C28/C19,0) -> 1.1795904 | D37: =IFERROR(D28/D19,0) -> 1.2038522 | E37: =IFERROR(E28/E19,0) -> 1.1677766 | F37: =IFERROR(F28/F19,0) -> 1.2351306
A38: -> LossyStore 0.1% | B38: =IFERROR(B29/B20,0) -> 1.3956244 | C38: =IFERROR(C29/C20,0) -> 1.25786 | D38: =IFERROR(D29/D20,0) -> 1.2957327 | E38: =IFERROR(E29/E20,0) -> 1.233804 | F38: =IFERROR(F29/F20,0) -> 1.3552068
A39: -> LossyStore 1% | B39: =IFERROR(B30/B21,0) -> 1.4462517 | C39: =IFERROR(C30/C21,0) -> 1.2832213 | D39: =IFERROR(D30/D21,0) -> 1.3345383 | E39: =IFERROR(E30/E21,0) -> 1.2581056 | F39: =IFERROR(F30/F21,0) -> 1.403682
A40: -> LossyStore 5% | B40: =IFERROR(B31/B22,0) -> 1.4893768 | C40: =IFERROR(C31/C22,0) -> 1.3019894 | D40: =IFERROR(D31/D22,0) -> 1.3621931 | E40: =IFERROR(E31/E22,0) -> 1.2793202 | F40: =IFERROR(F31/F22,0) -> 1.4510538

Sheet Accuracy Tradeoff
A1: What each accuracy bound buys
A2: LossyStore only. The bound is a per-value error ceiling; a wider bound lets the quantiser spend fewer bits.
A4: STANDALONE - ratio by bound
A5: Configuration | B5: 16 KB | C5: 64 KB | D5: 256 KB | E5: 1024 KB | F5: 4096 KB
A6: LossyStore lossless | B6: =SUMIFS(Standalone!$R:$R,Standalone!$A:$A,"LossyStore",Standalone!$B:$B,"",Standalone!$C:$C,16) -> 4.6408367 | C6: =SUMIFS(Standalone!$R:$R,Standalone!$A:$A,"LossyStore",Standalone!$B:$B,"",Standalone!$C:$C,64) -> 3.7357827 | D6: =SUMIFS(Standalone!$R:$R,Standalone!$A:$A,"LossyStore",Standalone!$B:$B,"",Standalone!$C:$C,256) -> 4.1013347 | E6: =SUMIFS(Standalone!$R:$R,Standalone!$A:$A,"LossyStore",Standalone!$B:$B,"",Standalone!$C:$C,1024) -> 3.5884688 | F6: =SUMIFS(Standalone!$R:$R,Standalone!$A:$A,"LossyStore",Standalone!$B:$B,"",Standalone!$C:$C,4096) -> 4.4958225
A7: LossyStore 0.1% | B7: =SUMIFS(Standalone!$R:$R,Standalone!$A:$A,"LossyStore",Standalone!$B:$B,0.1,Standalone!$C:$C,16) -> 6.9234102 | C7: =SUMIFS(Standalone!$R:$R,Standalone!$A:$A,"LossyStore",Standalone!$B:$B,0.1,Standalone!$C:$C,64) -> 4.9271992 | D7: =SUMIFS(Standalone!$R:$R,Standalone!$A:$A,"LossyStore",Standalone!$B:$B,0.1,Standalone!$C:$C,256) -> 5.4988114 | E7: =SUMIFS(Standalone!$R:$R,Standalone!$A:$A,"LossyStore",Standalone!$B:$B,0.1,Standalone!$C:$C,1024) -> 4.614789 | F7: =SUMIFS(Standalone!$R:$R,Standalone!$A:$A,"LossyStore",Standalone!$B:$B,0.1,Standalone!$C:$C,4096) -> 6.2425973
A8: LossyStore 1% | B8: =SUMIFS(Standalone!$R:$R,Standalone!$A:$A,"LossyStore",Standalone!$B:$B,1,Standalone!$C:$C,16) -> 7.6703781 | C8: =SUMIFS(Standalone!$R:$R,Standalone!$A:$A,"LossyStore",Standalone!$B:$B,1,Standalone!$C:$C,64) -> 5.3141884 | D8: =SUMIFS(Standalone!$R:$R,Standalone!$A:$A,"LossyStore",Standalone!$B:$B,1,Standalone!$C:$C,256) -> 6.0860608 | E8: =SUMIFS(Standalone!$R:$R,Standalone!$A:$A,"LossyStore",Standalone!$B:$B,1,Standalone!$C:$C,1024) -> 4.9960059 | F8: =SUMIFS(Standalone!$R:$R,Standalone!$A:$A,"LossyStore",Standalone!$B:$B,1,Standalone!$C:$C,4096) -> 6.9392558
A9: LossyStore 5% | B9: =SUMIFS(Standalone!$R:$R,Standalone!$A:$A,"LossyStore",Standalone!$B:$B,5,Standalone!$C:$C,16) -> 8.3247158 | C9: =SUMIFS(Standalone!$R:$R,Standalone!$A:$A,"LossyStore",Standalone!$B:$B,5,Standalone!$C:$C,64) -> 5.5997032 | D9: =SUMIFS(Standalone!$R:$R,Standalone!$A:$A,"LossyStore",Standalone!$B:$B,5,Standalone!$C:$C,256) -> 6.5037425 | E9: =SUMIFS(Standalone!$R:$R,Standalone!$A:$A,"LossyStore",Standalone!$B:$B,5,Standalone!$C:$C,1024) -> 5.3241518 | F9: =SUMIFS(Standalone!$R:$R,Standalone!$A:$A,"LossyStore",Standalone!$B:$B,5,Standalone!$C:$C,4096) -> 7.6174379
A12: CHAINED - ratio_on_tail by bound
A13: Configuration | B13: 16 KB | C13: 64 KB | D13: 256 KB | E13: 1024 KB | F13: 4096 KB
A14: -> LossyStore lossless | B14: =SUMIFS(Chained!$U:$U,Chained!$A:$A,"MemoryStore->FileStore->LossyStore",Chained!$B:$B,"",Chained!$C:$C,16) -> 4.7159964 | C14: =SUMIFS(Chained!$U:$U,Chained!$A:$A,"MemoryStore->FileStore->LossyStore",Chained!$B:$B,"",Chained!$C:$C,64) -> 3.7385064 | D14: =SUMIFS(Chained!$U:$U,Chained!$A:$A,"MemoryStore->FileStore->LossyStore",Chained!$B:$B,"",Chained!$C:$C,256) -> 4.1084655 | E14: =SUMIFS(Chained!$U:$U,Chained!$A:$A,"MemoryStore->FileStore->LossyStore",Chained!$B:$B,"",Chained!$C:$C,1024) -> 3.5583636 | F14: =SUMIFS(Chained!$U:$U,Chained!$A:$A,"MemoryStore->FileStore->LossyStore",Chained!$B:$B,"",Chained!$C:$C,4096) -> 4.5854196
A15: -> LossyStore 0.1% | B15: =SUMIFS(Chained!$U:$U,Chained!$A:$A,"MemoryStore->FileStore->LossyStore",Chained!$B:$B,0.1,Chained!$C:$C,16) -> 7.0327298 | C15: =SUMIFS(Chained!$U:$U,Chained!$A:$A,"MemoryStore->FileStore->LossyStore",Chained!$B:$B,0.1,Chained!$C:$C,64) -> 4.9320112 | D15: =SUMIFS(Chained!$U:$U,Chained!$A:$A,"MemoryStore->FileStore->LossyStore",Chained!$B:$B,0.1,Chained!$C:$C,256) -> 5.5095176 | E15: =SUMIFS(Chained!$U:$U,Chained!$A:$A,"MemoryStore->FileStore->LossyStore",Chained!$B:$B,0.1,Chained!$C:$C,1024) -> 4.5651895 | F15: =SUMIFS(Chained!$U:$U,Chained!$A:$A,"MemoryStore->FileStore->LossyStore",Chained!$B:$B,0.1,Chained!$C:$C,4096) -> 6.4164163
A16: -> LossyStore 1% | B16: =SUMIFS(Chained!$U:$U,Chained!$A:$A,"MemoryStore->FileStore->LossyStore",Chained!$B:$B,1,Chained!$C:$C,16) -> 7.804726 | C16: =SUMIFS(Chained!$U:$U,Chained!$A:$A,"MemoryStore->FileStore->LossyStore",Chained!$B:$B,1,Chained!$C:$C,64) -> 5.3187361 | D16: =SUMIFS(Chained!$U:$U,Chained!$A:$A,"MemoryStore->FileStore->LossyStore",Chained!$B:$B,1,Chained!$C:$C,256) -> 6.1012503 | E16: =SUMIFS(Chained!$U:$U,Chained!$A:$A,"MemoryStore->FileStore->LossyStore",Chained!$B:$B,1,Chained!$C:$C,1024) -> 4.9357561 | F16: =SUMIFS(Chained!$U:$U,Chained!$A:$A,"MemoryStore->FileStore->LossyStore",Chained!$B:$B,1,Chained!$C:$C,4096) -> 7.155596
A17: -> LossyStore 5% | B17: =SUMIFS(Chained!$U:$U,Chained!$A:$A,"MemoryStore->FileStore->LossyStore",Chained!$B:$B,5,Chained!$C:$C,16) -> 8.4623247 | C17: =SUMIFS(Chained!$U:$U,Chained!$A:$A,"MemoryStore->FileStore->LossyStore",Chained!$B:$B,5,Chained!$C:$C,64) -> 5.6049246 | D17: =SUMIFS(Chained!$U:$U,Chained!$A:$A,"MemoryStore->FileStore->LossyStore",Chained!$B:$B,5,Chained!$C:$C,256) -> 6.5229472 | E17: =SUMIFS(Chained!$U:$U,Chained!$A:$A,"MemoryStore->FileStore->LossyStore",Chained!$B:$B,5,Chained!$C:$C,1024) -> 5.2592498 | F17: =SUMIFS(Chained!$U:$U,Chained!$A:$A,"MemoryStore->FileStore->LossyStore",Chained!$B:$B,5,Chained!$C:$C,4096) -> 7.8779521
A20: GAIN OVER LOSSLESS - bounded ratio / lossless ratio, standalone
A21: 1.00 would mean the bound bought nothing at that unit size.
A22: Configuration | B22: 16 KB | C22: 64 KB | D22: 256 KB | E22: 1024 KB | F22: 4096 KB
A23: LossyStore 0.1% | B23: =IFERROR(B7/B6,0) -> 1.4918453 | C23: =IFERROR(C7/C6,0) -> 1.3189202 | D23: =IFERROR(D7/D6,0) -> 1.3407371 | E23: =IFERROR(E7/E6,0) -> 1.2860051 | F23: =IFERROR(F7/F6,0) -> 1.3885329
A24: LossyStore 1% | B24: =IFERROR(B8/B6,0) -> 1.6528007 | C24: =IFERROR(C8/C6,0) -> 1.42251 | D24: =IFERROR(D8/D6,0) -> 1.483922 | E24: =IFERROR(E8/E6,0) -> 1.3922389 | F24: =IFERROR(F8/F6,0) -> 1.5434897
