Workbook

Sheet Read Me
A1: Solar panels, standalone tiers — Benchmark build
A2: One sheet per question. Sizes, ratios, timing, throughput, framing, and what of the time is actually the store.
A4: dataset | B4: debs_solar_panels, 42,700,000 rows x 28 B = 1,195,600,000 B stored
A5: configurations | B5: 6 standalone tiers
A6: unit sizes | B6: 256 KB, 1024 KB, 4096 KB, 16384 KB (FileStore segment / LossyStore group / CompressedStore segment, set equal)
A7: capacity | B7: FileStore totalSize 4096 MB over 4 files
A8: build | B8: Benchmark
A9: repeats | B9: 256 KB: N=1, 1024 KB: N=1, 4096 KB: N=3, 16384 KB: N=1
A10: source | B10: solar_standalone_release.csv (merged from four per-unit CSVs)
A12: WHAT IS NEW HERE
A13: the build | B13: Benchmark (-O3, NO_ASSERT, log level NONE), not the Debug build every other CSV in results/ was measured in. On the read path Debug is ~88% build overhead, enough to put FileStore -- which decodes nothing -- within 2% of LossyStore at 1%, which runs three decode stages.
A14: the baseline | B14: Every row carries baseline_s: the same query with no store at all. store_write_s = encode_s - baseline_s. Without it a store's cost could only be quoted as an absolute, and on this workload three quarters of a write query is the CSV parse.
A15: the store fixes | B15: Two FileStore defects were fixed between the Debug sweep and this one (commits 6ba85c1cbb, 1492ece8a7). The second mattered: FileStore's read-back was 113.6 s at a 16384 KB unit against a 93 s median, and is now on the pack median. Decode figures here are not comparable to the Debug sweep's; byte counts are, and reproduce exactly.
A17: WHAT A TIME HERE IS
B18: systest reports stop - running. Registration, planning, query compilation and opening the store happen before `running` and are NOT included. Nothing here is a codec step time: no store carries a timer, so encode and decode cannot be separated from the query that drives them. That needs the microbenchmark.

Sheet Summary
A1: Summary
A2: Four charts, and what each one settles.
A4: 1. BYTES ON DISK
A5: Configuration | B5: 256 KB | C5: 1024 KB | D5: 4096 KB | E5: 16384 KB
A6: FileStore (raw) | B6: =SUMIFS(Data!$P:$P,Data!$C:$C,"FileStore",Data!$E:$E,"",Data!$F:$F,256) -> 1195928436 | C6: =SUMIFS(Data!$P:$P,Data!$C:$C,"FileStore",Data!$E:$E,"",Data!$F:$F,1024) -> 1195682676 | D6: =SUMIFS(Data!$P:$P,Data!$C:$C,"FileStore",Data!$E:$E,"",Data!$F:$F,4096) -> 1195621236 | E6: =SUMIFS(Data!$P:$P,Data!$C:$C,"FileStore",Data!$E:$E,"",Data!$F:$F,16384) -> 1195605876
A7: CompressedStore | B7: =SUMIFS(Data!$P:$P,Data!$C:$C,"CompressedStore",Data!$E:$E,"",Data!$F:$F,256) -> 724616220 | C7: =SUMIFS(Data!$P:$P,Data!$C:$C,"CompressedStore",Data!$E:$E,"",Data!$F:$F,1024) -> 723908636 | D7: =SUMIFS(Data!$P:$P,Data!$C:$C,"CompressedStore",Data!$E:$E,"",Data!$F:$F,4096) -> 723778560 | E7: =SUMIFS(Data!$P:$P,Data!$C:$C,"CompressedStore",Data!$E:$E,"",Data!$F:$F,16384) -> 723748236
A8: LossyStore lossless | B8: =SUMIFS(Data!$P:$P,Data!$C:$C,"LossyStore",Data!$E:$E,"",Data!$F:$F,256) -> 643275922 | C8: =SUMIFS(Data!$P:$P,Data!$C:$C,"LossyStore",Data!$E:$E,"",Data!$F:$F,1024) -> 640065281 | D8: =SUMIFS(Data!$P:$P,Data!$C:$C,"LossyStore",Data!$E:$E,"",Data!$F:$F,4096) -> 646112362 | E8: =SUMIFS(Data!$P:$P,Data!$C:$C,"LossyStore",Data!$E:$E,"",Data!$F:$F,16384) -> 651555712
A9: LossyStore 0.1% | B9: =SUMIFS(Data!$P:$P,Data!$C:$C,"LossyStore",Data!$E:$E,"0.1",Data!$F:$F,256) -> 395581079 | C9: =SUMIFS(Data!$P:$P,Data!$C:$C,"LossyStore",Data!$E:$E,"0.1",Data!$F:$F,1024) -> 405584451 | D9: =SUMIFS(Data!$P:$P,Data!$C:$C,"LossyStore",Data!$E:$E,"0.1",Data!$F:$F,4096) -> 415788665 | E9: =SUMIFS(Data!$P:$P,Data!$C:$C,"LossyStore",Data!$E:$E,"0.1",Data!$F:$F,16384) -> 422752179
A10: LossyStore 1% | B10: =SUMIFS(Data!$P:$P,Data!$C:$C,"LossyStore",Data!$E:$E,"1",Data!$F:$F,256) -> 374923574 | C10: =SUMIFS(Data!$P:$P,Data!$C:$C,"LossyStore",Data!$E:$E,"1",Data!$F:$F,1024) -> 385519644 | D10: =SUMIFS(Data!$P:$P,Data!$C:$C,"LossyStore",Data!$E:$E,"1",Data!$F:$F,4096) -> 396473093 | E10: =SUMIFS(Data!$P:$P,Data!$C:$C,"LossyStore",Data!$E:$E,"1",Data!$F:$F,16384) -> 402276030
A11: LossyStore 5% | B11: =SUMIFS(Data!$P:$P,Data!$C:$C,"LossyStore",Data!$E:$E,"5",Data!$F:$F,256) -> 362075569 | C11: =SUMIFS(Data!$P:$P,Data!$C:$C,"LossyStore",Data!$E:$E,"5",Data!$F:$F,1024) -> 370424249 | D11: =SUMIFS(Data!$P:$P,Data!$C:$C,"LossyStore",Data!$E:$E,"5",Data!$F:$F,4096) -> 378290835 | E11: =SUMIFS(Data!$P:$P,Data!$C:$C,"LossyStore",Data!$E:$E,"5",Data!$F:$F,16384) -> 380812616
A35: WHAT THIS SHOWS | B35: What each configuration costs in storage.
A36: WHAT TO LOOK FOR | B36: 834 MB separates raw rows from LossyStore at 5%. That is the decision this whole tier exists to make.
A38: 2. COMPRESSION RATIO
A39: Configuration | B39: 256 KB | C39: 1024 KB | D39: 4096 KB | E39: 16384 KB
A40: FileStore (raw) | B40: =SUMIFS(Data!$T:$T,Data!$C:$C,"FileStore",Data!$E:$E,"",Data!$F:$F,256) -> 0.999725 | C40: =SUMIFS(Data!$T:$T,Data!$C:$C,"FileStore",Data!$E:$E,"",Data!$F:$F,1024) -> 0.999931 | D40: =SUMIFS(Data!$T:$T,Data!$C:$C,"FileStore",Data!$E:$E,"",Data!$F:$F,4096) -> 0.999982 | E40: =SUMIFS(Data!$T:$T,Data!$C:$C,"FileStore",Data!$E:$E,"",Data!$F:$F,16384) -> 0.999995
A41: CompressedStore | B41: =SUMIFS(Data!$T:$T,Data!$C:$C,"CompressedStore",Data!$E:$E,"",Data!$F:$F,256) -> 1.649977 | C41: =SUMIFS(Data!$T:$T,Data!$C:$C,"CompressedStore",Data!$E:$E,"",Data!$F:$F,1024) -> 1.65159 | D41: =SUMIFS(Data!$T:$T,Data!$C:$C,"CompressedStore",Data!$E:$E,"",Data!$F:$F,4096) -> 1.651886 | E41: =SUMIFS(Data!$T:$T,Data!$C:$C,"CompressedStore",Data!$E:$E,"",Data!$F:$F,16384) -> 1.651956
A42: LossyStore lossless | B42: =SUMIFS(Data!$T:$T,Data!$C:$C,"LossyStore",Data!$E:$E,"",Data!$F:$F,256) -> 1.858611 | C42: =SUMIFS(Data!$T:$T,Data!$C:$C,"LossyStore",Data!$E:$E,"",Data!$F:$F,1024) -> 1.867934 | D42: =SUMIFS(Data!$T:$T,Data!$C:$C,"LossyStore",Data!$E:$E,"",Data!$F:$F,4096) -> 1.850452 | E42: =SUMIFS(Data!$T:$T,Data!$C:$C,"LossyStore",Data!$E:$E,"",Data!$F:$F,16384) -> 1.834993
A43: LossyStore 0.1% | B43: =SUMIFS(Data!$T:$T,Data!$C:$C,"LossyStore",Data!$E:$E,"0.1",Data!$F:$F,256) -> 3.022389 | C43: =SUMIFS(Data!$T:$T,Data!$C:$C,"LossyStore",Data!$E:$E,"0.1",Data!$F:$F,1024) -> 2.947845 | D43: =SUMIFS(Data!$T:$T,Data!$C:$C,"LossyStore",Data!$E:$E,"0.1",Data!$F:$F,4096) -> 2.875499 | E43: =SUMIFS(Data!$T:$T,Data!$C:$C,"LossyStore",Data!$E:$E,"0.1",Data!$F:$F,16384) -> 2.828134
A44: LossyStore 1% | B44: =SUMIFS(Data!$T:$T,Data!$C:$C,"LossyStore",Data!$E:$E,"1",Data!$F:$F,256) -> 3.188917 | C44: =SUMIFS(Data!$T:$T,Data!$C:$C,"LossyStore",Data!$E:$E,"1",Data!$F:$F,1024) -> 3.101269 | D44: =SUMIFS(Data!$T:$T,Data!$C:$C,"LossyStore",Data!$E:$E,"1",Data!$F:$F,4096) -> 3.015589 | E44: =SUMIFS(Data!$T:$T,Data!$C:$C,"LossyStore",Data!$E:$E,"1",Data!$F:$F,16384) -> 2.972089
A45: LossyStore 5% | B45: =SUMIFS(Data!$T:$T,Data!$C:$C,"LossyStore",Data!$E:$E,"5",Data!$F:$F,256) -> 3.302073 | C45: =SUMIFS(Data!$T:$T,Data!$C:$C,"LossyStore",Data!$E:$E,"5",Data!$F:$F,1024) -> 3.22765 | D45: =SUMIFS(Data!$T:$T,Data!$C:$C,"LossyStore",Data!$E:$E,"5",Data!$F:$F,4096) -> 3.160531 | E45: =SUMIFS(Data!$T:$T,Data!$C:$C,"LossyStore",Data!$E:$E,"5",Data!$F:$F,16384) -> 3.139602
A69: WHAT THIS SHOWS | B69: The same thing as a factor, against unit size.
A70: WHAT TO LOOK FOR | B70: Build-independent and reproduces the Debug sweep exactly. Smaller units compress BETTER on the bounded paths -- 256 KB is the best setting on both ratio and, per the Timing sheet, it costs nothing to choose it.
A72: 3. WRITE QUERY, AGAINST A QUERY WITH NO STORE
A73: Configuration | B73: 256 KB | C73: 1024 KB | D73: 4096 KB | E73: 16384 KB
A74: FileStore (raw) | B74: =SUMIFS(Data!$L:$L,Data!$C:$C,"FileStore",Data!$E:$E,"",Data!$F:$F,256) -> 27.8315 | C74: =SUMIFS(Data!$L:$L,Data!$C:$C,"FileStore",Data!$E:$E,"",Data!$F:$F,1024) -> 27.5565 | D74: =SUMIFS(Data!$L:$L,Data!$C:$C,"FileStore",Data!$E:$E,"",Data!$F:$F,4096) -> 28.4896 | E74: =SUMIFS(Data!$L:$L,Data!$C:$C,"FileStore",Data!$E:$E,"",Data!$F:$F,16384) -> 27.8012
A75: CompressedStore | B75: =SUMIFS(Data!$L:$L,Data!$C:$C,"CompressedStore",Data!$E:$E,"",Data!$F:$F,256) -> 34.0164 | C75: =SUMIFS(Data!$L:$L,Data!$C:$C,"CompressedStore",Data!$E:$E,"",Data!$F:$F,1024) -> 33.1633 | D75: =SUMIFS(Data!$L:$L,Data!$C:$C,"CompressedStore",Data!$E:$E,"",Data!$F:$F,4096) -> 34.3937 | E75: =SUMIFS(Data!$L:$L,Data!$C:$C,"CompressedStore",Data!$E:$E,"",Data!$F:$F,16384) -> 36.2321
A76: LossyStore lossless | B76: =SUMIFS(Data!$L:$L,Data!$C:$C,"LossyStore",Data!$E:$E,"",Data!$F:$F,256) -> 32.017 | C76: =SUMIFS(Data!$L:$L,Data!$C:$C,"LossyStore",Data!$E:$E,"",Data!$F:$F,1024) -> 31.0179 | D76: =SUMIFS(Data!$L:$L,Data!$C:$C,"LossyStore",Data!$E:$E,"",Data!$F:$F,4096) -> 32.7766 | E76: =SUMIFS(Data!$L:$L,Data!$C:$C,"LossyStore",Data!$E:$E,"",Data!$F:$F,16384) -> 32.6821
A77: LossyStore 0.1% | B77: =SUMIFS(Data!$L:$L,Data!$C:$C,"LossyStore",Data!$E:$E,"0.1",Data!$F:$F,256) -> 31.9136 | C77: =SUMIFS(Data!$L:$L,Data!$C:$C,"LossyStore",Data!$E:$E,"0.1",Data!$F:$F,1024) -> 30.3721 | D77: =SUMIFS(Data!$L:$L,Data!$C:$C,"LossyStore",Data!$E:$E,"0.1",Data!$F:$F,4096) -> 30.7451 | E77: =SUMIFS(Data!$L:$L,Data!$C:$C,"LossyStore",Data!$E:$E,"0.1",Data!$F:$F,16384) -> 30.7901
A78: LossyStore 1% | B78: =SUMIFS(Data!$L:$L,Data!$C:$C,"LossyStore",Data!$E:$E,"1",Data!$F:$F,256) -> 31.7757 | C78: =SUMIFS(Data!$L:$L,Data!$C:$C,"LossyStore",Data!$E:$E,"1",Data!$F:$F,1024) -> 30.9375 | D78: =SUMIFS(Data!$L:$L,Data!$C:$C,"LossyStore",Data!$E:$E,"1",Data!$F:$F,4096) -> 31.1061 | E78: =SUMIFS(Data!$L:$L,Data!$C:$C,"LossyStore",Data!$E:$E,"1",Data!$F:$F,16384) -> 30.5885
A79: LossyStore 5% | B79: =SUMIFS(Data!$L:$L,Data!$C:$C,"LossyStore",Data!$E:$E,"5",Data!$F:$F,256) -> 31.8938 | C79: =SUMIFS(Data!$L:$L,Data!$C:$C,"LossyStore",Data!$E:$E,"5",Data!$F:$F,1024) -> 30.5255 | D79: =SUMIFS(Data!$L:$L,Data!$C:$C,"LossyStore",Data!$E:$E,"5",Data!$F:$F,4096) -> 31.7295 | E79: =SUMIFS(Data!$L:$L,Data!$C:$C,"LossyStore",Data!$E:$E,"5",Data!$F:$F,16384) -> 31.6
A80: normal query (no store) | B80: =SUMIFS(Data!$K:$K,Data!$C:$C,"FileStore",Data!$E:$E,"",Data!$F:$F,256) -> 20.7321 | C80: =SUMIFS(Data!$K:$K,Data!$C:$C,"FileStore",Data!$E:$E,"",Data!$F:$F,1024) -> 20.7883 | D80: =SUMIFS(Data!$K:$K,Data!$C:$C,"FileStore",Data!$E:$E,"",Data!$F:$F,4096) -> 21.1554 | E80: =SUMIFS(Data!$K:$K,Data!$C:$C,"FileStore",Data!$E:$E,"",Data!$F:$F,16384) -> 20.7318
A104: WHAT THIS SHOWS | B104: Bars are the write query; the red line is the same query with no store. The gap is the store.
A105: WHAT TO LOOK FOR | B105: About two thirds of every bar lies below the line and is the CSV parse. The store itself is 6.8 to 15.5 s -- quoting encode_s alone overstates it three to four times.
A107: 4. READ-BACK, AGAINST A QUERY WITH NO STORE
A108: Configuration | B108: 256 KB | C108: 1024 KB | D108: 4096 KB | E108: 16384 KB
A109: FileStore (raw) | B109: =SUMIFS(Data!$M:$M,Data!$C:$C,"FileStore",Data!$E:$E,"",Data!$F:$F,256) -> 10.9249 | C109: =SUMIFS(Data!$M:$M,Data!$C:$C,"FileStore",Data!$E:$E,"",Data!$F:$F,1024) -> 10.2081 | D109: =SUMIFS(Data!$M:$M,Data!$C:$C,"FileStore",Data!$E:$E,"",Data!$F:$F,4096) -> 9.832 | E109: =SUMIFS(Data!$M:$M,Data!$C:$C,"FileStore",Data!$E:$E,"",Data!$F:$F,16384) -> 10.232
A110: CompressedStore | B110: =SUMIFS(Data!$M:$M,Data!$C:$C,"CompressedStore",Data!$E:$E,"",Data!$F:$F,256) -> 9.6512 | C110: =SUMIFS(Data!$M:$M,Data!$C:$C,"CompressedStore",Data!$E:$E,"",Data!$F:$F,1024) -> 9.5181 | D110: =SUMIFS(Data!$M:$M,Data!$C:$C,"CompressedStore",Data!$E:$E,"",Data!$F:$F,4096) -> 9.9165 | E110: =SUMIFS(Data!$M:$M,Data!$C:$C,"CompressedStore",Data!$E:$E,"",Data!$F:$F,16384) -> 9.8915
A111: LossyStore lossless | B111: =SUMIFS(Data!$M:$M,Data!$C:$C,"LossyStore",Data!$E:$E,"",Data!$F:$F,256) -> 10.3771 | C111: =SUMIFS(Data!$M:$M,Data!$C:$C,"LossyStore",Data!$E:$E,"",Data!$F:$F,1024) -> 9.8422 | D111: =SUMIFS(Data!$M:$M,Data!$C:$C,"LossyStore",Data!$E:$E,"",Data!$F:$F,4096) -> 9.9102 | E111: =SUMIFS(Data!$M:$M,Data!$C:$C,"LossyStore",Data!$E:$E,"",Data!$F:$F,16384) -> 9.9934
A112: LossyStore 0.1% | B112: =SUMIFS(Data!$M:$M,Data!$C:$C,"LossyStore",Data!$E:$E,"0.1",Data!$F:$F,256) -> 9.9668 | C112: =SUMIFS(Data!$M:$M,Data!$C:$C,"LossyStore",Data!$E:$E,"0.1",Data!$F:$F,1024) -> 9.9944 | D112: =SUMIFS(Data!$M:$M,Data!$C:$C,"LossyStore",Data!$E:$E,"0.1",Data!$F:$F,4096) -> 9.9176 | E112: =SUMIFS(Data!$M:$M,Data!$C:$C,"LossyStore",Data!$E:$E,"0.1",Data!$F:$F,16384) -> 9.9976
A113: LossyStore 1% | B113: =SUMIFS(Data!$M:$M,Data!$C:$C,"LossyStore",Data!$E:$E,"1",Data!$F:$F,256) -> 9.9096 | C113: =SUMIFS(Data!$M:$M,Data!$C:$C,"LossyStore",Data!$E:$E,"1",Data!$F:$F,1024) -> 9.9524 | D113: =SUMIFS(Data!$M:$M,Data!$C:$C,"LossyStore",Data!$E:$E,"1",Data!$F:$F,4096) -> 10.0552 | E113: =SUMIFS(Data!$M:$M,Data!$C:$C,"LossyStore",Data!$E:$E,"1",Data!$F:$F,16384) -> 9.9678
...

Sheet Data
A1: dataset | B1: configuration | C1: store_order | D1: tail_tier | E1: bound_pct | F1: unit_kb | G1: filestore_kb | H1: rows | I1: row_width_bytes | J1: bytes_in | K1: baseline_s | L1: encode_s | M1: decode_s | N1: store_write_s | O1: data_out | P1: disk_bytes | Q1: units | R1: framing_bytes | S1: ratio_on_data | T1: ratio_on_disk | U1: runs | V1: build | W1: filestore_segment_kb | X1: filestore_total_mb | Y1: filestore_files_at_capacity | Z1: filestore_flush_threshold_kb | AA1: lossystore_group_kb | AB1: compressedstore_segment_kb | AC1: compressedstore_level | AD1: memorystore_max_buffer_count | AE1: pool_buffer_bytes | AF1: flush_threshold | AG1: MemoryStore_data | AH1: MemoryStore_disk | AI1: FileStore_data | AJ1: FileStore_disk | AK1: CompressedStore_data | AL1: CompressedStore_disk | AM1: LossyStore_data | AN1: LossyStore_disk
A2: debs_solar_panels | B2: standalone | C2: CompressedStore | D2: CompressedStore | F2: 256 | G2: 256 | H2: 42700000 | I2: 28 | J2: 1195600000 | K2: 20.7321 | L2: 34.0164 | M2: 9.6512 | N2: 13.2843 | O2: 724428841 | P2: 724616220 | Q2: 4561 | R2: 187379 | S2: 1.650404 | T2: 1.649977 | U2: 1 | V2: Benchmark | W2: 256 | X2: 4096 | Y2: 4 | Z2: 1048576 | AA2: 256 | AB2: 256 | AC2: 3 | AD2: 128 | AE2: 4096 | AF2: 1MB | AG2: 0 | AH2: 0 | AI2: 0 | AJ2: 0 | AK2: 724428841 | AL2: 724616220 | AM2: 0 | AN2: 0
A3: debs_solar_panels | B3: standalone | C3: FileStore | D3: FileStore | F3: 256 | G3: 256 | H3: 42700000 | I3: 28 | J3: 1195600000 | K3: 20.7321 | L3: 27.8315 | M3: 10.9249 | N3: 7.0994 | O3: 1195600000 | P3: 1195928436 | Q3: 4561 | R3: 328436 | S3: 1 | T3: 0.999725 | U3: 1 | V3: Benchmark | W3: 256 | X3: 4096 | Y3: 4 | Z3: 1048576 | AA3: 256 | AB3: 256 | AC3: 3 | AD3: 128 | AE3: 4096 | AF3: 1MB | AG3: 0 | AH3: 0 | AI3: 1195600000 | AJ3: 1195928436 | AK3: 0 | AL3: 0 | AM3: 0 | AN3: 0
A4: debs_solar_panels | B4: standalone | C4: LossyStore | D4: LossyStore | F4: 256 | G4: 256 | H4: 42700000 | I4: 28 | J4: 1195600000 | K4: 20.7321 | L4: 32.017 | M4: 10.3771 | N4: 11.2849 | O4: 642199148 | P4: 643275922 | Q4: 4561 | R4: 1076774 | S4: 1.861728 | T4: 1.858611 | U4: 1 | V4: Benchmark | W4: 256 | X4: 4096 | Y4: 4 | Z4: 1048576 | AA4: 256 | AB4: 256 | AC4: 3 | AD4: 128 | AE4: 4096 | AF4: 1MB | AG4: 0 | AH4: 0 | AI4: 0 | AJ4: 0 | AK4: 0 | AL4: 0 | AM4: 642199148 | AN4: 643275922
A5: debs_solar_panels | B5: standalone | C5: LossyStore | D5: LossyStore | E5: 0.1 | F5: 256 | G5: 256 | H5: 42700000 | I5: 28 | J5: 1195600000 | K5: 20.7321 | L5: 31.9136 | M5: 9.9668 | N5: 11.1815 | O5: 394504305 | P5: 395581079 | Q5: 4561 | R5: 1076774 | S5: 3.030639 | T5: 3.022389 | U5: 1 | V5: Benchmark | W5: 256 | X5: 4096 | Y5: 4 | Z5: 1048576 | AA5: 256 | AB5: 256 | AC5: 3 | AD5: 128 | AE5: 4096 | AF5: 1MB | AG5: 0 | AH5: 0 | AI5: 0 | AJ5: 0 | AK5: 0 | AL5: 0 | AM5: 394504305 | AN5: 395581079
A6: debs_solar_panels | B6: standalone | C6: LossyStore | D6: LossyStore | E6: 1 | F6: 256 | G6: 256 | H6: 42700000 | I6: 28 | J6: 1195600000 | K6: 20.7321 | L6: 31.7757 | M6: 9.9096 | N6: 11.0436 | O6: 373846800 | P6: 374923574 | Q6: 4561 | R6: 1076774 | S6: 3.198101 | T6: 3.188917 | U6: 1 | V6: Benchmark | W6: 256 | X6: 4096 | Y6: 4 | Z6: 1048576 | AA6: 256 | AB6: 256 | AC6: 3 | AD6: 128 | AE6: 4096 | AF6: 1MB | AG6: 0 | AH6: 0 | AI6: 0 | AJ6: 0 | AK6: 0 | AL6: 0 | AM6: 373846800 | AN6: 374923574
A7: debs_solar_panels | B7: standalone | C7: LossyStore | D7: LossyStore | E7: 5 | F7: 256 | G7: 256 | H7: 42700000 | I7: 28 | J7: 1195600000 | K7: 20.7321 | L7: 31.8938 | M7: 9.9197 | N7: 11.1617 | O7: 360998795 | P7: 362075569 | Q7: 4561 | R7: 1076774 | S7: 3.311922 | T7: 3.302073 | U7: 1 | V7: Benchmark | W7: 256 | X7: 4096 | Y7: 4 | Z7: 1048576 | AA7: 256 | AB7: 256 | AC7: 3 | AD7: 128 | AE7: 4096 | AF7: 1MB | AG7: 0 | AH7: 0 | AI7: 0 | AJ7: 0 | AK7: 0 | AL7: 0 | AM7: 360998795 | AN7: 362075569
A8: debs_solar_panels | B8: standalone | C8: CompressedStore | D8: CompressedStore | F8: 1024 | G8: 1024 | H8: 42700000 | I8: 28 | J8: 1195600000 | K8: 20.7883 | L8: 33.1633 | M8: 9.5181 | N8: 12.375 | O8: 723861477 | P8: 723908636 | Q8: 1141 | R8: 47159 | S8: 1.651697 | T8: 1.65159 | U8: 1 | V8: Benchmark | W8: 1024 | X8: 4096 | Y8: 4 | Z8: 1048576 | AA8: 1024 | AB8: 1024 | AC8: 3 | AD8: 128 | AE8: 4096 | AF8: 1MB | AG8: 0 | AH8: 0 | AI8: 0 | AJ8: 0 | AK8: 723861477 | AL8: 723908636 | AM8: 0 | AN8: 0
A9: debs_solar_panels | B9: standalone | C9: FileStore | D9: FileStore | F9: 1024 | G9: 1024 | H9: 42700000 | I9: 28 | J9: 1195600000 | K9: 20.7883 | L9: 27.5565 | M9: 10.2081 | N9: 6.7682 | O9: 1195600000 | P9: 1195682676 | Q9: 1141 | R9: 82676 | S9: 1 | T9: 0.999931 | U9: 1 | V9: Benchmark | W9: 1024 | X9: 4096 | Y9: 4 | Z9: 1048576 | AA9: 1024 | AB9: 1024 | AC9: 3 | AD9: 128 | AE9: 4096 | AF9: 1MB | AG9: 0 | AH9: 0 | AI9: 1195600000 | AJ9: 1195682676 | AK9: 0 | AL9: 0 | AM9: 0 | AN9: 0
A10: debs_solar_panels | B10: standalone | C10: LossyStore | D10: LossyStore | F10: 1024 | G10: 1024 | H10: 42700000 | I10: 28 | J10: 1195600000 | K10: 20.7883 | L10: 31.0179 | M10: 9.8422 | N10: 10.2296 | O10: 639795627 | P10: 640065281 | Q10: 1141 | R10: 269654 | S10: 1.868722 | T10: 1.867934 | U10: 1 | V10: Benchmark | W10: 1024 | X10: 4096 | Y10: 4 | Z10: 1048576 | AA10: 1024 | AB10: 1024 | AC10: 3 | AD10: 128 | AE10: 4096 | AF10: 1MB | AG10: 0 | AH10: 0 | AI10: 0 | AJ10: 0 | AK10: 0 | AL10: 0 | AM10: 639795627 | AN10: 640065281
A11: debs_solar_panels | B11: standalone | C11: LossyStore | D11: LossyStore | E11: 0.1 | F11: 1024 | G11: 1024 | H11: 42700000 | I11: 28 | J11: 1195600000 | K11: 20.7883 | L11: 30.3721 | M11: 9.9944 | N11: 9.5838 | O11: 405314797 | P11: 405584451 | Q11: 1141 | R11: 269654 | S11: 2.949806 | T11: 2.947845 | U11: 1 | V11: Benchmark | W11: 1024 | X11: 4096 | Y11: 4 | Z11: 1048576 | AA11: 1024 | AB11: 1024 | AC11: 3 | AD11: 128 | AE11: 4096 | AF11: 1MB | AG11: 0 | AH11: 0 | AI11: 0 | AJ11: 0 | AK11: 0 | AL11: 0 | AM11: 405314797 | AN11: 405584451
A12: debs_solar_panels | B12: standalone | C12: LossyStore | D12: LossyStore | E12: 1 | F12: 1024 | G12: 1024 | H12: 42700000 | I12: 28 | J12: 1195600000 | K12: 20.7883 | L12: 30.9375 | M12: 9.9524 | N12: 10.1492 | O12: 385249990 | P12: 385519644 | Q12: 1141 | R12: 269654 | S12: 3.103439 | T12: 3.101269 | U12: 1 | V12: Benchmark | W12: 1024 | X12: 4096 | Y12: 4 | Z12: 1048576 | AA12: 1024 | AB12: 1024 | AC12: 3 | AD12: 128 | AE12: 4096 | AF12: 1MB | AG12: 0 | AH12: 0 | AI12: 0 | AJ12: 0 | AK12: 0 | AL12: 0 | AM12: 385249990 | AN12: 385519644
A13: debs_solar_panels | B13: standalone | C13: LossyStore | D13: LossyStore | E13: 5 | F13: 1024 | G13: 1024 | H13: 42700000 | I13: 28 | J13: 1195600000 | K13: 20.7883 | L13: 30.5255 | M13: 10.7078 | N13: 9.7372 | O13: 370154595 | P13: 370424249 | Q13: 1141 | R13: 269654 | S13: 3.230002 | T13: 3.22765 | U13: 1 | V13: Benchmark | W13: 1024 | X13: 4096 | Y13: 4 | Z13: 1048576 | AA13: 1024 | AB13: 1024 | AC13: 3 | AD13: 128 | AE13: 4096 | AF13: 1MB | AG13: 0 | AH13: 0 | AI13: 0 | AJ13: 0 | AK13: 0 | AL13: 0 | AM13: 370154595 | AN13: 370424249
A14: debs_solar_panels | B14: standalone | C14: CompressedStore | D14: CompressedStore | F14: 4096 | G14: 4096 | H14: 42700000 | I14: 28 | J14: 1195600000 | K14: 21.1554 | L14: 34.3937 | M14: 9.9165 | N14: 13.2383 | O14: 723766456 | P14: 723778560 | Q14: 286 | R14: 12104 | S14: 1.651914 | T14: 1.651886 | U14: 3 | V14: Benchmark | W14: 4096 | X14: 4096 | Y14: 4 | Z14: 1048576 | AA14: 4096 | AB14: 4096 | AC14: 3 | AD14: 128 | AE14: 4096 | AF14: 1MB | AG14: 0 | AH14: 0 | AI14: 0 | AJ14: 0 | AK14: 723766456 | AL14: 723778560 | AM14: 0 | AN14: 0
A15: debs_solar_panels | B15: standalone | C15: FileStore | D15: FileStore | F15: 4096 | G15: 4096 | H15: 42700000 | I15: 28 | J15: 1195600000 | K15: 21.1554 | L15: 28.4896 | M15: 9.832 | N15: 7.3342 | O15: 1195600000 | P15: 1195621236 | Q15: 286 | R15: 21236 | S15: 1 | T15: 0.999982 | U15: 3 | V15: Benchmark | W15: 4096 | X15: 4096 | Y15: 4 | Z15: 1048576 | AA15: 4096 | AB15: 4096 | AC15: 3 | AD15: 128 | AE15: 4096 | AF15: 1MB | AG15: 0 | AH15: 0 | AI15: 1195600000 | AJ15: 1195621236 | AK15: 0 | AL15: 0 | AM15: 0 | AN15: 0
A16: debs_solar_panels | B16: standalone | C16: LossyStore | D16: LossyStore | F16: 4096 | G16: 4096 | H16: 42700000 | I16: 28 | J16: 1195600000 | K16: 21.1554 | L16: 32.7766 | M16: 9.9102 | N16: 11.6212 | O16: 646044488 | P16: 646112362 | Q16: 286 | R16: 67874 | S16: 1.850647 | T16: 1.850452 | U16: 3 | V16: Benchmark | W16: 4096 | X16: 4096 | Y16: 4 | Z16: 1048576 | AA16: 4096 | AB16: 4096 | AC16: 3 | AD16: 128 | AE16: 4096 | AF16: 1MB | AG16: 0 | AH16: 0 | AI16: 0 | AJ16: 0 | AK16: 0 | AL16: 0 | AM16: 646044488 | AN16: 646112362
A17: debs_solar_panels | B17: standalone | C17: LossyStore | D17: LossyStore | E17: 0.1 | F17: 4096 | G17: 4096 | H17: 42700000 | I17: 28 | J17: 1195600000 | K17: 21.1554 | L17: 30.7451 | M17: 9.9176 | N17: 9.5897 | O17: 415720791 | P17: 415788665 | Q17: 286 | R17: 67874 | S17: 2.875969 | T17: 2.875499 | U17: 3 | V17: Benchmark | W17: 4096 | X17: 4096 | Y17: 4 | Z17: 1048576 | AA17: 4096 | AB17: 4096 | AC17: 3 | AD17: 128 | AE17: 4096 | AF17: 1MB | AG17: 0 | AH17: 0 | AI17: 0 | AJ17: 0 | AK17: 0 | AL17: 0 | AM17: 415720791 | AN17: 415788665
A18: debs_solar_panels | B18: standalone | C18: LossyStore | D18: LossyStore | E18: 1 | F18: 4096 | G18: 4096 | H18: 42700000 | I18: 28 | J18: 1195600000 | K18: 21.1554 | L18: 31.1061 | M18: 10.0552 | N18: 9.9507 | O18: 396405219 | P18: 396473093 | Q18: 286 | R18: 67874 | S18: 3.016106 | T18: 3.015589 | U18: 3 | V18: Benchmark | W18: 4096 | X18: 4096 | Y18: 4 | Z18: 1048576 | AA18: 4096 | AB18: 4096 | AC18: 3 | AD18: 128 | AE18: 4096 | AF18: 1MB | AG18: 0 | AH18: 0 | AI18: 0 | AJ18: 0 | AK18: 0 | AL18: 0 | AM18: 396405219 | AN18: 396473093
A19: debs_solar_panels | B19: standalone | C19: LossyStore | D19: LossyStore | E19: 5 | F19: 4096 | G19: 4096 | H19: 42700000 | I19: 28 | J19: 1195600000 | K19: 21.1554 | L19: 31.7295 | M19: 9.8691 | N19: 10.5741 | O19: 378222961 | P19: 378290835 | Q19: 286 | R19: 67874 | S19: 3.161098 | T19: 3.160531 | U19: 3 | V19: Benchmark | W19: 4096 | X19: 4096 | Y19: 4 | Z19: 1048576 | AA19: 4096 | AB19: 4096 | AC19: 3 | AD19: 128 | AE19: 4096 | AF19: 1MB | AG19: 0 | AH19: 0 | AI19: 0 | AJ19: 0 | AK19: 0 | AL19: 0 | AM19: 378222961 | AN19: 378290835
A20: debs_solar_panels | B20: standalone | C20: CompressedStore | D20: CompressedStore | F20: 16384 | G20: 16384 | H20: 42700000 | I20: 28 | J20: 1195600000 | K20: 20.7318 | L20: 36.2321 | M20: 9.8915 | N20: 15.5003 | O20: 723744906 | P20: 723748236 | Q20: 72 | R20: 3330 | S20: 1.651963 | T20: 1.651956 | U20: 1 | V20: Benchmark | W20: 16384 | X20: 4096 | Y20: 4 | Z20: 1048576 | AA20: 16384 | AB20: 16384 | AC20: 3 | AD20: 128 | AE20: 4096 | AF20: 1MB | AG20: 0 | AH20: 0 | AI20: 0 | AJ20: 0 | AK20: 723744906 | AL20: 723748236 | AM20: 0 | AN20: 0
A21: debs_solar_panels | B21: standalone | C21: FileStore | D21: FileStore | F21: 16384 | G21: 16384 | H21: 42700000 | I21: 28 | J21: 1195600000 | K21: 20.7318 | L21: 27.8012 | M21: 10.232 | N21: 7.0694 | O21: 1195600000 | P21: 1195605876 | Q21: 72 | R21: 5876 | S21: 1 | T21: 0.999995 | U21: 1 | V21: Benchmark | W21: 16384 | X21: 4096 | Y21: 4 | Z21: 1048576 | AA21: 16384 | AB21: 16384 | AC21: 3 | AD21: 128 | AE21: 4096 | AF21: 1MB | AG21: 0 | AH21: 0 | AI21: 1195600000 | AJ21: 1195605876 | AK21: 0 | AL21: 0 | AM21: 0 | AN21: 0
A22: debs_solar_panels | B22: standalone | C22: LossyStore | D22: LossyStore | F22: 16384 | G22: 16384 | H22: 42700000 | I22: 28 | J22: 1195600000 | K22: 20.7318 | L22: 32.6821 | M22: 9.9934 | N22: 11.9503 | O22: 651538342 | P22: 651555712 | Q22: 72 | R22: 17370 | S22: 1.835042 | T22: 1.834993 | U22: 1 | V22: Benchmark | W22: 16384 | X22: 4096 | Y22: 4 | Z22: 1048576 | AA22: 16384 | AB22: 16384 | AC22: 3 | AD22: 128 | AE22: 4096 | AF22: 1MB | AG22: 0 | AH22: 0 | AI22: 0 | AJ22: 0 | AK22: 0 | AL22: 0 | AM22: 651538342 | AN22: 651555712
A23: debs_solar_panels | B23: standalone | C23: LossyStore | D23: LossyStore | E23: 0.1 | F23: 16384 | G23: 16384 | H23: 42700000 | I23: 28 | J23: 1195600000 | K23: 20.7318 | L23: 30.7901 | M23: 9.9976 | N23: 10.0583 | O23: 422734809 | P23: 422752179 | Q23: 72 | R23: 17370 | S23: 2.828251 | T23: 2.828134 | U23: 1 | V23: Benchmark | W23: 16384 | X23: 4096 | Y23: 4 | Z23: 1048576 | AA23: 16384 | AB23: 16384 | AC23: 3 | AD23: 128 | AE23: 4096 | AF23: 1MB | AG23: 0 | AH23: 0 | AI23: 0 | AJ23: 0 | AK23: 0 | AL23: 0 | AM23: 422734809 | AN23: 422752179
A24: debs_solar_panels | B24: standalone | C24: LossyStore | D24: LossyStore | E24: 1 | F24: 16384 | G24: 16384 | H24: 42700000 | I24: 28 | J24: 1195600000 | K24: 20.7318 | L24: 30.5885 | M24: 9.9678 | N24: 9.8567 | O24: 402258660 | P24: 402276030 | Q24: 72 | R24: 17370 | S24: 2.972217 | T24: 2.972089 | U24: 1 | V24: Benchmark | W24: 16384 | X24: 4096 | Y24: 4 | Z24: 1048576 | AA24: 16384 | AB24: 16384 | AC24: 3 | AD24: 128 | AE24: 4096 | AF24: 1MB | AG24: 0 | AH24: 0 | AI24: 0 | AJ24: 0 | AK24: 0 | AL24: 0 | AM24: 402258660 | AN24: 402276030
A25: debs_solar_panels | B25: standalone | C25: LossyStore | D25: LossyStore | E25: 5 | F25: 16384 | G25: 16384 | H25: 42700000 | I25: 28 | J25: 1195600000 | K25: 20.7318 | L25: 31.6 | M25: 10.2527 | N25: 10.8682 | O25: 380795246 | P25: 380812616 | Q25: 72 | R25: 17370 | S25: 3.139745 | T25: 3.139602 | U25: 1 | V25: Benchmark | W25: 16384 | X25: 4096 | Y25: 4 | Z25: 1048576 | AA25: 16384 | AB25: 16384 | AC25: 3 | AD25: 128 | AE25: 4096 | AF25: 1MB | AG25: 0 | AH25: 0 | AI25: 0 | AJ25: 0 | AK25: 0 | AL25: 0 | AM25: 380795246 | AN25: 380812616

Sheet Sizes
A1: Sizes — what each configuration put on disk
A2: Bytes, not ratios. A ratio hides the thing a storage budget cares about: 796 MB is the decision, 3.19x is the summary.
A4: BYTES ON DISK (framing included)
A5: Configuration | B5: 256 KB | C5: 1024 KB | D5: 4096 KB | E5: 16384 KB
A6: FileStore (raw) | B6: =SUMIFS(Data!$P:$P,Data!$C:$C,"FileStore",Data!$E:$E,"",Data!$F:$F,256) -> 1195928436 | C6: =SUMIFS(Data!$P:$P,Data!$C:$C,"FileStore",Data!$E:$E,"",Data!$F:$F,1024) -> 1195682676 | D6: =SUMIFS(Data!$P:$P,Data!$C:$C,"FileStore",Data!$E:$E,"",Data!$F:$F,4096) -> 1195621236 | E6: =SUMIFS(Data!$P:$P,Data!$C:$C,"FileStore",Data!$E:$E,"",Data!$F:$F,16384) -> 1195605876
A7: CompressedStore | B7: =SUMIFS(Data!$P:$P,Data!$C:$C,"CompressedStore",Data!$E:$E,"",Data!$F:$F,256) -> 724616220 | C7: =SUMIFS(Data!$P:$P,Data!$C:$C,"CompressedStore",Data!$E:$E,"",Data!$F:$F,1024) -> 723908636 | D7: =SUMIFS(Data!$P:$P,Data!$C:$C,"CompressedStore",Data!$E:$E,"",Data!$F:$F,4096) -> 723778560 | E7: =SUMIFS(Data!$P:$P,Data!$C:$C,"CompressedStore",Data!$E:$E,"",Data!$F:$F,16384) -> 723748236
A8: LossyStore lossless | B8: =SUMIFS(Data!$P:$P,Data!$C:$C,"LossyStore",Data!$E:$E,"",Data!$F:$F,256) -> 643275922 | C8: =SUMIFS(Data!$P:$P,Data!$C:$C,"LossyStore",Data!$E:$E,"",Data!$F:$F,1024) -> 640065281 | D8: =SUMIFS(Data!$P:$P,Data!$C:$C,"LossyStore",Data!$E:$E,"",Data!$F:$F,4096) -> 646112362 | E8: =SUMIFS(Data!$P:$P,Data!$C:$C,"LossyStore",Data!$E:$E,"",Data!$F:$F,16384) -> 651555712
A9: LossyStore 0.1% | B9: =SUMIFS(Data!$P:$P,Data!$C:$C,"LossyStore",Data!$E:$E,"0.1",Data!$F:$F,256) -> 395581079 | C9: =SUMIFS(Data!$P:$P,Data!$C:$C,"LossyStore",Data!$E:$E,"0.1",Data!$F:$F,1024) -> 405584451 | D9: =SUMIFS(Data!$P:$P,Data!$C:$C,"LossyStore",Data!$E:$E,"0.1",Data!$F:$F,4096) -> 415788665 | E9: =SUMIFS(Data!$P:$P,Data!$C:$C,"LossyStore",Data!$E:$E,"0.1",Data!$F:$F,16384) -> 422752179
A10: LossyStore 1% | B10: =SUMIFS(Data!$P:$P,Data!$C:$C,"LossyStore",Data!$E:$E,"1",Data!$F:$F,256) -> 374923574 | C10: =SUMIFS(Data!$P:$P,Data!$C:$C,"LossyStore",Data!$E:$E,"1",Data!$F:$F,1024) -> 385519644 | D10: =SUMIFS(Data!$P:$P,Data!$C:$C,"LossyStore",Data!$E:$E,"1",Data!$F:$F,4096) -> 396473093 | E10: =SUMIFS(Data!$P:$P,Data!$C:$C,"LossyStore",Data!$E:$E,"1",Data!$F:$F,16384) -> 402276030
A11: LossyStore 5% | B11: =SUMIFS(Data!$P:$P,Data!$C:$C,"LossyStore",Data!$E:$E,"5",Data!$F:$F,256) -> 362075569 | C11: =SUMIFS(Data!$P:$P,Data!$C:$C,"LossyStore",Data!$E:$E,"5",Data!$F:$F,1024) -> 370424249 | D11: =SUMIFS(Data!$P:$P,Data!$C:$C,"LossyStore",Data!$E:$E,"5",Data!$F:$F,4096) -> 378290835 | E11: =SUMIFS(Data!$P:$P,Data!$C:$C,"LossyStore",Data!$E:$E,"5",Data!$F:$F,16384) -> 380812616
A35: WHAT THIS SHOWS | B35: The file each configuration left behind, container and all, at each unit size.
A36: WHAT TO LOOK FOR | B36: FileStore is flat at 1,195,928,436 B -- 42,700,000 rows x 28 B plus framing -- and is the reference every other bar is read against. The lossy bars GROW slightly as the unit grows, which is the opposite of what a reader expects and is explained on the Anomalies sheet.
A38: ENCODED BYTES (framing removed)
A39: What the codec produced, with the container subtracted. This is the number to compare codecs on; disk_bytes mixes in a per-unit overhead that has nothing to do with the codec.
A40: Configuration | B40: 256 KB | C40: 1024 KB | D40: 4096 KB | E40: 16384 KB
A41: FileStore (raw) | B41: =SUMIFS(Data!$O:$O,Data!$C:$C,"FileStore",Data!$E:$E,"",Data!$F:$F,256) -> 1195600000 | C41: =SUMIFS(Data!$O:$O,Data!$C:$C,"FileStore",Data!$E:$E,"",Data!$F:$F,1024) -> 1195600000 | D41: =SUMIFS(Data!$O:$O,Data!$C:$C,"FileStore",Data!$E:$E,"",Data!$F:$F,4096) -> 1195600000 | E41: =SUMIFS(Data!$O:$O,Data!$C:$C,"FileStore",Data!$E:$E,"",Data!$F:$F,16384) -> 1195600000
A42: CompressedStore | B42: =SUMIFS(Data!$O:$O,Data!$C:$C,"CompressedStore",Data!$E:$E,"",Data!$F:$F,256) -> 724428841 | C42: =SUMIFS(Data!$O:$O,Data!$C:$C,"CompressedStore",Data!$E:$E,"",Data!$F:$F,1024) -> 723861477 | D42: =SUMIFS(Data!$O:$O,Data!$C:$C,"CompressedStore",Data!$E:$E,"",Data!$F:$F,4096) -> 723766456 | E42: =SUMIFS(Data!$O:$O,Data!$C:$C,"CompressedStore",Data!$E:$E,"",Data!$F:$F,16384) -> 723744906
A43: LossyStore lossless | B43: =SUMIFS(Data!$O:$O,Data!$C:$C,"LossyStore",Data!$E:$E,"",Data!$F:$F,256) -> 642199148 | C43: =SUMIFS(Data!$O:$O,Data!$C:$C,"LossyStore",Data!$E:$E,"",Data!$F:$F,1024) -> 639795627 | D43: =SUMIFS(Data!$O:$O,Data!$C:$C,"LossyStore",Data!$E:$E,"",Data!$F:$F,4096) -> 646044488 | E43: =SUMIFS(Data!$O:$O,Data!$C:$C,"LossyStore",Data!$E:$E,"",Data!$F:$F,16384) -> 651538342
A44: LossyStore 0.1% | B44: =SUMIFS(Data!$O:$O,Data!$C:$C,"LossyStore",Data!$E:$E,"0.1",Data!$F:$F,256) -> 394504305 | C44: =SUMIFS(Data!$O:$O,Data!$C:$C,"LossyStore",Data!$E:$E,"0.1",Data!$F:$F,1024) -> 405314797 | D44: =SUMIFS(Data!$O:$O,Data!$C:$C,"LossyStore",Data!$E:$E,"0.1",Data!$F:$F,4096) -> 415720791 | E44: =SUMIFS(Data!$O:$O,Data!$C:$C,"LossyStore",Data!$E:$E,"0.1",Data!$F:$F,16384) -> 422734809
A45: LossyStore 1% | B45: =SUMIFS(Data!$O:$O,Data!$C:$C,"LossyStore",Data!$E:$E,"1",Data!$F:$F,256) -> 373846800 | C45: =SUMIFS(Data!$O:$O,Data!$C:$C,"LossyStore",Data!$E:$E,"1",Data!$F:$F,1024) -> 385249990 | D45: =SUMIFS(Data!$O:$O,Data!$C:$C,"LossyStore",Data!$E:$E,"1",Data!$F:$F,4096) -> 396405219 | E45: =SUMIFS(Data!$O:$O,Data!$C:$C,"LossyStore",Data!$E:$E,"1",Data!$F:$F,16384) -> 402258660
A46: LossyStore 5% | B46: =SUMIFS(Data!$O:$O,Data!$C:$C,"LossyStore",Data!$E:$E,"5",Data!$F:$F,256) -> 360998795 | C46: =SUMIFS(Data!$O:$O,Data!$C:$C,"LossyStore",Data!$E:$E,"5",Data!$F:$F,1024) -> 370154595 | D46: =SUMIFS(Data!$O:$O,Data!$C:$C,"LossyStore",Data!$E:$E,"5",Data!$F:$F,4096) -> 378222961 | E46: =SUMIFS(Data!$O:$O,Data!$C:$C,"LossyStore",Data!$E:$E,"5",Data!$F:$F,16384) -> 380795246
A70: WHAT THIS SHOWS | B70: The same configurations with framing taken out.
A71: WHAT TO LOOK FOR | B71: At a 256 KB unit the span runs from 1,195,600,000 B for FileStore down to 362 MB for LossyStore at 5% -- about 834 MB of difference, which is the actual decision. The ratio chart on the next sheet cannot tell you that.
A73: BYTES SAVED AGAINST FileStore
A74: FileStore's bytes minus this configuration's. The row for FileStore is zero by construction.
A75: Configuration | B75: 256 KB | C75: 1024 KB | D75: 4096 KB | E75: 16384 KB
A76: FileStore (raw) | B76: =SUMIFS(Data!$P:$P,Data!$C:$C,"FileStore",Data!$E:$E,"",Data!$F:$F,256)-SUMIFS(Data!$P:$P,Data!$C:$C,"FileStore",Data!$E:$E,"",Data!$F:$F,256) -> 0 | C76: =SUMIFS(Data!$P:$P,Data!$C:$C,"FileStore",Data!$E:$E,"",Data!$F:$F,1024)-SUMIFS(Data!$P:$P,Data!$C:$C,"FileStore",Data!$E:$E,"",Data!$F:$F,1024) -> 0 | D76: =SUMIFS(Data!$P:$P,Data!$C:$C,"FileStore",Data!$E:$E,"",Data!$F:$F,4096)-SUMIFS(Data!$P:$P,Data!$C:$C,"FileStore",Data!$E:$E,"",Data!$F:$F,4096) -> 0 | E76: =SUMIFS(Data!$P:$P,Data!$C:$C,"FileStore",Data!$E:$E,"",Data!$F:$F,16384)-SUMIFS(Data!$P:$P,Data!$C:$C,"FileStore",Data!$E:$E,"",Data!$F:$F,16384) -> 0
A77: CompressedStore | B77: =SUMIFS(Data!$P:$P,Data!$C:$C,"FileStore",Data!$E:$E,"",Data!$F:$F,256)-SUMIFS(Data!$P:$P,Data!$C:$C,"CompressedStore",Data!$E:$E,"",Data!$F:$F,256) -> 471312216 | C77: =SUMIFS(Data!$P:$P,Data!$C:$C,"FileStore",Data!$E:$E,"",Data!$F:$F,1024)-SUMIFS(Data!$P:$P,Data!$C:$C,"CompressedStore",Data!$E:$E,"",Data!$F:$F,1024) -> 471774040 | D77: =SUMIFS(Data!$P:$P,Data!$C:$C,"FileStore",Data!$E:$E,"",Data!$F:$F,4096)-SUMIFS(Data!$P:$P,Data!$C:$C,"CompressedStore",Data!$E:$E,"",Data!$F:$F,4096) -> 471842676 | E77: =SUMIFS(Data!$P:$P,Data!$C:$C,"FileStore",Data!$E:$E,"",Data!$F:$F,16384)-SUMIFS(Data!$P:$P,Data!$C:$C,"CompressedStore",Data!$E:$E,"",Data!$F:$F,16384) -> 471857640
A78: LossyStore lossless | B78: =SUMIFS(Data!$P:$P,Data!$C:$C,"FileStore",Data!$E:$E,"",Data!$F:$F,256)-SUMIFS(Data!$P:$P,Data!$C:$C,"LossyStore",Data!$E:$E,"",Data!$F:$F,256) -> 552652514 | C78: =SUMIFS(Data!$P:$P,Data!$C:$C,"FileStore",Data!$E:$E,"",Data!$F:$F,1024)-SUMIFS(Data!$P:$P,Data!$C:$C,"LossyStore",Data!$E:$E,"",Data!$F:$F,1024) -> 555617395 | D78: =SUMIFS(Data!$P:$P,Data!$C:$C,"FileStore",Data!$E:$E,"",Data!$F:$F,4096)-SUMIFS(Data!$P:$P,Data!$C:$C,"LossyStore",Data!$E:$E,"",Data!$F:$F,4096) -> 549508874 | E78: =SUMIFS(Data!$P:$P,Data!$C:$C,"FileStore",Data!$E:$E,"",Data!$F:$F,16384)-SUMIFS(Data!$P:$P,Data!$C:$C,"LossyStore",Data!$E:$E,"",Data!$F:$F,16384) -> 544050164
A79: LossyStore 0.1% | B79: =SUMIFS(Data!$P:$P,Data!$C:$C,"FileStore",Data!$E:$E,"",Data!$F:$F,256)-SUMIFS(Data!$P:$P,Data!$C:$C,"LossyStore",Data!$E:$E,"0.1",Data!$F:$F,256) -> 800347357 | C79: =SUMIFS(Data!$P:$P,Data!$C:$C,"FileStore",Data!$E:$E,"",Data!$F:$F,1024)-SUMIFS(Data!$P:$P,Data!$C:$C,"LossyStore",Data!$E:$E,"0.1",Data!$F:$F,1024) -> 790098225 | D79: =SUMIFS(Data!$P:$P,Data!$C:$C,"FileStore",Data!$E:$E,"",Data!$F:$F,4096)-SUMIFS(Data!$P:$P,Data!$C:$C,"LossyStore",Data!$E:$E,"0.1",Data!$F:$F,4096) -> 779832571 | E79: =SUMIFS(Data!$P:$P,Data!$C:$C,"FileStore",Data!$E:$E,"",Data!$F:$F,16384)-SUMIFS(Data!$P:$P,Data!$C:$C,"LossyStore",Data!$E:$E,"0.1",Data!$F:$F,16384) -> 772853697
A80: LossyStore 1% | B80: =SUMIFS(Data!$P:$P,Data!$C:$C,"FileStore",Data!$E:$E,"",Data!$F:$F,256)-SUMIFS(Data!$P:$P,Data!$C:$C,"LossyStore",Data!$E:$E,"1",Data!$F:$F,256) -> 821004862 | C80: =SUMIFS(Data!$P:$P,Data!$C:$C,"FileStore",Data!$E:$E,"",Data!$F:$F,1024)-SUMIFS(Data!$P:$P,Data!$C:$C,"LossyStore",Data!$E:$E,"1",Data!$F:$F,1024) -> 810163032 | D80: =SUMIFS(Data!$P:$P,Data!$C:$C,"FileStore",Data!$E:$E,"",Data!$F:$F,4096)-SUMIFS(Data!$P:$P,Data!$C:$C,"LossyStore",Data!$E:$E,"1",Data!$F:$F,4096) -> 799148143 | E80: =SUMIFS(Data!$P:$P,Data!$C:$C,"FileStore",Data!$E:$E,"",Data!$F:$F,16384)-SUMIFS(Data!$P:$P,Data!$C:$C,"LossyStore",Data!$E:$E,"1",Data!$F:$F,16384) -> 793329846
A81: LossyStore 5% | B81: =SUMIFS(Data!$P:$P,Data!$C:$C,"FileStore",Data!$E:$E,"",Data!$F:$F,256)-SUMIFS(Data!$P:$P,Data!$C:$C,"LossyStore",Data!$E:$E,"5",Data!$F:$F,256) -> 833852867 | C81: =SUMIFS(Data!$P:$P,Data!$C:$C,"FileStore",Data!$E:$E,"",Data!$F:$F,1024)-SUMIFS(Data!$P:$P,Data!$C:$C,"LossyStore",Data!$E:$E,"5",Data!$F:$F,1024) -> 825258427 | D81: =SUMIFS(Data!$P:$P,Data!$C:$C,"FileStore",Data!$E:$E,"",Data!$F:$F,4096)-SUMIFS(Data!$P:$P,Data!$C:$C,"LossyStore",Data!$E:$E,"5",Data!$F:$F,4096) -> 817330401 | E81: =SUMIFS(Data!$P:$P,Data!$C:$C,"FileStore",Data!$E:$E,"",Data!$F:$F,16384)-SUMIFS(Data!$P:$P,Data!$C:$C,"LossyStore",Data!$E:$E,"5",Data!$F:$F,16384) -> 814793260
A105: WHAT THIS SHOWS | B105: How many bytes each configuration avoided writing, against storing the rows raw. FileStore is excluded from the chart, being zero.
A106: WHAT TO LOOK FOR | B106: LossyStore at 5% saves about 834 MB at a 256 KB unit and 810 MB at 16384 KB. zstd alone saves 471 MB and does not move with the unit size at all.

Sheet Ratios
A1: Ratios — the same thing as a factor
A2: Useful for comparing configurations with each other. Not a substitute for the Sizes sheet when the question is how much disk is needed.
A4: RATIO ON DISK (stored bytes / bytes on disk)
A5: Configuration | B5: 256 KB | C5: 1024 KB | D5: 4096 KB | E5: 16384 KB
A6: FileStore (raw) | B6: =SUMIFS(Data!$T:$T,Data!$C:$C,"FileStore",Data!$E:$E,"",Data!$F:$F,256) -> 0.999725 | C6: =SUMIFS(Data!$T:$T,Data!$C:$C,"FileStore",Data!$E:$E,"",Data!$F:$F,1024) -> 0.999931 | D6: =SUMIFS(Data!$T:$T,Data!$C:$C,"FileStore",Data!$E:$E,"",Data!$F:$F,4096) -> 0.999982 | E6: =SUMIFS(Data!$T:$T,Data!$C:$C,"FileStore",Data!$E:$E,"",Data!$F:$F,16384) -> 0.999995
A7: CompressedStore | B7: =SUMIFS(Data!$T:$T,Data!$C:$C,"CompressedStore",Data!$E:$E,"",Data!$F:$F,256) -> 1.649977 | C7: =SUMIFS(Data!$T:$T,Data!$C:$C,"CompressedStore",Data!$E:$E,"",Data!$F:$F,1024) -> 1.65159 | D7: =SUMIFS(Data!$T:$T,Data!$C:$C,"CompressedStore",Data!$E:$E,"",Data!$F:$F,4096) -> 1.651886 | E7: =SUMIFS(Data!$T:$T,Data!$C:$C,"CompressedStore",Data!$E:$E,"",Data!$F:$F,16384) -> 1.651956
A8: LossyStore lossless | B8: =SUMIFS(Data!$T:$T,Data!$C:$C,"LossyStore",Data!$E:$E,"",Data!$F:$F,256) -> 1.858611 | C8: =SUMIFS(Data!$T:$T,Data!$C:$C,"LossyStore",Data!$E:$E,"",Data!$F:$F,1024) -> 1.867934 | D8: =SUMIFS(Data!$T:$T,Data!$C:$C,"LossyStore",Data!$E:$E,"",Data!$F:$F,4096) -> 1.850452 | E8: =SUMIFS(Data!$T:$T,Data!$C:$C,"LossyStore",Data!$E:$E,"",Data!$F:$F,16384) -> 1.834993
A9: LossyStore 0.1% | B9: =SUMIFS(Data!$T:$T,Data!$C:$C,"LossyStore",Data!$E:$E,"0.1",Data!$F:$F,256) -> 3.022389 | C9: =SUMIFS(Data!$T:$T,Data!$C:$C,"LossyStore",Data!$E:$E,"0.1",Data!$F:$F,1024) -> 2.947845 | D9: =SUMIFS(Data!$T:$T,Data!$C:$C,"LossyStore",Data!$E:$E,"0.1",Data!$F:$F,4096) -> 2.875499 | E9: =SUMIFS(Data!$T:$T,Data!$C:$C,"LossyStore",Data!$E:$E,"0.1",Data!$F:$F,16384) -> 2.828134
A10: LossyStore 1% | B10: =SUMIFS(Data!$T:$T,Data!$C:$C,"LossyStore",Data!$E:$E,"1",Data!$F:$F,256) -> 3.188917 | C10: =SUMIFS(Data!$T:$T,Data!$C:$C,"LossyStore",Data!$E:$E,"1",Data!$F:$F,1024) -> 3.101269 | D10: =SUMIFS(Data!$T:$T,Data!$C:$C,"LossyStore",Data!$E:$E,"1",Data!$F:$F,4096) -> 3.015589 | E10: =SUMIFS(Data!$T:$T,Data!$C:$C,"LossyStore",Data!$E:$E,"1",Data!$F:$F,16384) -> 2.972089
A11: LossyStore 5% | B11: =SUMIFS(Data!$T:$T,Data!$C:$C,"LossyStore",Data!$E:$E,"5",Data!$F:$F,256) -> 3.302073 | C11: =SUMIFS(Data!$T:$T,Data!$C:$C,"LossyStore",Data!$E:$E,"5",Data!$F:$F,1024) -> 3.22765 | D11: =SUMIFS(Data!$T:$T,Data!$C:$C,"LossyStore",Data!$E:$E,"5",Data!$F:$F,4096) -> 3.160531 | E11: =SUMIFS(Data!$T:$T,Data!$C:$C,"LossyStore",Data!$E:$E,"5",Data!$F:$F,16384) -> 3.139602
A35: WHAT THIS SHOWS | B35: 1,195,600,000 stored bytes divided by what each configuration wrote.
A36: WHAT TO LOOK FOR | B36: FileStore reads 1.000 and is really 0.9997 -- it stores rows raw, so the shortfall is its framing. CompressedStore is flat to three decimals (1.650 to 1.652): zstd does not care about the unit size at this scale. The three bounded lossy lines FALL as the unit grows, which is the headline anomaly -- see the Anomalies sheet.
A38: RATIO ON DATA (framing removed)
A39: The codec's own figure. Differs from ratio_on_disk by the container, which the Framing sheet quantifies.
A40: Configuration | B40: 256 KB | C40: 1024 KB | D40: 4096 KB | E40: 16384 KB
A41: FileStore (raw) | B41: =SUMIFS(Data!$S:$S,Data!$C:$C,"FileStore",Data!$E:$E,"",Data!$F:$F,256) -> 1 | C41: =SUMIFS(Data!$S:$S,Data!$C:$C,"FileStore",Data!$E:$E,"",Data!$F:$F,1024) -> 1 | D41: =SUMIFS(Data!$S:$S,Data!$C:$C,"FileStore",Data!$E:$E,"",Data!$F:$F,4096) -> 1 | E41: =SUMIFS(Data!$S:$S,Data!$C:$C,"FileStore",Data!$E:$E,"",Data!$F:$F,16384) -> 1
A42: CompressedStore | B42: =SUMIFS(Data!$S:$S,Data!$C:$C,"CompressedStore",Data!$E:$E,"",Data!$F:$F,256) -> 1.650404 | C42: =SUMIFS(Data!$S:$S,Data!$C:$C,"CompressedStore",Data!$E:$E,"",Data!$F:$F,1024) -> 1.651697 | D42: =SUMIFS(Data!$S:$S,Data!$C:$C,"CompressedStore",Data!$E:$E,"",Data!$F:$F,4096) -> 1.651914 | E42: =SUMIFS(Data!$S:$S,Data!$C:$C,"CompressedStore",Data!$E:$E,"",Data!$F:$F,16384) -> 1.651963
A43: LossyStore lossless | B43: =SUMIFS(Data!$S:$S,Data!$C:$C,"LossyStore",Data!$E:$E,"",Data!$F:$F,256) -> 1.861728 | C43: =SUMIFS(Data!$S:$S,Data!$C:$C,"LossyStore",Data!$E:$E,"",Data!$F:$F,1024) -> 1.868722 | D43: =SUMIFS(Data!$S:$S,Data!$C:$C,"LossyStore",Data!$E:$E,"",Data!$F:$F,4096) -> 1.850647 | E43: =SUMIFS(Data!$S:$S,Data!$C:$C,"LossyStore",Data!$E:$E,"",Data!$F:$F,16384) -> 1.835042
A44: LossyStore 0.1% | B44: =SUMIFS(Data!$S:$S,Data!$C:$C,"LossyStore",Data!$E:$E,"0.1",Data!$F:$F,256) -> 3.030639 | C44: =SUMIFS(Data!$S:$S,Data!$C:$C,"LossyStore",Data!$E:$E,"0.1",Data!$F:$F,1024) -> 2.949806 | D44: =SUMIFS(Data!$S:$S,Data!$C:$C,"LossyStore",Data!$E:$E,"0.1",Data!$F:$F,4096) -> 2.875969 | E44: =SUMIFS(Data!$S:$S,Data!$C:$C,"LossyStore",Data!$E:$E,"0.1",Data!$F:$F,16384) -> 2.828251
A45: LossyStore 1% | B45: =SUMIFS(Data!$S:$S,Data!$C:$C,"LossyStore",Data!$E:$E,"1",Data!$F:$F,256) -> 3.198101 | C45: =SUMIFS(Data!$S:$S,Data!$C:$C,"LossyStore",Data!$E:$E,"1",Data!$F:$F,1024) -> 3.103439 | D45: =SUMIFS(Data!$S:$S,Data!$C:$C,"LossyStore",Data!$E:$E,"1",Data!$F:$F,4096) -> 3.016106 | E45: =SUMIFS(Data!$S:$S,Data!$C:$C,"LossyStore",Data!$E:$E,"1",Data!$F:$F,16384) -> 2.972217
A46: LossyStore 5% | B46: =SUMIFS(Data!$S:$S,Data!$C:$C,"LossyStore",Data!$E:$E,"5",Data!$F:$F,256) -> 3.311922 | C46: =SUMIFS(Data!$S:$S,Data!$C:$C,"LossyStore",Data!$E:$E,"5",Data!$F:$F,1024) -> 3.230002 | D46: =SUMIFS(Data!$S:$S,Data!$C:$C,"LossyStore",Data!$E:$E,"5",Data!$F:$F,4096) -> 3.161098 | E46: =SUMIFS(Data!$S:$S,Data!$C:$C,"LossyStore",Data!$E:$E,"5",Data!$F:$F,16384) -> 3.139745
A70: WHAT THIS SHOWS | B70: The same ratio with the container taken out of the denominator.
A71: WHAT TO LOOK FOR | B71: Compare against the chart above. The gap between them IS the framing, and it is widest at 256 KB where there are 4,561 units to put a header on.

Sheet Timing
A1: Timing — seconds, and which of them are the store
A2: N=1 per grid point except 4096 KB, which is N=3 after an outlier there was re-measured and did not reproduce. Byte counts are deterministic; the single samples are not, so read differences of a few tenths as noise.
A4: WRITE QUERY (encode_s, whole query)
A5: Configuration | B5: 256 KB | C5: 1024 KB | D5: 4096 KB | E5: 16384 KB
A6: FileStore (raw) | B6: =SUMIFS(Data!$L:$L,Data!$C:$C,"FileStore",Data!$E:$E,"",Data!$F:$F,256) -> 27.8315 | C6: =SUMIFS(Data!$L:$L,Data!$C:$C,"FileStore",Data!$E:$E,"",Data!$F:$F,1024) -> 27.5565 | D6: =SUMIFS(Data!$L:$L,Data!$C:$C,"FileStore",Data!$E:$E,"",Data!$F:$F,4096) -> 28.4896 | E6: =SUMIFS(Data!$L:$L,Data!$C:$C,"FileStore",Data!$E:$E,"",Data!$F:$F,16384) -> 27.8012
A7: CompressedStore | B7: =SUMIFS(Data!$L:$L,Data!$C:$C,"CompressedStore",Data!$E:$E,"",Data!$F:$F,256) -> 34.0164 | C7: =SUMIFS(Data!$L:$L,Data!$C:$C,"CompressedStore",Data!$E:$E,"",Data!$F:$F,1024) -> 33.1633 | D7: =SUMIFS(Data!$L:$L,Data!$C:$C,"CompressedStore",Data!$E:$E,"",Data!$F:$F,4096) -> 34.3937 | E7: =SUMIFS(Data!$L:$L,Data!$C:$C,"CompressedStore",Data!$E:$E,"",Data!$F:$F,16384) -> 36.2321
A8: LossyStore lossless | B8: =SUMIFS(Data!$L:$L,Data!$C:$C,"LossyStore",Data!$E:$E,"",Data!$F:$F,256) -> 32.017 | C8: =SUMIFS(Data!$L:$L,Data!$C:$C,"LossyStore",Data!$E:$E,"",Data!$F:$F,1024) -> 31.0179 | D8: =SUMIFS(Data!$L:$L,Data!$C:$C,"LossyStore",Data!$E:$E,"",Data!$F:$F,4096) -> 32.7766 | E8: =SUMIFS(Data!$L:$L,Data!$C:$C,"LossyStore",Data!$E:$E,"",Data!$F:$F,16384) -> 32.6821
A9: LossyStore 0.1% | B9: =SUMIFS(Data!$L:$L,Data!$C:$C,"LossyStore",Data!$E:$E,"0.1",Data!$F:$F,256) -> 31.9136 | C9: =SUMIFS(Data!$L:$L,Data!$C:$C,"LossyStore",Data!$E:$E,"0.1",Data!$F:$F,1024) -> 30.3721 | D9: =SUMIFS(Data!$L:$L,Data!$C:$C,"LossyStore",Data!$E:$E,"0.1",Data!$F:$F,4096) -> 30.7451 | E9: =SUMIFS(Data!$L:$L,Data!$C:$C,"LossyStore",Data!$E:$E,"0.1",Data!$F:$F,16384) -> 30.7901
A10: LossyStore 1% | B10: =SUMIFS(Data!$L:$L,Data!$C:$C,"LossyStore",Data!$E:$E,"1",Data!$F:$F,256) -> 31.7757 | C10: =SUMIFS(Data!$L:$L,Data!$C:$C,"LossyStore",Data!$E:$E,"1",Data!$F:$F,1024) -> 30.9375 | D10: =SUMIFS(Data!$L:$L,Data!$C:$C,"LossyStore",Data!$E:$E,"1",Data!$F:$F,4096) -> 31.1061 | E10: =SUMIFS(Data!$L:$L,Data!$C:$C,"LossyStore",Data!$E:$E,"1",Data!$F:$F,16384) -> 30.5885
A11: LossyStore 5% | B11: =SUMIFS(Data!$L:$L,Data!$C:$C,"LossyStore",Data!$E:$E,"5",Data!$F:$F,256) -> 31.8938 | C11: =SUMIFS(Data!$L:$L,Data!$C:$C,"LossyStore",Data!$E:$E,"5",Data!$F:$F,1024) -> 30.5255 | D11: =SUMIFS(Data!$L:$L,Data!$C:$C,"LossyStore",Data!$E:$E,"5",Data!$F:$F,4096) -> 31.7295 | E11: =SUMIFS(Data!$L:$L,Data!$C:$C,"LossyStore",Data!$E:$E,"5",Data!$F:$F,16384) -> 31.6
A12: normal query (no store) | B12: =SUMIFS(Data!$K:$K,Data!$C:$C,"FileStore",Data!$E:$E,"",Data!$F:$F,256) -> 20.7321 | C12: =SUMIFS(Data!$K:$K,Data!$C:$C,"FileStore",Data!$E:$E,"",Data!$F:$F,1024) -> 20.7883 | D12: =SUMIFS(Data!$K:$K,Data!$C:$C,"FileStore",Data!$E:$E,"",Data!$F:$F,4096) -> 21.1554 | E12: =SUMIFS(Data!$K:$K,Data!$C:$C,"FileStore",Data!$E:$E,"",Data!$F:$F,16384) -> 20.7318
A36: WHAT THIS SHOWS | B36: Bars are what each configuration cost. The red line is the SAME query with no store attached, measured at every grid point. The vertical gap between a bar and the line is the store.
A37: WHAT TO LOOK FOR | B37: The line sits at about 20.8 s and the bars at 27.6 to 36.2, so roughly two thirds of every bar is below the line and has nothing to do with the store -- it is reading and parsing a 1.49 GB CSV. That is also why the configurations look so alike here: they are sharing the same large constant.
A39: THE GAP, AS A NUMBER (encode_s - baseline_s)
A40: The same quantity the chart above shows as a gap, for when a figure is wanted rather than a picture.
A41: Configuration | B41: 256 KB | C41: 1024 KB | D41: 4096 KB | E41: 16384 KB
A42: FileStore (raw) | B42: =SUMIFS(Data!$N:$N,Data!$C:$C,"FileStore",Data!$E:$E,"",Data!$F:$F,256) -> 7.0994 | C42: =SUMIFS(Data!$N:$N,Data!$C:$C,"FileStore",Data!$E:$E,"",Data!$F:$F,1024) -> 6.7682 | D42: =SUMIFS(Data!$N:$N,Data!$C:$C,"FileStore",Data!$E:$E,"",Data!$F:$F,4096) -> 7.3342 | E42: =SUMIFS(Data!$N:$N,Data!$C:$C,"FileStore",Data!$E:$E,"",Data!$F:$F,16384) -> 7.0694
A43: CompressedStore | B43: =SUMIFS(Data!$N:$N,Data!$C:$C,"CompressedStore",Data!$E:$E,"",Data!$F:$F,256) -> 13.2843 | C43: =SUMIFS(Data!$N:$N,Data!$C:$C,"CompressedStore",Data!$E:$E,"",Data!$F:$F,1024) -> 12.375 | D43: =SUMIFS(Data!$N:$N,Data!$C:$C,"CompressedStore",Data!$E:$E,"",Data!$F:$F,4096) -> 13.2383 | E43: =SUMIFS(Data!$N:$N,Data!$C:$C,"CompressedStore",Data!$E:$E,"",Data!$F:$F,16384) -> 15.5003
A44: LossyStore lossless | B44: =SUMIFS(Data!$N:$N,Data!$C:$C,"LossyStore",Data!$E:$E,"",Data!$F:$F,256) -> 11.2849 | C44: =SUMIFS(Data!$N:$N,Data!$C:$C,"LossyStore",Data!$E:$E,"",Data!$F:$F,1024) -> 10.2296 | D44: =SUMIFS(Data!$N:$N,Data!$C:$C,"LossyStore",Data!$E:$E,"",Data!$F:$F,4096) -> 11.6212 | E44: =SUMIFS(Data!$N:$N,Data!$C:$C,"LossyStore",Data!$E:$E,"",Data!$F:$F,16384) -> 11.9503
A45: LossyStore 0.1% | B45: =SUMIFS(Data!$N:$N,Data!$C:$C,"LossyStore",Data!$E:$E,"0.1",Data!$F:$F,256) -> 11.1815 | C45: =SUMIFS(Data!$N:$N,Data!$C:$C,"LossyStore",Data!$E:$E,"0.1",Data!$F:$F,1024) -> 9.5838 | D45: =SUMIFS(Data!$N:$N,Data!$C:$C,"LossyStore",Data!$E:$E,"0.1",Data!$F:$F,4096) -> 9.5897 | E45: =SUMIFS(Data!$N:$N,Data!$C:$C,"LossyStore",Data!$E:$E,"0.1",Data!$F:$F,16384) -> 10.0583
A46: LossyStore 1% | B46: =SUMIFS(Data!$N:$N,Data!$C:$C,"LossyStore",Data!$E:$E,"1",Data!$F:$F,256) -> 11.0436 | C46: =SUMIFS(Data!$N:$N,Data!$C:$C,"LossyStore",Data!$E:$E,"1",Data!$F:$F,1024) -> 10.1492 | D46: =SUMIFS(Data!$N:$N,Data!$C:$C,"LossyStore",Data!$E:$E,"1",Data!$F:$F,4096) -> 9.9507 | E46: =SUMIFS(Data!$N:$N,Data!$C:$C,"LossyStore",Data!$E:$E,"1",Data!$F:$F,16384) -> 9.8567
A47: LossyStore 5% | B47: =SUMIFS(Data!$N:$N,Data!$C:$C,"LossyStore",Data!$E:$E,"5",Data!$F:$F,256) -> 11.1617 | C47: =SUMIFS(Data!$N:$N,Data!$C:$C,"LossyStore",Data!$E:$E,"5",Data!$F:$F,1024) -> 9.7372 | D47: =SUMIFS(Data!$N:$N,Data!$C:$C,"LossyStore",Data!$E:$E,"5",Data!$F:$F,4096) -> 10.5741 | E47: =SUMIFS(Data!$N:$N,Data!$C:$C,"LossyStore",Data!$E:$E,"5",Data!$F:$F,16384) -> 10.8682
A49: WHAT THIS SHOWS | B49: Each bar's distance above the red line.
A50: WHAT TO LOOK FOR | B50: 6.8 to 15.5 s. FileStore is cheapest because it writes the rows as they are. CompressedStore is dearest and gets worse as the unit grows, 12.4 to 15.5 s, while the lossy configurations get cheaper -- and CompressedStore's ratio does not improve to pay for it. See the Anomalies sheet.
A52: READ-BACK (decode_s, whole query)
A53: Configuration | B53: 256 KB | C53: 1024 KB | D53: 4096 KB | E53: 16384 KB
A54: FileStore (raw) | B54: =SUMIFS(Data!$M:$M,Data!$C:$C,"FileStore",Data!$E:$E,"",Data!$F:$F,256) -> 10.9249 | C54: =SUMIFS(Data!$M:$M,Data!$C:$C,"FileStore",Data!$E:$E,"",Data!$F:$F,1024) -> 10.2081 | D54: =SUMIFS(Data!$M:$M,Data!$C:$C,"FileStore",Data!$E:$E,"",Data!$F:$F,4096) -> 9.832 | E54: =SUMIFS(Data!$M:$M,Data!$C:$C,"FileStore",Data!$E:$E,"",Data!$F:$F,16384) -> 10.232
A55: CompressedStore | B55: =SUMIFS(Data!$M:$M,Data!$C:$C,"CompressedStore",Data!$E:$E,"",Data!$F:$F,256) -> 9.6512 | C55: =SUMIFS(Data!$M:$M,Data!$C:$C,"CompressedStore",Data!$E:$E,"",Data!$F:$F,1024) -> 9.5181 | D55: =SUMIFS(Data!$M:$M,Data!$C:$C,"CompressedStore",Data!$E:$E,"",Data!$F:$F,4096) -> 9.9165 | E55: =SUMIFS(Data!$M:$M,Data!$C:$C,"CompressedStore",Data!$E:$E,"",Data!$F:$F,16384) -> 9.8915
A56: LossyStore lossless | B56: =SUMIFS(Data!$M:$M,Data!$C:$C,"LossyStore",Data!$E:$E,"",Data!$F:$F,256) -> 10.3771 | C56: =SUMIFS(Data!$M:$M,Data!$C:$C,"LossyStore",Data!$E:$E,"",Data!$F:$F,1024) -> 9.8422 | D56: =SUMIFS(Data!$M:$M,Data!$C:$C,"LossyStore",Data!$E:$E,"",Data!$F:$F,4096) -> 9.9102 | E56: =SUMIFS(Data!$M:$M,Data!$C:$C,"LossyStore",Data!$E:$E,"",Data!$F:$F,16384) -> 9.9934
A57: LossyStore 0.1% | B57: =SUMIFS(Data!$M:$M,Data!$C:$C,"LossyStore",Data!$E:$E,"0.1",Data!$F:$F,256) -> 9.9668 | C57: =SUMIFS(Data!$M:$M,Data!$C:$C,"LossyStore",Data!$E:$E,"0.1",Data!$F:$F,1024) -> 9.9944 | D57: =SUMIFS(Data!$M:$M,Data!$C:$C,"LossyStore",Data!$E:$E,"0.1",Data!$F:$F,4096) -> 9.9176 | E57: =SUMIFS(Data!$M:$M,Data!$C:$C,"LossyStore",Data!$E:$E,"0.1",Data!$F:$F,16384) -> 9.9976
A58: LossyStore 1% | B58: =SUMIFS(Data!$M:$M,Data!$C:$C,"LossyStore",Data!$E:$E,"1",Data!$F:$F,256) -> 9.9096 | C58: =SUMIFS(Data!$M:$M,Data!$C:$C,"LossyStore",Data!$E:$E,"1",Data!$F:$F,1024) -> 9.9524 | D58: =SUMIFS(Data!$M:$M,Data!$C:$C,"LossyStore",Data!$E:$E,"1",Data!$F:$F,4096) -> 10.0552 | E58: =SUMIFS(Data!$M:$M,Data!$C:$C,"LossyStore",Data!$E:$E,"1",Data!$F:$F,16384) -> 9.9678
A59: LossyStore 5% | B59: =SUMIFS(Data!$M:$M,Data!$C:$C,"LossyStore",Data!$E:$E,"5",Data!$F:$F,256) -> 9.9197 | C59: =SUMIFS(Data!$M:$M,Data!$C:$C,"LossyStore",Data!$E:$E,"5",Data!$F:$F,1024) -> 10.7078 | D59: =SUMIFS(Data!$M:$M,Data!$C:$C,"LossyStore",Data!$E:$E,"5",Data!$F:$F,4096) -> 9.8691 | E59: =SUMIFS(Data!$M:$M,Data!$C:$C,"LossyStore",Data!$E:$E,"5",Data!$F:$F,16384) -> 10.2527
A60: normal query (no store) | B60: =SUMIFS(Data!$K:$K,Data!$C:$C,"FileStore",Data!$E:$E,"",Data!$F:$F,256) -> 20.7321 | C60: =SUMIFS(Data!$K:$K,Data!$C:$C,"FileStore",Data!$E:$E,"",Data!$F:$F,1024) -> 20.7883 | D60: =SUMIFS(Data!$K:$K,Data!$C:$C,"FileStore",Data!$E:$E,"",Data!$F:$F,4096) -> 21.1554 | E60: =SUMIFS(Data!$K:$K,Data!$C:$C,"FileStore",Data!$E:$E,"",Data!$F:$F,16384) -> 20.7318
A84: WHAT THIS SHOWS | B84: Replaying everything back out. No CSV is involved -- ReplaySource calls store->read and nothing else, formatted Native -- so here the line is not a floor but a comparison.
A85: WHAT TO LOOK FOR | B85: Every bar is BELOW the line: replaying 42.7M rows out of a store takes about 10 s against 20.8 s to scan the same rows out of the CSV. Reading from the store is twice as fast as reading the file it came from. Flat at 9.5 to 10.9 s everywhere except LossyStore at 5% and 4096 KB, which reads 16.26 s and is unexplained -- see Anomalies.

Sheet Throughput
A1: Throughput — the same measurements as rates
A2: Over 1,195,600,000 stored bytes. The CSV is 1,489,260,482 B, so a rate quoted on CSV bytes would be 1.25x these.
A4: WRITE QUERY MB/s
A5: Configuration | B5: 256 KB | C5: 1024 KB | D5: 4096 KB | E5: 16384 KB
A6: FileStore (raw) | B6: =1195600000/(SUMIFS(Data!$L:$L,Data!$C:$C,"FileStore",Data!$E:$E,"",Data!$F:$F,256))/1000000 -> 42.958518 | C6: =1195600000/(SUMIFS(Data!$L:$L,Data!$C:$C,"FileStore",Data!$E:$E,"",Data!$F:$F,1024))/1000000 -> 43.387223 | D6: =1195600000/(SUMIFS(Data!$L:$L,Data!$C:$C,"FileStore",Data!$E:$E,"",Data!$F:$F,4096))/1000000 -> 41.966191 | E6: =1195600000/(SUMIFS(Data!$L:$L,Data!$C:$C,"FileStore",Data!$E:$E,"",Data!$F:$F,16384))/1000000 -> 43.005338
A7: CompressedStore | B7: =1195600000/(SUMIFS(Data!$L:$L,Data!$C:$C,"CompressedStore",Data!$E:$E,"",Data!$F:$F,256))/1000000 -> 35.147752 | C7: =1195600000/(SUMIFS(Data!$L:$L,Data!$C:$C,"CompressedStore",Data!$E:$E,"",Data!$F:$F,1024))/1000000 -> 36.051901 | D7: =1195600000/(SUMIFS(Data!$L:$L,Data!$C:$C,"CompressedStore",Data!$E:$E,"",Data!$F:$F,4096))/1000000 -> 34.76218 | E7: =1195600000/(SUMIFS(Data!$L:$L,Data!$C:$C,"CompressedStore",Data!$E:$E,"",Data!$F:$F,16384))/1000000 -> 32.998363
A8: LossyStore lossless | B8: =1195600000/(SUMIFS(Data!$L:$L,Data!$C:$C,"LossyStore",Data!$E:$E,"",Data!$F:$F,256))/1000000 -> 37.342662 | C8: =1195600000/(SUMIFS(Data!$L:$L,Data!$C:$C,"LossyStore",Data!$E:$E,"",Data!$F:$F,1024))/1000000 -> 38.545485 | D8: =1195600000/(SUMIFS(Data!$L:$L,Data!$C:$C,"LossyStore",Data!$E:$E,"",Data!$F:$F,4096))/1000000 -> 36.477243 | E8: =1195600000/(SUMIFS(Data!$L:$L,Data!$C:$C,"LossyStore",Data!$E:$E,"",Data!$F:$F,16384))/1000000 -> 36.582717
A9: LossyStore 0.1% | B9: =1195600000/(SUMIFS(Data!$L:$L,Data!$C:$C,"LossyStore",Data!$E:$E,"0.1",Data!$F:$F,256))/1000000 -> 37.463652 | C9: =1195600000/(SUMIFS(Data!$L:$L,Data!$C:$C,"LossyStore",Data!$E:$E,"0.1",Data!$F:$F,1024))/1000000 -> 39.365075 | D9: =1195600000/(SUMIFS(Data!$L:$L,Data!$C:$C,"LossyStore",Data!$E:$E,"0.1",Data!$F:$F,4096))/1000000 -> 38.887498 | E9: =1195600000/(SUMIFS(Data!$L:$L,Data!$C:$C,"LossyStore",Data!$E:$E,"0.1",Data!$F:$F,16384))/1000000 -> 38.830663
A10: LossyStore 1% | B10: =1195600000/(SUMIFS(Data!$L:$L,Data!$C:$C,"LossyStore",Data!$E:$E,"1",Data!$F:$F,256))/1000000 -> 37.626236 | C10: =1195600000/(SUMIFS(Data!$L:$L,Data!$C:$C,"LossyStore",Data!$E:$E,"1",Data!$F:$F,1024))/1000000 -> 38.645657 | D10: =1195600000/(SUMIFS(Data!$L:$L,Data!$C:$C,"LossyStore",Data!$E:$E,"1",Data!$F:$F,4096))/1000000 -> 38.436191 | E10: =1195600000/(SUMIFS(Data!$L:$L,Data!$C:$C,"LossyStore",Data!$E:$E,"1",Data!$F:$F,16384))/1000000 -> 39.086585
A11: LossyStore 5% | B11: =1195600000/(SUMIFS(Data!$L:$L,Data!$C:$C,"LossyStore",Data!$E:$E,"5",Data!$F:$F,256))/1000000 -> 37.48691 | C11: =1195600000/(SUMIFS(Data!$L:$L,Data!$C:$C,"LossyStore",Data!$E:$E,"5",Data!$F:$F,1024))/1000000 -> 39.167254 | D11: =1195600000/(SUMIFS(Data!$L:$L,Data!$C:$C,"LossyStore",Data!$E:$E,"5",Data!$F:$F,4096))/1000000 -> 37.681022 | E11: =1195600000/(SUMIFS(Data!$L:$L,Data!$C:$C,"LossyStore",Data!$E:$E,"5",Data!$F:$F,16384))/1000000 -> 37.835443
A12: normal query (no store) | B12: =1195600000/(SUMIFS(Data!$K:$K,Data!$C:$C,"FileStore",Data!$E:$E,"",Data!$F:$F,256))/1000000 -> 57.669025 | C12: =1195600000/(SUMIFS(Data!$K:$K,Data!$C:$C,"FileStore",Data!$E:$E,"",Data!$F:$F,1024))/1000000 -> 57.51312 | D12: =1195600000/(SUMIFS(Data!$K:$K,Data!$C:$C,"FileStore",Data!$E:$E,"",Data!$F:$F,4096))/1000000 -> 56.515121 | E12: =1195600000/(SUMIFS(Data!$K:$K,Data!$C:$C,"FileStore",Data!$E:$E,"",Data!$F:$F,16384))/1000000 -> 57.66986
A36: WHAT THIS SHOWS | B36: Stored bytes over the whole write query. The red line is the same query with no store.
A37: WHAT TO LOOK FOR | B37: 33 to 43 MB/s against a store-free 57 MB/s. Every bar is BELOW the line here, which is the same fact as the Timing sheet seen the other way up: attaching a store makes the query slower, and the distance tells you by how much.
A39: STORE WRITE MB/s (baseline removed)
A40: Configuration | B40: 256 KB | C40: 1024 KB | D40: 4096 KB | E40: 16384 KB
A41: FileStore (raw) | B41: =1195600000/(SUMIFS(Data!$N:$N,Data!$C:$C,"FileStore",Data!$E:$E,"",Data!$F:$F,256))/1000000 -> 168.4086 | C41: =1195600000/(SUMIFS(Data!$N:$N,Data!$C:$C,"FileStore",Data!$E:$E,"",Data!$F:$F,1024))/1000000 -> 176.64963 | D41: =1195600000/(SUMIFS(Data!$N:$N,Data!$C:$C,"FileStore",Data!$E:$E,"",Data!$F:$F,4096))/1000000 -> 163.0171 | E41: =1195600000/(SUMIFS(Data!$N:$N,Data!$C:$C,"FileStore",Data!$E:$E,"",Data!$F:$F,16384))/1000000 -> 169.12326
A42: CompressedStore | B42: =1195600000/(SUMIFS(Data!$N:$N,Data!$C:$C,"CompressedStore",Data!$E:$E,"",Data!$F:$F,256))/1000000 -> 90.000979 | C42: =1195600000/(SUMIFS(Data!$N:$N,Data!$C:$C,"CompressedStore",Data!$E:$E,"",Data!$F:$F,1024))/1000000 -> 96.614141 | D42: =1195600000/(SUMIFS(Data!$N:$N,Data!$C:$C,"CompressedStore",Data!$E:$E,"",Data!$F:$F,4096))/1000000 -> 90.313711 | E42: =1195600000/(SUMIFS(Data!$N:$N,Data!$C:$C,"CompressedStore",Data!$E:$E,"",Data!$F:$F,16384))/1000000 -> 77.133991
A43: LossyStore lossless | B43: =1195600000/(SUMIFS(Data!$N:$N,Data!$C:$C,"LossyStore",Data!$E:$E,"",Data!$F:$F,256))/1000000 -> 105.94688 | C43: =1195600000/(SUMIFS(Data!$N:$N,Data!$C:$C,"LossyStore",Data!$E:$E,"",Data!$F:$F,1024))/1000000 -> 116.87652 | D43: =1195600000/(SUMIFS(Data!$N:$N,Data!$C:$C,"LossyStore",Data!$E:$E,"",Data!$F:$F,4096))/1000000 -> 102.88094 | E43: =1195600000/(SUMIFS(Data!$N:$N,Data!$C:$C,"LossyStore",Data!$E:$E,"",Data!$F:$F,16384))/1000000 -> 100.0477
A44: LossyStore 0.1% | B44: =1195600000/(SUMIFS(Data!$N:$N,Data!$C:$C,"LossyStore",Data!$E:$E,"0.1",Data!$F:$F,256))/1000000 -> 106.92662 | C44: =1195600000/(SUMIFS(Data!$N:$N,Data!$C:$C,"LossyStore",Data!$E:$E,"0.1",Data!$F:$F,1024))/1000000 -> 124.75219 | D44: =1195600000/(SUMIFS(Data!$N:$N,Data!$C:$C,"LossyStore",Data!$E:$E,"0.1",Data!$F:$F,4096))/1000000 -> 124.67543 | E44: =1195600000/(SUMIFS(Data!$N:$N,Data!$C:$C,"LossyStore",Data!$E:$E,"0.1",Data!$F:$F,16384))/1000000 -> 118.86701
A45: LossyStore 1% | B45: =1195600000/(SUMIFS(Data!$N:$N,Data!$C:$C,"LossyStore",Data!$E:$E,"1",Data!$F:$F,256))/1000000 -> 108.2618 | C45: =1195600000/(SUMIFS(Data!$N:$N,Data!$C:$C,"LossyStore",Data!$E:$E,"1",Data!$F:$F,1024))/1000000 -> 117.80239 | D45: =1195600000/(SUMIFS(Data!$N:$N,Data!$C:$C,"LossyStore",Data!$E:$E,"1",Data!$F:$F,4096))/1000000 -> 120.15235 | E45: =1195600000/(SUMIFS(Data!$N:$N,Data!$C:$C,"LossyStore",Data!$E:$E,"1",Data!$F:$F,16384))/1000000 -> 121.2982
