Workbook

Sheet Read Me
A1: LossyStore, measured directly — stage breakdown
A2: No SQL, no query engine, and the CSV parse outside every measurement.
A4: dataset | B4: debs_solar_panels, 42,700,000 rows x 28 B = 1,195,600,000 B stored
A5: store | B5: LossyStore, standalone, driven through its own API
A6: group sizes | B6: 256 KB, 1024 KB, 4096 KB, 16384 KB
A7: accuracy bounds | B7: 0.1%, 1%, 5%
A8: charts shown at | B8: 1% (every bound is in the Data sheet)
A9: build | B9: Benchmark (-O3, NO_ASSERT) with -DNES_STORE_PROFILING=ON
A10: repeats | B10: N=3, fastest kept
A12: WHERE THESE NUMBERS COME FROM
A13: timers in the store | B13: StoreProfile.hpp, compiled in with -DNES_STORE_PROFILING=ON. The stages are timed inside LossyStore and ColumnCodec, on the real path.
A14: not a replica | B14: An earlier version of this benchmark called the codecs itself and reconstructed the stages. It agreed on the codecs and the order and was wrong about everything else: it put bitpacking at ~2.4 s where the real timer says 0.161, and it never saw serialization at all -- which turns out to be the largest stage on the write path.
A15: the CSV is separate | B15: Parsing 1.49 GB of CSV into packed rows is reported on its own line and is NOT in any store total. In the SQL benchmarks it is about three quarters of a write query.
A17: WHAT CANNOT BE SPLIT
B18: writeRecord is called once per row -- 42,700,000 times -- so two clock reads inside it would be ~2 s against a 5.8 s write: the timer would be a third of the measurement. Its cost (lock, preconditions, pending insert, timestamp min/max) is DERIVED as the write total minus sealGroup, and those four cannot be separated from each other. Everything else is at group or read-call granularity, where a timer is noise.
A20: repeats | B20: --repeat 3 keeps the FASTEST repeat, not the median: a slow repeat is interference. The stage counters come from that same run, so wall clock and stages are consistent with one another.

Sheet Summary
A1: Summary
A2: Five charts, and what each settles.
A4: 1. WHAT THE STORE COSTS
A5: Measurement | B5: 256 KB | C5: 1024 KB | D5: 4096 KB | E5: 16384 KB
A6: CSV parse — NOT the store | B6: =SUMIFS(Data!$H:$H,Data!$E:$E,256,Data!$F:$F,1) -> 7.51851 | C6: =SUMIFS(Data!$H:$H,Data!$E:$E,1024,Data!$F:$F,1) -> 7.40829 | D6: =SUMIFS(Data!$H:$H,Data!$E:$E,4096,Data!$F:$F,1) -> 7.49298 | E6: =SUMIFS(Data!$H:$H,Data!$E:$E,16384,Data!$F:$F,1) -> 7.6243
A7: store write | B7: =SUMIFS(Data!$I:$I,Data!$E:$E,256,Data!$F:$F,1) -> 6.02062 | C7: =SUMIFS(Data!$I:$I,Data!$E:$E,1024,Data!$F:$F,1) -> 5.79751 | D7: =SUMIFS(Data!$I:$I,Data!$E:$E,4096,Data!$F:$F,1) -> 6.18093 | E7: =SUMIFS(Data!$I:$I,Data!$E:$E,16384,Data!$F:$F,1) -> 6.47535
A8: store read | B8: =SUMIFS(Data!$J:$J,Data!$E:$E,256,Data!$F:$F,1) -> 3.64248 | C8: =SUMIFS(Data!$J:$J,Data!$E:$E,1024,Data!$F:$F,1) -> 3.55094 | D8: =SUMIFS(Data!$J:$J,Data!$E:$E,4096,Data!$F:$F,1) -> 4.10058 | E8: =SUMIFS(Data!$J:$J,Data!$E:$E,16384,Data!$F:$F,1) -> 4.33874
A34: WHAT THIS SHOWS | B34: The three wall-clock totals the stage charts below break down.
A35: WHAT TO LOOK FOR | B35: Parsing the CSV costs more than writing and reading the store together, and the store is flat across a 64x range of group sizes.
A37: 2. WRITE PATH COMPOSITION
A38: Stage | B38: 256 KB | C38: 1024 KB | D38: 4096 KB | E38: 16384 KB
A39: writeRecord overhead | B39: =SUMIFS(Data!$K:$K,Data!$E:$E,256,Data!$F:$F,1) -> 0.948878 | C39: =SUMIFS(Data!$K:$K,Data!$E:$E,1024,Data!$F:$F,1) -> 0.926175 | D39: =SUMIFS(Data!$K:$K,Data!$E:$E,4096,Data!$F:$F,1) -> 0.976294 | E39: =SUMIFS(Data!$K:$K,Data!$E:$E,16384,Data!$F:$F,1) -> 0.954946
A40: row -> column | B40: =SUMIFS(Data!$M:$M,Data!$E:$E,256,Data!$F:$F,1) -> 0.641167 | C40: =SUMIFS(Data!$M:$M,Data!$E:$E,1024,Data!$F:$F,1) -> 0.598639 | D40: =SUMIFS(Data!$M:$M,Data!$E:$E,4096,Data!$F:$F,1) -> 0.69376 | E40: =SUMIFS(Data!$M:$M,Data!$E:$E,16384,Data!$F:$F,1) -> 0.619168
A41: quantization | B41: =SUMIFS(Data!$N:$N,Data!$E:$E,256,Data!$F:$F,1) -> 1.22852 | C41: =SUMIFS(Data!$N:$N,Data!$E:$E,1024,Data!$F:$F,1) -> 1.2014 | D41: =SUMIFS(Data!$N:$N,Data!$E:$E,4096,Data!$F:$F,1) -> 1.2841 | E41: =SUMIFS(Data!$N:$N,Data!$E:$E,16384,Data!$F:$F,1) -> 1.29334
A42: bitpacking | B42: =SUMIFS(Data!$O:$O,Data!$E:$E,256,Data!$F:$F,1) -> 0.16133 | C42: =SUMIFS(Data!$O:$O,Data!$E:$E,1024,Data!$F:$F,1) -> 0.159474 | D42: =SUMIFS(Data!$O:$O,Data!$E:$E,4096,Data!$F:$F,1) -> 0.168748 | E42: =SUMIFS(Data!$O:$O,Data!$E:$E,16384,Data!$F:$F,1) -> 0.164432
A43: compression | B43: =SUMIFS(Data!$P:$P,Data!$E:$E,256,Data!$F:$F,1) -> 0.425254 | C43: =SUMIFS(Data!$P:$P,Data!$E:$E,1024,Data!$F:$F,1) -> 0.320366 | D43: =SUMIFS(Data!$P:$P,Data!$E:$E,4096,Data!$F:$F,1) -> 0.283518 | E43: =SUMIFS(Data!$P:$P,Data!$E:$E,16384,Data!$F:$F,1) -> 0.617215
A44: header / serialize / index | B44: =SUMIFS(Data!$Q:$Q,Data!$E:$E,256,Data!$F:$F,1) -> 2.35128 | C44: =SUMIFS(Data!$Q:$Q,Data!$E:$E,1024,Data!$F:$F,1) -> 2.33991 | D44: =SUMIFS(Data!$Q:$Q,Data!$E:$E,4096,Data!$F:$F,1) -> 2.49403 | E44: =SUMIFS(Data!$Q:$Q,Data!$E:$E,16384,Data!$F:$F,1) -> 2.57645
A45: I/O: group to disk | B45: =SUMIFS(Data!$R:$R,Data!$E:$E,256,Data!$F:$F,1) -> 0.264191 | C45: =SUMIFS(Data!$R:$R,Data!$E:$E,1024,Data!$F:$F,1) -> 0.251556 | D45: =SUMIFS(Data!$R:$R,Data!$E:$E,4096,Data!$F:$F,1) -> 0.28047 | E45: =SUMIFS(Data!$R:$R,Data!$E:$E,16384,Data!$F:$F,1) -> 0.2498
A71: WHAT THIS SHOWS | B71: Where the store's write time goes.
A72: WHAT TO LOOK FOR | B72: Serialization is the largest stage, ahead of quantisation, and bitpacking is nearly free. A benchmark that reconstructs the stages from outside the store cannot see any of that.
A74: 3. READ PATH COMPOSITION
A75: Stage | B75: 256 KB | C75: 1024 KB | D75: 4096 KB | E75: 16384 KB
A76: file I/O | B76: =SUMIFS(Data!$S:$S,Data!$E:$E,256,Data!$F:$F,1) -> 0.0425326 | C76: =SUMIFS(Data!$S:$S,Data!$E:$E,1024,Data!$F:$F,1) -> 0.0366151 | D76: =SUMIFS(Data!$S:$S,Data!$E:$E,4096,Data!$F:$F,1) -> 0.0410518 | E76: =SUMIFS(Data!$S:$S,Data!$E:$E,16384,Data!$F:$F,1) -> 0.0685541
A77: decompression | B77: =SUMIFS(Data!$T:$T,Data!$E:$E,256,Data!$F:$F,1) -> 0.0503619 | C77: =SUMIFS(Data!$T:$T,Data!$E:$E,1024,Data!$F:$F,1) -> 0.0521807 | D77: =SUMIFS(Data!$T:$T,Data!$E:$E,4096,Data!$F:$F,1) -> 0.0606564 | E77: =SUMIFS(Data!$T:$T,Data!$E:$E,16384,Data!$F:$F,1) -> 0.278391
A78: decoding | B78: =SUMIFS(Data!$U:$U,Data!$E:$E,256,Data!$F:$F,1) -> 1.83643 | C78: =SUMIFS(Data!$U:$U,Data!$E:$E,1024,Data!$F:$F,1) -> 1.80201 | D78: =SUMIFS(Data!$U:$U,Data!$E:$E,4096,Data!$F:$F,1) -> 1.97269 | E78: =SUMIFS(Data!$U:$U,Data!$E:$E,16384,Data!$F:$F,1) -> 1.98123
A79: column -> row | B79: =SUMIFS(Data!$V:$V,Data!$E:$E,256,Data!$F:$F,1) -> 0.591834 | C79: =SUMIFS(Data!$V:$V,Data!$E:$E,1024,Data!$F:$F,1) -> 0.556759 | D79: =SUMIFS(Data!$V:$V,Data!$E:$E,4096,Data!$F:$F,1) -> 0.695804 | E79: =SUMIFS(Data!$V:$V,Data!$E:$E,16384,Data!$F:$F,1) -> 0.673944
A80: cursor/buffer management | B80: =SUMIFS(Data!$W:$W,Data!$E:$E,256,Data!$F:$F,1) -> 1.12132 | C80: =SUMIFS(Data!$W:$W,Data!$E:$E,1024,Data!$F:$F,1) -> 1.10338 | D80: =SUMIFS(Data!$W:$W,Data!$E:$E,4096,Data!$F:$F,1) -> 1.33038 | E80: =SUMIFS(Data!$W:$W,Data!$E:$E,16384,Data!$F:$F,1) -> 1.33662
A106: WHAT THIS SHOWS | B106: Where the store's read time goes.
A107: WHAT TO LOOK FOR | B107: Decoding plus cursor bookkeeping. File I/O and decompression together are under 3% -- the read is not waiting on the disk or on zstd.
A109: 4. WRITE SHARES (%)
A110: Stage | B110: 256 KB | C110: 1024 KB | D110: 4096 KB | E110: 16384 KB
A111: writeRecord overhead | B111: =100*SUMIFS(Data!$K:$K,Data!$E:$E,256,Data!$F:$F,1)/MAX(0.000001,SUMIFS(Data!$I:$I,Data!$E:$E,256,Data!$F:$F,1)) -> 15.76047 | C111: =100*SUMIFS(Data!$K:$K,Data!$E:$E,1024,Data!$F:$F,1)/MAX(0.000001,SUMIFS(Data!$I:$I,Data!$E:$E,1024,Data!$F:$F,1)) -> 15.975393 | D111: =100*SUMIFS(Data!$K:$K,Data!$E:$E,4096,Data!$F:$F,1)/MAX(0.000001,SUMIFS(Data!$I:$I,Data!$E:$E,4096,Data!$F:$F,1)) -> 15.795261 | E111: =100*SUMIFS(Data!$K:$K,Data!$E:$E,16384,Data!$F:$F,1)/MAX(0.000001,SUMIFS(Data!$I:$I,Data!$E:$E,16384,Data!$F:$F,1)) -> 14.747404
A112: row -> column | B112: =100*SUMIFS(Data!$M:$M,Data!$E:$E,256,Data!$F:$F,1)/MAX(0.000001,SUMIFS(Data!$I:$I,Data!$E:$E,256,Data!$F:$F,1)) -> 10.649518 | C112: =100*SUMIFS(Data!$M:$M,Data!$E:$E,1024,Data!$F:$F,1)/MAX(0.000001,SUMIFS(Data!$I:$I,Data!$E:$E,1024,Data!$F:$F,1)) -> 10.325795 | D112: =100*SUMIFS(Data!$M:$M,Data!$E:$E,4096,Data!$F:$F,1)/MAX(0.000001,SUMIFS(Data!$I:$I,Data!$E:$E,4096,Data!$F:$F,1)) -> 11.224201 | E112: =100*SUMIFS(Data!$M:$M,Data!$E:$E,16384,Data!$F:$F,1)/MAX(0.000001,SUMIFS(Data!$I:$I,Data!$E:$E,16384,Data!$F:$F,1)) -> 9.5619233
A113: quantization | B113: =100*SUMIFS(Data!$N:$N,Data!$E:$E,256,Data!$F:$F,1)/MAX(0.000001,SUMIFS(Data!$I:$I,Data!$E:$E,256,Data!$F:$F,1)) -> 20.405207 | C113: =100*SUMIFS(Data!$N:$N,Data!$E:$E,1024,Data!$F:$F,1)/MAX(0.000001,SUMIFS(Data!$I:$I,Data!$E:$E,1024,Data!$F:$F,1)) -> 20.72269 | D113: =100*SUMIFS(Data!$N:$N,Data!$E:$E,4096,Data!$F:$F,1)/MAX(0.000001,SUMIFS(Data!$I:$I,Data!$E:$E,4096,Data!$F:$F,1)) -> 20.775191 | E113: =100*SUMIFS(Data!$N:$N,Data!$E:$E,16384,Data!$F:$F,1)/MAX(0.000001,SUMIFS(Data!$I:$I,Data!$E:$E,16384,Data!$F:$F,1)) -> 19.973283
A114: bitpacking | B114: =100*SUMIFS(Data!$O:$O,Data!$E:$E,256,Data!$F:$F,1)/MAX(0.000001,SUMIFS(Data!$I:$I,Data!$E:$E,256,Data!$F:$F,1)) -> 2.6796244 | C114: =100*SUMIFS(Data!$O:$O,Data!$E:$E,1024,Data!$F:$F,1)/MAX(0.000001,SUMIFS(Data!$I:$I,Data!$E:$E,1024,Data!$F:$F,1)) -> 2.7507326 | D114: =100*SUMIFS(Data!$O:$O,Data!$E:$E,4096,Data!$F:$F,1)/MAX(0.000001,SUMIFS(Data!$I:$I,Data!$E:$E,4096,Data!$F:$F,1)) -> 2.7301393 | E114: =100*SUMIFS(Data!$O:$O,Data!$E:$E,16384,Data!$F:$F,1)/MAX(0.000001,SUMIFS(Data!$I:$I,Data!$E:$E,16384,Data!$F:$F,1)) -> 2.5393531
A115: compression | B115: =100*SUMIFS(Data!$P:$P,Data!$E:$E,256,Data!$F:$F,1)/MAX(0.000001,SUMIFS(Data!$I:$I,Data!$E:$E,256,Data!$F:$F,1)) -> 7.0632925 | C115: =100*SUMIFS(Data!$P:$P,Data!$E:$E,1024,Data!$F:$F,1)/MAX(0.000001,SUMIFS(Data!$I:$I,Data!$E:$E,1024,Data!$F:$F,1)) -> 5.5259241 | D115: =100*SUMIFS(Data!$P:$P,Data!$E:$E,4096,Data!$F:$F,1)/MAX(0.000001,SUMIFS(Data!$I:$I,Data!$E:$E,4096,Data!$F:$F,1)) -> 4.5869796 | E115: =100*SUMIFS(Data!$P:$P,Data!$E:$E,16384,Data!$F:$F,1)/MAX(0.000001,SUMIFS(Data!$I:$I,Data!$E:$E,16384,Data!$F:$F,1)) -> 9.5317628
A116: header / serialize / index | B116: =100*SUMIFS(Data!$Q:$Q,Data!$E:$E,256,Data!$F:$F,1)/MAX(0.000001,SUMIFS(Data!$I:$I,Data!$E:$E,256,Data!$F:$F,1)) -> 39.053785 | C116: =100*SUMIFS(Data!$Q:$Q,Data!$E:$E,1024,Data!$F:$F,1)/MAX(0.000001,SUMIFS(Data!$I:$I,Data!$E:$E,1024,Data!$F:$F,1)) -> 40.360603 | D116: =100*SUMIFS(Data!$Q:$Q,Data!$E:$E,4096,Data!$F:$F,1)/MAX(0.000001,SUMIFS(Data!$I:$I,Data!$E:$E,4096,Data!$F:$F,1)) -> 40.3504 | E116: =100*SUMIFS(Data!$Q:$Q,Data!$E:$E,16384,Data!$F:$F,1)/MAX(0.000001,SUMIFS(Data!$I:$I,Data!$E:$E,16384,Data!$F:$F,1)) -> 39.788583
A117: I/O: group to disk | B117: =100*SUMIFS(Data!$R:$R,Data!$E:$E,256,Data!$F:$F,1)/MAX(0.000001,SUMIFS(Data!$I:$I,Data!$E:$E,256,Data!$F:$F,1)) -> 4.3881029 | C117: =100*SUMIFS(Data!$R:$R,Data!$E:$E,1024,Data!$F:$F,1)/MAX(0.000001,SUMIFS(Data!$I:$I,Data!$E:$E,1024,Data!$F:$F,1)) -> 4.3390352 | D117: =100*SUMIFS(Data!$R:$R,Data!$E:$E,4096,Data!$F:$F,1)/MAX(0.000001,SUMIFS(Data!$I:$I,Data!$E:$E,4096,Data!$F:$F,1)) -> 4.5376667 | E117: =100*SUMIFS(Data!$R:$R,Data!$E:$E,16384,Data!$F:$F,1)/MAX(0.000001,SUMIFS(Data!$I:$I,Data!$E:$E,16384,Data!$F:$F,1)) -> 3.8577065
A143: WHAT THIS SHOWS | B143: The write composition normalised, so group sizes compare by shape.
A144: WHAT TO LOOK FOR | B144: Per-group work should shrink as groups grow; per-row work should not. The chart separates the two without needing the totals.
...

Sheet Data
A1: dataset | B1: rows | C1: row_width_bytes | D1: stored_bytes | E1: group_kb | F1: bound_pct | G1: repeats | H1: csv_s | I1: write_s | J1: read_s | K1: writerecord_overhead_s | L1: group_finalization_s | M1: transpose_out_s | N1: quantize_s | O1: bitpack_s | P1: compress_s | Q1: serialize_s | R1: write_io_s | S1: read_io_s | T1: decompress_s | U1: decode_s | V1: transpose_in_s | W1: cursor_mgmt_s | X1: groups | Y1: read_calls | Z1: disk_bytes | AA1: ratio | AB1: rank_decide_s | AC1: rank_fixed_bytes | AD1: rank_ranked_bytes
A2: debs_solar_panels | B2: 42700000 | C2: 28 | D2: 1195600000 | E2: 256 | F2: 0.1 | G2: 3 | H2: 7.47975 | I2: 6.06841 | J2: 3.66914 | K2: 0.946867 | L2: 4.83869 | M2: 0.646867 | N2: 1.23057 | O2: 0.186013 | P2: 0.41879 | Q2: 2.35645 | R2: 0.282851 | S2: 0.0475123 | T2: 0.0120418 | U2: 1.88475 | V2: 0.605831 | W2: 1.119 | X2: 4561 | Y2: 292467 | Z2: 395580701 | AA2: 3.02239 | AB2: 0 | AC2: 0 | AD2: 0
A3: debs_solar_panels | B3: 42700000 | C3: 28 | D3: 1195600000 | E3: 256 | F3: 1 | G3: 3 | H3: 7.51851 | I3: 6.02062 | J3: 3.64248 | K3: 0.948878 | L3: 4.80755 | M3: 0.641167 | N3: 1.22852 | O3: 0.16133 | P3: 0.425254 | Q3: 2.35128 | R3: 0.264191 | S3: 0.0425326 | T3: 0.0503619 | U3: 1.83643 | V3: 0.591834 | W3: 1.12132 | X3: 4561 | Y3: 292467 | Z3: 374923196 | AA3: 3.18892 | AB3: 6.81107 | AC3: 304368627 | AD3: 256439670
A4: debs_solar_panels | B4: 42700000 | C4: 28 | D4: 1195600000 | E4: 256 | F4: 5 | G4: 3 | H4: 7.39782 | I4: 5.92365 | J4: 3.56509 | K4: 0.93896 | L4: 4.73973 | M4: 0.652045 | N4: 1.21719 | O4: 0.143356 | P4: 0.388094 | Q4: 2.33904 | R4: 0.244965 | S4: 0.0409007 | T4: 0.0484412 | U4: 1.78124 | V4: 0.581913 | W4: 1.11259 | X4: 4561 | Y4: 292467 | Z4: 362075191 | AA4: 3.30208 | AB4: 0 | AC4: 0 | AD4: 0
A5: debs_solar_panels | B5: 42700000 | C5: 28 | D5: 1195600000 | E5: 1024 | F5: 0.1 | G5: 3 | H5: 7.44292 | I5: 5.82049 | J5: 3.55076 | K5: 0.931747 | L5: 4.62 | M5: 0.621844 | N5: 1.21357 | O5: 0.180962 | P5: 0.287968 | Q5: 2.31565 | R5: 0.268738 | S5: 0.0382647 | T5: 0.0211852 | U5: 1.83464 | V5: 0.555896 | W5: 1.10078 | X5: 1141 | Y5: 292467 | Z5: 405584073 | AA5: 2.94785 | AB5: 0 | AC5: 0 | AD5: 0
A6: debs_solar_panels | B6: 42700000 | C6: 28 | D6: 1195600000 | E6: 1024 | F6: 1 | G6: 3 | H6: 7.40829 | I6: 5.79751 | J6: 3.55094 | K6: 0.926175 | L6: 4.61978 | M6: 0.598639 | N6: 1.2014 | O6: 0.159474 | P6: 0.320366 | Q6: 2.33991 | R6: 0.251556 | S6: 0.0366151 | T6: 0.0521807 | U6: 1.80201 | V6: 0.556759 | W6: 1.10338 | X6: 1141 | Y6: 292467 | Z6: 385519266 | AA6: 3.10127 | AB6: 0 | AC6: 0 | AD6: 0
A7: debs_solar_panels | B7: 42700000 | C7: 28 | D7: 1195600000 | E7: 1024 | F7: 5 | G7: 3 | H7: 7.66029 | I7: 5.80237 | J7: 3.49444 | K7: 0.937859 | L7: 4.60713 | M7: 0.630755 | N7: 1.22032 | O7: 0.141846 | P7: 0.286774 | Q7: 2.32743 | R7: 0.257384 | S7: 0.0379958 | T7: 0.0396242 | U7: 1.7602 | V7: 0.551921 | W7: 1.1047 | X7: 1141 | Y7: 292467 | Z7: 370423871 | AA7: 3.22765 | AB7: 0 | AC7: 0 | AD7: 0
A8: debs_solar_panels | B8: 42700000 | C8: 28 | D8: 1195600000 | E8: 4096 | F8: 0.1 | G8: 3 | H8: 7.6181 | I8: 6.16294 | J8: 4.10132 | K8: 0.965906 | L8: 4.89619 | M8: 0.670157 | N8: 1.28017 | O8: 0.186154 | P8: 0.279127 | Q8: 2.48058 | R8: 0.300847 | S8: 0.0486986 | T8: 0.0390132 | U8: 2.00852 | V8: 0.683328 | W8: 1.32175 | X8: 286 | Y8: 292467 | Z8: 415788287 | AA8: 2.8755 | AB8: 0 | AC8: 0 | AD8: 0
A9: debs_solar_panels | B9: 42700000 | C9: 28 | D9: 1195600000 | E9: 4096 | F9: 1 | G9: 3 | H9: 7.49298 | I9: 6.18093 | J9: 4.10058 | K9: 0.976294 | L9: 4.92416 | M9: 0.69376 | N9: 1.2841 | O9: 0.168748 | P9: 0.283518 | Q9: 2.49403 | R9: 0.28047 | S9: 0.0410518 | T9: 0.0606564 | U9: 1.97269 | V9: 0.695804 | W9: 1.33038 | X9: 286 | Y9: 292467 | Z9: 396472715 | AA9: 3.01559 | AB9: 0 | AC9: 0 | AD9: 0
A10: debs_solar_panels | B10: 42700000 | C10: 28 | D10: 1195600000 | E10: 4096 | F10: 5 | G10: 3 | H10: 7.75812 | I10: 6.09897 | J10: 4.09761 | K10: 0.952661 | L10: 4.88502 | M10: 0.666782 | N10: 1.26779 | O10: 0.146799 | P10: 0.354481 | Q10: 2.44917 | R10: 0.261293 | S10: 0.0356545 | T10: 0.0493507 | U10: 1.97959 | V10: 0.704865 | W10: 1.32815 | X10: 286 | Y10: 292467 | Z10: 378290457 | AA10: 3.16053 | AB10: 0 | AC10: 0 | AD10: 0
A11: debs_solar_panels | B11: 42700000 | C11: 28 | D11: 1195600000 | E11: 16384 | F11: 0.1 | G11: 3 | H11: 7.55344 | I11: 6.77744 | J11: 4.36588 | K11: 0.985251 | L11: 5.50956 | M11: 0.654087 | N11: 1.32877 | O11: 0.190683 | P11: 0.705114 | Q11: 2.6309 | R11: 0.28263 | S11: 0.0758051 | T11: 0.242601 | U11: 2.01829 | V11: 0.68106 | W11: 1.34813 | X11: 72 | Y11: 292467 | Z11: 422751801 | AA11: 2.82814 | AB11: 0 | AC11: 0 | AD11: 0
A12: debs_solar_panels | B12: 42700000 | C12: 28 | D12: 1195600000 | E12: 16384 | F12: 1 | G12: 3 | H12: 7.6243 | I12: 6.47535 | J12: 4.33874 | K12: 0.954946 | L12: 5.2706 | M12: 0.619168 | N12: 1.29334 | O12: 0.164432 | P12: 0.617215 | Q12: 2.57645 | R12: 0.2498 | S12: 0.0685541 | T12: 0.278391 | U12: 1.98123 | V12: 0.673944 | W12: 1.33662 | X12: 72 | Y12: 292467 | Z12: 402275652 | AA12: 2.97209 | AB12: 0 | AC12: 0 | AD12: 0
A13: debs_solar_panels | B13: 42700000 | C13: 28 | D13: 1195600000 | E13: 16384 | F13: 5 | G13: 3 | H13: 7.66006 | I13: 6.78201 | J13: 4.36478 | K13: 0.98584 | L13: 5.54745 | M13: 0.663794 | N13: 1.3378 | O13: 0.154357 | P13: 0.75681 | Q13: 2.63469 | R13: 0.248728 | S13: 0.0674789 | T13: 0.264793 | U13: 1.97971 | V13: 0.698984 | W13: 1.35382 | X13: 72 | Y13: 292467 | Z13: 380812238 | AA13: 3.1396 | AB13: 0 | AC13: 0 | AD13: 0

Sheet Totals
A1: Totals — what the store costs, end to end
A2: The store driven through its own API: open, writeRecord per row, flush, then read back into 4 KB buffers until exhausted. The Write Path and Read Path sheets break these same numbers into stages.
A4: SECONDS (bound 1%)
A5: The CSV row is the cost of turning 1.49 GB of text into packed rows. It is reported here because it dwarfs both store numbers, and because in the SQL benchmarks it is about three quarters of a write query -- but it is NOT part of either store total.
A6: Measurement | B6: 256 KB | C6: 1024 KB | D6: 4096 KB | E6: 16384 KB
A7: CSV parse — NOT the store | B7: =SUMIFS(Data!$H:$H,Data!$E:$E,256,Data!$F:$F,1) -> 7.51851 | C7: =SUMIFS(Data!$H:$H,Data!$E:$E,1024,Data!$F:$F,1) -> 7.40829 | D7: =SUMIFS(Data!$H:$H,Data!$E:$E,4096,Data!$F:$F,1) -> 7.49298 | E7: =SUMIFS(Data!$H:$H,Data!$E:$E,16384,Data!$F:$F,1) -> 7.6243
A8: store write | B8: =SUMIFS(Data!$I:$I,Data!$E:$E,256,Data!$F:$F,1) -> 6.02062 | C8: =SUMIFS(Data!$I:$I,Data!$E:$E,1024,Data!$F:$F,1) -> 5.79751 | D8: =SUMIFS(Data!$I:$I,Data!$E:$E,4096,Data!$F:$F,1) -> 6.18093 | E8: =SUMIFS(Data!$I:$I,Data!$E:$E,16384,Data!$F:$F,1) -> 6.47535
A9: store read | B9: =SUMIFS(Data!$J:$J,Data!$E:$E,256,Data!$F:$F,1) -> 3.64248 | C9: =SUMIFS(Data!$J:$J,Data!$E:$E,1024,Data!$F:$F,1) -> 3.55094 | D9: =SUMIFS(Data!$J:$J,Data!$E:$E,4096,Data!$F:$F,1) -> 4.10058 | E9: =SUMIFS(Data!$J:$J,Data!$E:$E,16384,Data!$F:$F,1) -> 4.33874
A35: WHAT THIS SHOWS | B35: The three wall-clock totals at each group size: parsing the input, writing it into the store, and replaying it all back out.
A36: WHAT TO LOOK FOR | B36: Parsing the CSV costs more than writing AND reading the store put together. The store itself is flat across a 64x range of group sizes -- nothing on either path is sensitive to how much data it batches at once.
A38: MB PER SECOND (bound 1%)
A39: The same three totals as rates, over 1,195,600,000 stored bytes. For the CSV row that denominator is the packed output, not the 1,489,260,482 B of text it was parsed from -- so every row here divides the same number and the three are directly comparable.
A40: Measurement | B40: 256 KB | C40: 1024 KB | D40: 4096 KB | E40: 16384 KB
A41: CSV parse — NOT the store | B41: =1195600000/MAX(0.000001,SUMIFS(Data!$H:$H,Data!$E:$E,256,Data!$F:$F,1))/1000000 -> 159.02087 | C41: =1195600000/MAX(0.000001,SUMIFS(Data!$H:$H,Data!$E:$E,1024,Data!$F:$F,1))/1000000 -> 161.38677 | D41: =1195600000/MAX(0.000001,SUMIFS(Data!$H:$H,Data!$E:$E,4096,Data!$F:$F,1))/1000000 -> 159.56268 | E41: =1195600000/MAX(0.000001,SUMIFS(Data!$H:$H,Data!$E:$E,16384,Data!$F:$F,1))/1000000 -> 156.8144
A42: store write | B42: =1195600000/MAX(0.000001,SUMIFS(Data!$I:$I,Data!$E:$E,256,Data!$F:$F,1))/1000000 -> 198.5842 | C42: =1195600000/MAX(0.000001,SUMIFS(Data!$I:$I,Data!$E:$E,1024,Data!$F:$F,1))/1000000 -> 206.22647 | D42: =1195600000/MAX(0.000001,SUMIFS(Data!$I:$I,Data!$E:$E,4096,Data!$F:$F,1))/1000000 -> 193.43367 | E42: =1195600000/MAX(0.000001,SUMIFS(Data!$I:$I,Data!$E:$E,16384,Data!$F:$F,1))/1000000 -> 184.63867
A43: store read | B43: =1195600000/MAX(0.000001,SUMIFS(Data!$J:$J,Data!$E:$E,256,Data!$F:$F,1))/1000000 -> 328.2379 | C43: =1195600000/MAX(0.000001,SUMIFS(Data!$J:$J,Data!$E:$E,1024,Data!$F:$F,1))/1000000 -> 336.69958 | D43: =1195600000/MAX(0.000001,SUMIFS(Data!$J:$J,Data!$E:$E,4096,Data!$F:$F,1))/1000000 -> 291.56851 | E43: =1195600000/MAX(0.000001,SUMIFS(Data!$J:$J,Data!$E:$E,16384,Data!$F:$F,1))/1000000 -> 275.56387
A69: WHAT THIS SHOWS | B69: Stored bytes divided by each of the three totals.
A70: WHAT TO LOOK FOR | B70: The store writes at about 200 MB/s and reads at about 330, against roughly 160 MB/s to parse the CSV that feeds it. Reading is the fastest of the three and parsing the slowest, which is the whole argument for the replay tier: getting rows back out of the store is twice as fast as getting them out of the file they came from.
A72: ACROSS ACCURACY BOUNDS (group 256 KB)
A73: The same two totals against the accuracy bound, with the group size held fixed.
A74: Measurement | B74: 0.1% | C74: 1% | D74: 5%
A75: store write | B75: =SUMIFS(Data!$I:$I,Data!$F:$F,0.1,Data!$E:$E,256) -> 6.06841 | C75: =SUMIFS(Data!$I:$I,Data!$F:$F,1,Data!$E:$E,256) -> 6.02062 | D75: =SUMIFS(Data!$I:$I,Data!$F:$F,5,Data!$E:$E,256) -> 5.92365
A76: store read | B76: =SUMIFS(Data!$J:$J,Data!$F:$F,0.1,Data!$E:$E,256) -> 3.66914 | C76: =SUMIFS(Data!$J:$J,Data!$F:$F,1,Data!$E:$E,256) -> 3.64248 | D76: =SUMIFS(Data!$J:$J,Data!$F:$F,5,Data!$E:$E,256) -> 3.56509
A102: WHAT THIS SHOWS | B102: Write and read against the accuracy bound.
A103: WHAT TO LOOK FOR | B103: A looser bound stores fewer bytes but does not take less time to do it: the quantiser does the same work whatever grid it maps onto. Time is bought by the codec CHOICE, not by the bound.
A105: WHAT CAME OUT (bound 1%)
A106: Measurement | B106: 256 KB | C106: 1024 KB | D106: 4096 KB | E106: 16384 KB
A107: bytes on disk | B107: =SUMIFS(Data!$Z:$Z,Data!$E:$E,256,Data!$F:$F,1) -> 374923196 | C107: =SUMIFS(Data!$Z:$Z,Data!$E:$E,1024,Data!$F:$F,1) -> 385519266 | D107: =SUMIFS(Data!$Z:$Z,Data!$E:$E,4096,Data!$F:$F,1) -> 396472715 | E107: =SUMIFS(Data!$Z:$Z,Data!$E:$E,16384,Data!$F:$F,1) -> 402275652
A108: compression ratio | B108: =SUMIFS(Data!$AA:$AA,Data!$E:$E,256,Data!$F:$F,1) -> 3.18892 | C108: =SUMIFS(Data!$AA:$AA,Data!$E:$E,1024,Data!$F:$F,1) -> 3.10127 | D108: =SUMIFS(Data!$AA:$AA,Data!$E:$E,4096,Data!$F:$F,1) -> 3.01559 | E108: =SUMIFS(Data!$AA:$AA,Data!$E:$E,16384,Data!$F:$F,1) -> 2.97209
A109: groups sealed | B109: =SUMIFS(Data!$X:$X,Data!$E:$E,256,Data!$F:$F,1) -> 4561 | C109: =SUMIFS(Data!$X:$X,Data!$E:$E,1024,Data!$F:$F,1) -> 1141 | D109: =SUMIFS(Data!$X:$X,Data!$E:$E,4096,Data!$F:$F,1) -> 286 | E109: =SUMIFS(Data!$X:$X,Data!$E:$E,16384,Data!$F:$F,1) -> 72
A110: read calls | B110: =SUMIFS(Data!$Y:$Y,Data!$E:$E,256,Data!$F:$F,1) -> 292467 | C110: =SUMIFS(Data!$Y:$Y,Data!$E:$E,1024,Data!$F:$F,1) -> 292467 | D110: =SUMIFS(Data!$Y:$Y,Data!$E:$E,4096,Data!$F:$F,1) -> 292467 | E110: =SUMIFS(Data!$Y:$Y,Data!$E:$E,16384,Data!$F:$F,1) -> 292467
A112: WHAT THIS SHOWS | B112: The bytes the store produced, and the shape of the work: how many groups it sealed and how many read calls the replay took.
A113: WHAT TO LOOK FOR | B113: The ratio is identical to the SQL benchmark's for the same configuration, which is the check that this is measuring the same store doing the same thing. Groups fall 64x across the sweep while read calls do not move at all -- a read call is one 4 KB destination buffer, and the group size has nothing to do with it.

Sheet Write Path
A1: Write path — where the store's seconds go (bound 1%)
A2: Stages in execution order. They sum to the write total by construction: serialization is what is left of sealGroup after the others, and writeRecord overhead is what is left of the write after sealGroup.
A4: SECONDS PER STAGE
A5: Stage | B5: 256 KB | C5: 1024 KB | D5: 4096 KB | E5: 16384 KB
A6: writeRecord overhead | B6: =SUMIFS(Data!$K:$K,Data!$E:$E,256,Data!$F:$F,1) -> 0.948878 | C6: =SUMIFS(Data!$K:$K,Data!$E:$E,1024,Data!$F:$F,1) -> 0.926175 | D6: =SUMIFS(Data!$K:$K,Data!$E:$E,4096,Data!$F:$F,1) -> 0.976294 | E6: =SUMIFS(Data!$K:$K,Data!$E:$E,16384,Data!$F:$F,1) -> 0.954946
A7: row -> column | B7: =SUMIFS(Data!$M:$M,Data!$E:$E,256,Data!$F:$F,1) -> 0.641167 | C7: =SUMIFS(Data!$M:$M,Data!$E:$E,1024,Data!$F:$F,1) -> 0.598639 | D7: =SUMIFS(Data!$M:$M,Data!$E:$E,4096,Data!$F:$F,1) -> 0.69376 | E7: =SUMIFS(Data!$M:$M,Data!$E:$E,16384,Data!$F:$F,1) -> 0.619168
A8: quantization | B8: =SUMIFS(Data!$N:$N,Data!$E:$E,256,Data!$F:$F,1) -> 1.22852 | C8: =SUMIFS(Data!$N:$N,Data!$E:$E,1024,Data!$F:$F,1) -> 1.2014 | D8: =SUMIFS(Data!$N:$N,Data!$E:$E,4096,Data!$F:$F,1) -> 1.2841 | E8: =SUMIFS(Data!$N:$N,Data!$E:$E,16384,Data!$F:$F,1) -> 1.29334
A9: bitpacking | B9: =SUMIFS(Data!$O:$O,Data!$E:$E,256,Data!$F:$F,1) -> 0.16133 | C9: =SUMIFS(Data!$O:$O,Data!$E:$E,1024,Data!$F:$F,1) -> 0.159474 | D9: =SUMIFS(Data!$O:$O,Data!$E:$E,4096,Data!$F:$F,1) -> 0.168748 | E9: =SUMIFS(Data!$O:$O,Data!$E:$E,16384,Data!$F:$F,1) -> 0.164432
A10: compression | B10: =SUMIFS(Data!$P:$P,Data!$E:$E,256,Data!$F:$F,1) -> 0.425254 | C10: =SUMIFS(Data!$P:$P,Data!$E:$E,1024,Data!$F:$F,1) -> 0.320366 | D10: =SUMIFS(Data!$P:$P,Data!$E:$E,4096,Data!$F:$F,1) -> 0.283518 | E10: =SUMIFS(Data!$P:$P,Data!$E:$E,16384,Data!$F:$F,1) -> 0.617215
A11: header / serialize / index | B11: =SUMIFS(Data!$Q:$Q,Data!$E:$E,256,Data!$F:$F,1) -> 2.35128 | C11: =SUMIFS(Data!$Q:$Q,Data!$E:$E,1024,Data!$F:$F,1) -> 2.33991 | D11: =SUMIFS(Data!$Q:$Q,Data!$E:$E,4096,Data!$F:$F,1) -> 2.49403 | E11: =SUMIFS(Data!$Q:$Q,Data!$E:$E,16384,Data!$F:$F,1) -> 2.57645
A12: I/O: group to disk | B12: =SUMIFS(Data!$R:$R,Data!$E:$E,256,Data!$F:$F,1) -> 0.264191 | C12: =SUMIFS(Data!$R:$R,Data!$E:$E,1024,Data!$F:$F,1) -> 0.251556 | D12: =SUMIFS(Data!$R:$R,Data!$E:$E,4096,Data!$F:$F,1) -> 0.28047 | E12: =SUMIFS(Data!$R:$R,Data!$E:$E,16384,Data!$F:$F,1) -> 0.2498
A38: WHAT THIS SHOWS | B38: Each bar is one group size, split into the stages that make it up. Bar height is the store's whole write time.
A39: WHAT TO LOOK FOR | B39: Serialization -- building the group header, laying out the columns, updating the index -- is the largest single stage, larger than quantisation. It was entirely invisible to the replica version of this benchmark. Bitpacking is small: quantisation costs about seven times more than packing its output.
A41: AS A SHARE OF THE WRITE (%)
A42: The same stages normalised, so the shape can be compared between group sizes rather than the totals.
A43: Stage | B43: 256 KB | C43: 1024 KB | D43: 4096 KB | E43: 16384 KB
A44: writeRecord overhead | B44: =100*SUMIFS(Data!$K:$K,Data!$E:$E,256,Data!$F:$F,1)/MAX(0.000001,SUMIFS(Data!$I:$I,Data!$E:$E,256,Data!$F:$F,1)) -> 15.76047 | C44: =100*SUMIFS(Data!$K:$K,Data!$E:$E,1024,Data!$F:$F,1)/MAX(0.000001,SUMIFS(Data!$I:$I,Data!$E:$E,1024,Data!$F:$F,1)) -> 15.975393 | D44: =100*SUMIFS(Data!$K:$K,Data!$E:$E,4096,Data!$F:$F,1)/MAX(0.000001,SUMIFS(Data!$I:$I,Data!$E:$E,4096,Data!$F:$F,1)) -> 15.795261 | E44: =100*SUMIFS(Data!$K:$K,Data!$E:$E,16384,Data!$F:$F,1)/MAX(0.000001,SUMIFS(Data!$I:$I,Data!$E:$E,16384,Data!$F:$F,1)) -> 14.747404
A45: row -> column | B45: =100*SUMIFS(Data!$M:$M,Data!$E:$E,256,Data!$F:$F,1)/MAX(0.000001,SUMIFS(Data!$I:$I,Data!$E:$E,256,Data!$F:$F,1)) -> 10.649518 | C45: =100*SUMIFS(Data!$M:$M,Data!$E:$E,1024,Data!$F:$F,1)/MAX(0.000001,SUMIFS(Data!$I:$I,Data!$E:$E,1024,Data!$F:$F,1)) -> 10.325795 | D45: =100*SUMIFS(Data!$M:$M,Data!$E:$E,4096,Data!$F:$F,1)/MAX(0.000001,SUMIFS(Data!$I:$I,Data!$E:$E,4096,Data!$F:$F,1)) -> 11.224201 | E45: =100*SUMIFS(Data!$M:$M,Data!$E:$E,16384,Data!$F:$F,1)/MAX(0.000001,SUMIFS(Data!$I:$I,Data!$E:$E,16384,Data!$F:$F,1)) -> 9.5619233
A46: quantization | B46: =100*SUMIFS(Data!$N:$N,Data!$E:$E,256,Data!$F:$F,1)/MAX(0.000001,SUMIFS(Data!$I:$I,Data!$E:$E,256,Data!$F:$F,1)) -> 20.405207 | C46: =100*SUMIFS(Data!$N:$N,Data!$E:$E,1024,Data!$F:$F,1)/MAX(0.000001,SUMIFS(Data!$I:$I,Data!$E:$E,1024,Data!$F:$F,1)) -> 20.72269 | D46: =100*SUMIFS(Data!$N:$N,Data!$E:$E,4096,Data!$F:$F,1)/MAX(0.000001,SUMIFS(Data!$I:$I,Data!$E:$E,4096,Data!$F:$F,1)) -> 20.775191 | E46: =100*SUMIFS(Data!$N:$N,Data!$E:$E,16384,Data!$F:$F,1)/MAX(0.000001,SUMIFS(Data!$I:$I,Data!$E:$E,16384,Data!$F:$F,1)) -> 19.973283
A47: bitpacking | B47: =100*SUMIFS(Data!$O:$O,Data!$E:$E,256,Data!$F:$F,1)/MAX(0.000001,SUMIFS(Data!$I:$I,Data!$E:$E,256,Data!$F:$F,1)) -> 2.6796244 | C47: =100*SUMIFS(Data!$O:$O,Data!$E:$E,1024,Data!$F:$F,1)/MAX(0.000001,SUMIFS(Data!$I:$I,Data!$E:$E,1024,Data!$F:$F,1)) -> 2.7507326 | D47: =100*SUMIFS(Data!$O:$O,Data!$E:$E,4096,Data!$F:$F,1)/MAX(0.000001,SUMIFS(Data!$I:$I,Data!$E:$E,4096,Data!$F:$F,1)) -> 2.7301393 | E47: =100*SUMIFS(Data!$O:$O,Data!$E:$E,16384,Data!$F:$F,1)/MAX(0.000001,SUMIFS(Data!$I:$I,Data!$E:$E,16384,Data!$F:$F,1)) -> 2.5393531
A48: compression | B48: =100*SUMIFS(Data!$P:$P,Data!$E:$E,256,Data!$F:$F,1)/MAX(0.000001,SUMIFS(Data!$I:$I,Data!$E:$E,256,Data!$F:$F,1)) -> 7.0632925 | C48: =100*SUMIFS(Data!$P:$P,Data!$E:$E,1024,Data!$F:$F,1)/MAX(0.000001,SUMIFS(Data!$I:$I,Data!$E:$E,1024,Data!$F:$F,1)) -> 5.5259241 | D48: =100*SUMIFS(Data!$P:$P,Data!$E:$E,4096,Data!$F:$F,1)/MAX(0.000001,SUMIFS(Data!$I:$I,Data!$E:$E,4096,Data!$F:$F,1)) -> 4.5869796 | E48: =100*SUMIFS(Data!$P:$P,Data!$E:$E,16384,Data!$F:$F,1)/MAX(0.000001,SUMIFS(Data!$I:$I,Data!$E:$E,16384,Data!$F:$F,1)) -> 9.5317628
A49: header / serialize / index | B49: =100*SUMIFS(Data!$Q:$Q,Data!$E:$E,256,Data!$F:$F,1)/MAX(0.000001,SUMIFS(Data!$I:$I,Data!$E:$E,256,Data!$F:$F,1)) -> 39.053785 | C49: =100*SUMIFS(Data!$Q:$Q,Data!$E:$E,1024,Data!$F:$F,1)/MAX(0.000001,SUMIFS(Data!$I:$I,Data!$E:$E,1024,Data!$F:$F,1)) -> 40.360603 | D49: =100*SUMIFS(Data!$Q:$Q,Data!$E:$E,4096,Data!$F:$F,1)/MAX(0.000001,SUMIFS(Data!$I:$I,Data!$E:$E,4096,Data!$F:$F,1)) -> 40.3504 | E49: =100*SUMIFS(Data!$Q:$Q,Data!$E:$E,16384,Data!$F:$F,1)/MAX(0.000001,SUMIFS(Data!$I:$I,Data!$E:$E,16384,Data!$F:$F,1)) -> 39.788583
A50: I/O: group to disk | B50: =100*SUMIFS(Data!$R:$R,Data!$E:$E,256,Data!$F:$F,1)/MAX(0.000001,SUMIFS(Data!$I:$I,Data!$E:$E,256,Data!$F:$F,1)) -> 4.3881029 | C50: =100*SUMIFS(Data!$R:$R,Data!$E:$E,1024,Data!$F:$F,1)/MAX(0.000001,SUMIFS(Data!$I:$I,Data!$E:$E,1024,Data!$F:$F,1)) -> 4.3390352 | D50: =100*SUMIFS(Data!$R:$R,Data!$E:$E,4096,Data!$F:$F,1)/MAX(0.000001,SUMIFS(Data!$I:$I,Data!$E:$E,4096,Data!$F:$F,1)) -> 4.5376667 | E50: =100*SUMIFS(Data!$R:$R,Data!$E:$E,16384,Data!$F:$F,1)/MAX(0.000001,SUMIFS(Data!$I:$I,Data!$E:$E,16384,Data!$F:$F,1)) -> 3.8577065
A76: WHAT THIS SHOWS | B76: Each stage as a percentage of the store's write time, at each group size.
A77: WHAT TO LOOK FOR | B77: A stage whose share moves with group size is sensitive to how much data it sees at once; a flat one is per-row work wearing a different hat. Compare the transpose (per row, so flat) against serialization (per group, so it should fall as groups get larger).

Sheet Read Path
A1: Read path — replaying everything back out (bound 1%)
A2: No CSV anywhere on this path. Cursor/buffer management is what is left of the read after the four measured stages.
A4: SECONDS PER STAGE
A5: Stage | B5: 256 KB | C5: 1024 KB | D5: 4096 KB | E5: 16384 KB
A6: file I/O | B6: =SUMIFS(Data!$S:$S,Data!$E:$E,256,Data!$F:$F,1) -> 0.0425326 | C6: =SUMIFS(Data!$S:$S,Data!$E:$E,1024,Data!$F:$F,1) -> 0.0366151 | D6: =SUMIFS(Data!$S:$S,Data!$E:$E,4096,Data!$F:$F,1) -> 0.0410518 | E6: =SUMIFS(Data!$S:$S,Data!$E:$E,16384,Data!$F:$F,1) -> 0.0685541
A7: decompression | B7: =SUMIFS(Data!$T:$T,Data!$E:$E,256,Data!$F:$F,1) -> 0.0503619 | C7: =SUMIFS(Data!$T:$T,Data!$E:$E,1024,Data!$F:$F,1) -> 0.0521807 | D7: =SUMIFS(Data!$T:$T,Data!$E:$E,4096,Data!$F:$F,1) -> 0.0606564 | E7: =SUMIFS(Data!$T:$T,Data!$E:$E,16384,Data!$F:$F,1) -> 0.278391
A8: decoding | B8: =SUMIFS(Data!$U:$U,Data!$E:$E,256,Data!$F:$F,1) -> 1.83643 | C8: =SUMIFS(Data!$U:$U,Data!$E:$E,1024,Data!$F:$F,1) -> 1.80201 | D8: =SUMIFS(Data!$U:$U,Data!$E:$E,4096,Data!$F:$F,1) -> 1.97269 | E8: =SUMIFS(Data!$U:$U,Data!$E:$E,16384,Data!$F:$F,1) -> 1.98123
A9: column -> row | B9: =SUMIFS(Data!$V:$V,Data!$E:$E,256,Data!$F:$F,1) -> 0.591834 | C9: =SUMIFS(Data!$V:$V,Data!$E:$E,1024,Data!$F:$F,1) -> 0.556759 | D9: =SUMIFS(Data!$V:$V,Data!$E:$E,4096,Data!$F:$F,1) -> 0.695804 | E9: =SUMIFS(Data!$V:$V,Data!$E:$E,16384,Data!$F:$F,1) -> 0.673944
A10: cursor/buffer management | B10: =SUMIFS(Data!$W:$W,Data!$E:$E,256,Data!$F:$F,1) -> 1.12132 | C10: =SUMIFS(Data!$W:$W,Data!$E:$E,1024,Data!$F:$F,1) -> 1.10338 | D10: =SUMIFS(Data!$W:$W,Data!$E:$E,4096,Data!$F:$F,1) -> 1.33038 | E10: =SUMIFS(Data!$W:$W,Data!$E:$E,16384,Data!$F:$F,1) -> 1.33662
A36: WHAT THIS SHOWS | B36: Each bar is one group size, split into the stages of a full replay.
A37: WHAT TO LOOK FOR | B37: File I/O is almost nothing -- the store file is in the page cache, so it reads at multiple GB/s. The read is decoding plus cursor and buffer bookkeeping, and that second term is the price of a 4 KB destination buffer: it is paid once per read call, and there are 292,467 of them.
A39: AS A SHARE OF THE READ (%)
A40: Stage | B40: 256 KB | C40: 1024 KB | D40: 4096 KB | E40: 16384 KB
A41: file I/O | B41: =100*SUMIFS(Data!$S:$S,Data!$E:$E,256,Data!$F:$F,1)/MAX(0.000001,SUMIFS(Data!$J:$J,Data!$E:$E,256,Data!$F:$F,1)) -> 1.1676825 | C41: =100*SUMIFS(Data!$S:$S,Data!$E:$E,1024,Data!$F:$F,1)/MAX(0.000001,SUMIFS(Data!$J:$J,Data!$E:$E,1024,Data!$F:$F,1)) -> 1.0311382 | D41: =100*SUMIFS(Data!$S:$S,Data!$E:$E,4096,Data!$F:$F,1)/MAX(0.000001,SUMIFS(Data!$J:$J,Data!$E:$E,4096,Data!$F:$F,1)) -> 1.0011218 | E41: =100*SUMIFS(Data!$S:$S,Data!$E:$E,16384,Data!$F:$F,1)/MAX(0.000001,SUMIFS(Data!$J:$J,Data!$E:$E,16384,Data!$F:$F,1)) -> 1.5800463
A42: decompression | B42: =100*SUMIFS(Data!$T:$T,Data!$E:$E,256,Data!$F:$F,1)/MAX(0.000001,SUMIFS(Data!$J:$J,Data!$E:$E,256,Data!$F:$F,1)) -> 1.3826267 | C42: =100*SUMIFS(Data!$T:$T,Data!$E:$E,1024,Data!$F:$F,1)/MAX(0.000001,SUMIFS(Data!$J:$J,Data!$E:$E,1024,Data!$F:$F,1)) -> 1.4694898 | D42: =100*SUMIFS(Data!$T:$T,Data!$E:$E,4096,Data!$F:$F,1)/MAX(0.000001,SUMIFS(Data!$J:$J,Data!$E:$E,4096,Data!$F:$F,1)) -> 1.4792151 | E42: =100*SUMIFS(Data!$T:$T,Data!$E:$E,16384,Data!$F:$F,1)/MAX(0.000001,SUMIFS(Data!$J:$J,Data!$E:$E,16384,Data!$F:$F,1)) -> 6.416402
A43: decoding | B43: =100*SUMIFS(Data!$U:$U,Data!$E:$E,256,Data!$F:$F,1)/MAX(0.000001,SUMIFS(Data!$J:$J,Data!$E:$E,256,Data!$F:$F,1)) -> 50.417024 | C43: =100*SUMIFS(Data!$U:$U,Data!$E:$E,1024,Data!$F:$F,1)/MAX(0.000001,SUMIFS(Data!$J:$J,Data!$E:$E,1024,Data!$F:$F,1)) -> 50.747408 | D43: =100*SUMIFS(Data!$U:$U,Data!$E:$E,4096,Data!$F:$F,1)/MAX(0.000001,SUMIFS(Data!$J:$J,Data!$E:$E,4096,Data!$F:$F,1)) -> 48.107585 | E43: =100*SUMIFS(Data!$U:$U,Data!$E:$E,16384,Data!$F:$F,1)/MAX(0.000001,SUMIFS(Data!$J:$J,Data!$E:$E,16384,Data!$F:$F,1)) -> 45.663718
A44: column -> row | B44: =100*SUMIFS(Data!$V:$V,Data!$E:$E,256,Data!$F:$F,1)/MAX(0.000001,SUMIFS(Data!$J:$J,Data!$E:$E,256,Data!$F:$F,1)) -> 16.248106 | C44: =100*SUMIFS(Data!$V:$V,Data!$E:$E,1024,Data!$F:$F,1)/MAX(0.000001,SUMIFS(Data!$J:$J,Data!$E:$E,1024,Data!$F:$F,1)) -> 15.6792 | D44: =100*SUMIFS(Data!$V:$V,Data!$E:$E,4096,Data!$F:$F,1)/MAX(0.000001,SUMIFS(Data!$J:$J,Data!$E:$E,4096,Data!$F:$F,1)) -> 16.968429 | E44: =100*SUMIFS(Data!$V:$V,Data!$E:$E,16384,Data!$F:$F,1)/MAX(0.000001,SUMIFS(Data!$J:$J,Data!$E:$E,16384,Data!$F:$F,1)) -> 15.533173
A45: cursor/buffer management | B45: =100*SUMIFS(Data!$W:$W,Data!$E:$E,256,Data!$F:$F,1)/MAX(0.000001,SUMIFS(Data!$J:$J,Data!$E:$E,256,Data!$F:$F,1)) -> 30.78452 | C45: =100*SUMIFS(Data!$W:$W,Data!$E:$E,1024,Data!$F:$F,1)/MAX(0.000001,SUMIFS(Data!$J:$J,Data!$E:$E,1024,Data!$F:$F,1)) -> 31.072899 | D45: =100*SUMIFS(Data!$W:$W,Data!$E:$E,4096,Data!$F:$F,1)/MAX(0.000001,SUMIFS(Data!$J:$J,Data!$E:$E,4096,Data!$F:$F,1)) -> 32.443703 | E45: =100*SUMIFS(Data!$W:$W,Data!$E:$E,16384,Data!$F:$F,1)/MAX(0.000001,SUMIFS(Data!$J:$J,Data!$E:$E,16384,Data!$F:$F,1)) -> 30.80664
A71: WHAT THIS SHOWS | B71: The same stages as percentages of the read.
A72: WHAT TO LOOK FOR | B72: Decoding dominates and does not shrink with a larger group, because it is per value. Decompression stays tiny: zstd is kept only where it helped, so most groups have nothing to inflate.

Sheet Throughput
A1: Throughput — the paths and the stages that move bytes (bound 1%)
A2: Over 1,195,600,000 stored bytes. Stages that transform rather than move bytes (quantisation, bitpacking) are left out: a MB/s figure for them would divide by a byte count that is not what they produced.
A4: MB PER SECOND
A5: Measurement | B5: 256 KB | C5: 1024 KB | D5: 4096 KB | E5: 16384 KB
A6: CSV parse (not the store) | B6: =1195600000/MAX(0.000001,SUMIFS(Data!$H:$H,Data!$E:$E,256,Data!$F:$F,1))/1000000 -> 159.02087 | C6: =1195600000/MAX(0.000001,SUMIFS(Data!$H:$H,Data!$E:$E,1024,Data!$F:$F,1))/1000000 -> 161.38677 | D6: =1195600000/MAX(0.000001,SUMIFS(Data!$H:$H,Data!$E:$E,4096,Data!$F:$F,1))/1000000 -> 159.56268 | E6: =1195600000/MAX(0.000001,SUMIFS(Data!$H:$H,Data!$E:$E,16384,Data!$F:$F,1))/1000000 -> 156.8144
A7: store write | B7: =1195600000/MAX(0.000001,SUMIFS(Data!$I:$I,Data!$E:$E,256,Data!$F:$F,1))/1000000 -> 198.5842 | C7: =1195600000/MAX(0.000001,SUMIFS(Data!$I:$I,Data!$E:$E,1024,Data!$F:$F,1))/1000000 -> 206.22647 | D7: =1195600000/MAX(0.000001,SUMIFS(Data!$I:$I,Data!$E:$E,4096,Data!$F:$F,1))/1000000 -> 193.43367 | E7: =1195600000/MAX(0.000001,SUMIFS(Data!$I:$I,Data!$E:$E,16384,Data!$F:$F,1))/1000000 -> 184.63867
A8: store read | B8: =1195600000/MAX(0.000001,SUMIFS(Data!$J:$J,Data!$E:$E,256,Data!$F:$F,1))/1000000 -> 328.2379 | C8: =1195600000/MAX(0.000001,SUMIFS(Data!$J:$J,Data!$E:$E,1024,Data!$F:$F,1))/1000000 -> 336.69958 | D8: =1195600000/MAX(0.000001,SUMIFS(Data!$J:$J,Data!$E:$E,4096,Data!$F:$F,1))/1000000 -> 291.56851 | E8: =1195600000/MAX(0.000001,SUMIFS(Data!$J:$J,Data!$E:$E,16384,Data!$F:$F,1))/1000000 -> 275.56387
A9: row -> column | B9: =1195600000/MAX(0.000001,SUMIFS(Data!$M:$M,Data!$E:$E,256,Data!$F:$F,1))/1000000 -> 1864.7248 | C9: =1195600000/MAX(0.000001,SUMIFS(Data!$M:$M,Data!$E:$E,1024,Data!$F:$F,1))/1000000 -> 1997.197 | D9: =1195600000/MAX(0.000001,SUMIFS(Data!$M:$M,Data!$E:$E,4096,Data!$F:$F,1))/1000000 -> 1723.3625 | E9: =1195600000/MAX(0.000001,SUMIFS(Data!$M:$M,Data!$E:$E,16384,Data!$F:$F,1))/1000000 -> 1930.9783
A10: column -> row | B10: =1195600000/MAX(0.000001,SUMIFS(Data!$V:$V,Data!$E:$E,256,Data!$F:$F,1))/1000000 -> 2020.1611 | C10: =1195600000/MAX(0.000001,SUMIFS(Data!$V:$V,Data!$E:$E,1024,Data!$F:$F,1))/1000000 -> 2147.4282 | D10: =1195600000/MAX(0.000001,SUMIFS(Data!$V:$V,Data!$E:$E,4096,Data!$F:$F,1))/1000000 -> 1718.3 | E10: =1195600000/MAX(0.000001,SUMIFS(Data!$V:$V,Data!$E:$E,16384,Data!$F:$F,1))/1000000 -> 1774.0346
A11: write I/O | B11: =1195600000/MAX(0.000001,SUMIFS(Data!$R:$R,Data!$E:$E,256,Data!$F:$F,1))/1000000 -> 4525.5137 | C11: =1195600000/MAX(0.000001,SUMIFS(Data!$R:$R,Data!$E:$E,1024,Data!$F:$F,1))/1000000 -> 4752.8185 | D11: =1195600000/MAX(0.000001,SUMIFS(Data!$R:$R,Data!$E:$E,4096,Data!$F:$F,1))/1000000 -> 4262.8445 | E11: =1195600000/MAX(0.000001,SUMIFS(Data!$R:$R,Data!$E:$E,16384,Data!$F:$F,1))/1000000 -> 4786.229
A12: read I/O | B12: =1195600000/MAX(0.000001,SUMIFS(Data!$S:$S,Data!$E:$E,256,Data!$F:$F,1))/1000000 -> 28110.203 | C12: =1195600000/MAX(0.000001,SUMIFS(Data!$S:$S,Data!$E:$E,1024,Data!$F:$F,1))/1000000 -> 32653.195 | D12: =1195600000/MAX(0.000001,SUMIFS(Data!$S:$S,Data!$E:$E,4096,Data!$F:$F,1))/1000000 -> 29124.18 | E12: =1195600000/MAX(0.000001,SUMIFS(Data!$S:$S,Data!$E:$E,16384,Data!$F:$F,1))/1000000 -> 17440.241
A38: WHAT THIS SHOWS | B38: Stored bytes divided by the time each phase took.
A39: WHAT TO LOOK FOR | B39: The two transposes run at ~2 GB/s and the two I/O lines far faster still, since nothing reaches the disk. The CSV parse is the slowest thing on the chart by a wide margin, and it is the only line here that is not the store.

Sheet Ranking
A1: Would codec ranking pay?
A2: LossyStore picks a codec once per column by a fixed type-only rule. The statistics-driven ranking path is in the tree, tested, and not wired in. LossyStore.cpp:326-332 says the tradeoff 'is exactly what the benchmarks decide'. These are the numbers.
B4: value
A5: bytes today, fixed type-only rule | B5: 304368627
A6: bytes if ranked | B6: 256439670
A7: saving | B7: 47928957
A8: saving, per cent | B8: 15.74701
A9: cost of deciding (computeStats + rank) | B9: 6.81107
A10: store write today | B10: 6.02062
A11: store read today | B11: 3.64248
A12: deciding, as a share of a write | B12: 113.12905
A14: WHAT THIS SHOWS | B14: Measured at a 256 KB group and a 1% bound. Ranking is independent of both, so it was run once.
A15: WHAT TO LOOK FOR | B15: A 15.75% saving on the integer columns for a cost larger than the entire store write. Nearly all of it is computeStats; filterCandidates and rank are free. On these numbers the fixed rule is the right choice, and the question the source comment left open is answered. Note the saving applies to the integer columns only, which are about four fifths of the file.
